Watching for file changes with StatReloader
Watching for file changes with StatReloader
/Volumes/Volume/jwt/tracker/app/tracker/settings.py changed, reloading.
Watching for file changes with StatReloader
/Volumes/Volume/jwt/tracker/app/tracker/settings.py changed, reloading.
Watching for file changes with StatReloader
/Volumes/Volume/jwt/tracker/app/tracker/settings.py changed, reloading.
Watching for file changes with StatReloader
/Volumes/Volume/jwt/tracker/app/tracker/settings.py changed, reloading.
Watching for file changes with StatReloader
/Volumes/Volume/jwt/tracker/app/tracker/settings.py changed, reloading.
Watching for file changes with StatReloader
Invalid HTTP_HOST header: '127.0.0.1:8000'. You may need to add '127.0.0.1' to ALLOWED_HOSTS.
Traceback (most recent call last):
  File "/Volumes/Volume/orderc/myenv/lib/python3.10/site-packages/django/core/handlers/exception.py", line 55, in inner
    response = get_response(request)
  File "/Volumes/Volume/orderc/myenv/lib/python3.10/site-packages/django/utils/deprecation.py", line 135, in __call__
    response = self.process_request(request)
  File "/Volumes/Volume/orderc/myenv/lib/python3.10/site-packages/django/middleware/common.py", line 48, in process_request
    host = request.get_host()
  File "/Volumes/Volume/orderc/myenv/lib/python3.10/site-packages/django/http/request.py", line 148, in get_host
    raise DisallowedHost(msg)
django.core.exceptions.DisallowedHost: Invalid HTTP_HOST header: '127.0.0.1:8000'. You may need to add '127.0.0.1' to ALLOWED_HOSTS.
Bad Request: /api/TrackingDetails
/Volumes/Volume/jwt/tracker/app/tracker/settings.py changed, reloading.
Watching for file changes with StatReloader
Watching for file changes with StatReloader
Watching for file changes with StatReloader
Method Not Allowed: /api/posttrack
/Volumes/Volume/jwt/tracker/app/msbctracker/views.py changed, reloading.
Watching for file changes with StatReloader
/Volumes/Volume/jwt/tracker/app/msbctracker/views.py changed, reloading.
Watching for file changes with StatReloader
/Volumes/Volume/jwt/tracker/app/msbctracker/urls.py changed, reloading.
Watching for file changes with StatReloader
Method Not Allowed: /api/posttrack
/Volumes/Volume/jwt/tracker/app/msbctracker/urls.py changed, reloading.
Watching for file changes with StatReloader
Method Not Allowed: /api/posttrack
/Volumes/Volume/jwt/tracker/app/msbctracker/views.py changed, reloading.
Watching for file changes with StatReloader
Method Not Allowed: /api/posttrack
Method Not Allowed: /api/posttrack
Method Not Allowed: /api/posttrack
Method Not Allowed: /api/posttrack
/Volumes/Volume/jwt/tracker/app/msbctracker/views.py changed, reloading.
Watching for file changes with StatReloader
/Volumes/Volume/jwt/tracker/app/msbctracker/views.py changed, reloading.
Watching for file changes with StatReloader
Watching for file changes with StatReloader
/Volumes/Volume/jwt/tracker/app/msbctracker/views.py changed, reloading.
Watching for file changes with StatReloader
/Volumes/Volume/jwt/tracker/app/msbctracker/views.py changed, reloading.
Watching for file changes with StatReloader
/Volumes/Volume/jwt/tracker/app/msbctracker/views.py changed, reloading.
Watching for file changes with StatReloader
/Volumes/Volume/jwt/tracker/app/msbctracker/views.py changed, reloading.
Watching for file changes with StatReloader
Method Not Allowed: /api/posttrack
/Volumes/Volume/jwt/tracker/app/msbctracker/views.py changed, reloading.
Watching for file changes with StatReloader
Method Not Allowed: /api/posttrack
/Volumes/Volume/jwt/tracker/app/msbctracker/views.py changed, reloading.
Watching for file changes with StatReloader
/Volumes/Volume/jwt/tracker/app/msbctracker/views.py changed, reloading.
Watching for file changes with StatReloader
/Volumes/Volume/jwt/tracker/app/msbctracker/views.py changed, reloading.
Watching for file changes with StatReloader
/Volumes/Volume/jwt/tracker/app/msbctracker/views.py changed, reloading.
Watching for file changes with StatReloader
Method Not Allowed: /api/posttrack
/Volumes/Volume/jwt/tracker/app/msbctracker/views.py changed, reloading.
Watching for file changes with StatReloader
Method Not Allowed: /api/posttrack
/Volumes/Volume/jwt/tracker/app/msbctracker/urls.py changed, reloading.
Watching for file changes with StatReloader
Method Not Allowed: /api/posttrack
Method Not Allowed: /api/posttrack
/Volumes/Volume/jwt/tracker/app/msbctracker/views.py changed, reloading.
Watching for file changes with StatReloader
Method Not Allowed: /api/posttrack
Method Not Allowed: /api/posttrack
Watching for file changes with StatReloader
Method Not Allowed: /api/posttrack
Method Not Allowed: /api/posttrack
/Volumes/Volume/jwt/tracker/app/msbctracker/views.py changed, reloading.
Watching for file changes with StatReloader
/Volumes/Volume/jwt/tracker/app/msbctracker/urls.py changed, reloading.
Watching for file changes with StatReloader
Method Not Allowed: /api/posttrack
Method Not Allowed: /api/posttrack
/Volumes/Volume/jwt/tracker/app/msbctracker/urls.py changed, reloading.
Watching for file changes with StatReloader
Method Not Allowed: /api/posttrack
/Volumes/Volume/jwt/tracker/app/msbctracker/views.py changed, reloading.
Watching for file changes with StatReloader
/Volumes/Volume/jwt/tracker/app/msbctracker/views.py changed, reloading.
Watching for file changes with StatReloader
/Volumes/Volume/jwt/tracker/app/msbctracker/views.py changed, reloading.
Watching for file changes with StatReloader
Internal Server Error: /api/PostTrack
Traceback (most recent call last):
  File "/Volumes/Volume/orderc/myenv/lib/python3.10/site-packages/pandas/core/indexes/base.py", line 3803, in get_loc
    return self._engine.get_loc(casted_key)
  File "pandas/_libs/index.pyx", line 138, in pandas._libs.index.IndexEngine.get_loc
  File "pandas/_libs/index.pyx", line 165, in pandas._libs.index.IndexEngine.get_loc
  File "pandas/_libs/hashtable_class_helper.pxi", line 5745, in pandas._libs.hashtable.PyObjectHashTable.get_item
  File "pandas/_libs/hashtable_class_helper.pxi", line 5753, in pandas._libs.hashtable.PyObjectHashTable.get_item
KeyError: 1

The above exception was the direct cause of the following exception:

Traceback (most recent call last):
  File "/Volumes/Volume/orderc/myenv/lib/python3.10/site-packages/django/core/handlers/exception.py", line 55, in inner
    response = get_response(request)
  File "/Volumes/Volume/orderc/myenv/lib/python3.10/site-packages/django/core/handlers/base.py", line 197, in _get_response
    response = wrapped_callback(request, *callback_args, **callback_kwargs)
  File "/Volumes/Volume/orderc/myenv/lib/python3.10/site-packages/django/views/decorators/csrf.py", line 54, in wrapped_view
    return view_func(*args, **kwargs)
  File "/Volumes/Volume/orderc/myenv/lib/python3.10/site-packages/django/views/generic/base.py", line 103, in view
    return self.dispatch(request, *args, **kwargs)
  File "/Volumes/Volume/orderc/myenv/lib/python3.10/site-packages/rest_framework/views.py", line 509, in dispatch
    response = self.handle_exception(exc)
  File "/Volumes/Volume/orderc/myenv/lib/python3.10/site-packages/rest_framework/views.py", line 469, in handle_exception
    self.raise_uncaught_exception(exc)
  File "/Volumes/Volume/orderc/myenv/lib/python3.10/site-packages/rest_framework/views.py", line 480, in raise_uncaught_exception
    raise exc
  File "/Volumes/Volume/orderc/myenv/lib/python3.10/site-packages/rest_framework/views.py", line 506, in dispatch
    response = handler(request, *args, **kwargs)
  File "/Volumes/Volume/jwt/tracker/app/msbctracker/views.py", line 733, in post
    print('HIIIIIIIIIIOOO',excel_data_df[1])
  File "/Volumes/Volume/orderc/myenv/lib/python3.10/site-packages/pandas/core/frame.py", line 3804, in __getitem__
    indexer = self.columns.get_loc(key)
  File "/Volumes/Volume/orderc/myenv/lib/python3.10/site-packages/pandas/core/indexes/base.py", line 3805, in get_loc
    raise KeyError(key) from err
KeyError: 1
/Volumes/Volume/jwt/tracker/app/msbctracker/views.py changed, reloading.
Watching for file changes with StatReloader
Internal Server Error: /api/PostTrack
Traceback (most recent call last):
  File "/Volumes/Volume/orderc/myenv/lib/python3.10/site-packages/pandas/core/indexes/base.py", line 3803, in get_loc
    return self._engine.get_loc(casted_key)
  File "pandas/_libs/index.pyx", line 138, in pandas._libs.index.IndexEngine.get_loc
  File "pandas/_libs/index.pyx", line 165, in pandas._libs.index.IndexEngine.get_loc
  File "pandas/_libs/hashtable_class_helper.pxi", line 5745, in pandas._libs.hashtable.PyObjectHashTable.get_item
  File "pandas/_libs/hashtable_class_helper.pxi", line 5753, in pandas._libs.hashtable.PyObjectHashTable.get_item
KeyError: 'tracking_number'

The above exception was the direct cause of the following exception:

Traceback (most recent call last):
  File "/Volumes/Volume/orderc/myenv/lib/python3.10/site-packages/django/core/handlers/exception.py", line 55, in inner
    response = get_response(request)
  File "/Volumes/Volume/orderc/myenv/lib/python3.10/site-packages/django/core/handlers/base.py", line 197, in _get_response
    response = wrapped_callback(request, *callback_args, **callback_kwargs)
  File "/Volumes/Volume/orderc/myenv/lib/python3.10/site-packages/django/views/decorators/csrf.py", line 54, in wrapped_view
    return view_func(*args, **kwargs)
  File "/Volumes/Volume/orderc/myenv/lib/python3.10/site-packages/django/views/generic/base.py", line 103, in view
    return self.dispatch(request, *args, **kwargs)
  File "/Volumes/Volume/orderc/myenv/lib/python3.10/site-packages/rest_framework/views.py", line 509, in dispatch
    response = self.handle_exception(exc)
  File "/Volumes/Volume/orderc/myenv/lib/python3.10/site-packages/rest_framework/views.py", line 469, in handle_exception
    self.raise_uncaught_exception(exc)
  File "/Volumes/Volume/orderc/myenv/lib/python3.10/site-packages/rest_framework/views.py", line 480, in raise_uncaught_exception
    raise exc
  File "/Volumes/Volume/orderc/myenv/lib/python3.10/site-packages/rest_framework/views.py", line 506, in dispatch
    response = handler(request, *args, **kwargs)
  File "/Volumes/Volume/jwt/tracker/app/msbctracker/views.py", line 735, in post
    p = excel_data_df['tracking_number'][ind]
  File "/Volumes/Volume/orderc/myenv/lib/python3.10/site-packages/pandas/core/frame.py", line 3804, in __getitem__
    indexer = self.columns.get_loc(key)
  File "/Volumes/Volume/orderc/myenv/lib/python3.10/site-packages/pandas/core/indexes/base.py", line 3805, in get_loc
    raise KeyError(key) from err
KeyError: 'tracking_number'
/Volumes/Volume/jwt/tracker/app/msbctracker/views.py changed, reloading.
Watching for file changes with StatReloader
/Volumes/Volume/jwt/tracker/app/msbctracker/views.py changed, reloading.
Watching for file changes with StatReloader
/Volumes/Volume/jwt/tracker/app/msbctracker/functions.py changed, reloading.
Watching for file changes with StatReloader
Internal Server Error: /api/TrackingDetails
Traceback (most recent call last):
  File "/Volumes/Volume/orderc/myenv/lib/python3.10/site-packages/django/core/handlers/exception.py", line 55, in inner
    response = get_response(request)
  File "/Volumes/Volume/orderc/myenv/lib/python3.10/site-packages/django/core/handlers/base.py", line 197, in _get_response
    response = wrapped_callback(request, *callback_args, **callback_kwargs)
  File "/Volumes/Volume/orderc/myenv/lib/python3.10/site-packages/django/views/decorators/csrf.py", line 54, in wrapped_view
    return view_func(*args, **kwargs)
  File "/Volumes/Volume/orderc/myenv/lib/python3.10/site-packages/django/views/generic/base.py", line 103, in view
    return self.dispatch(request, *args, **kwargs)
  File "/Volumes/Volume/orderc/myenv/lib/python3.10/site-packages/rest_framework/views.py", line 509, in dispatch
    response = self.handle_exception(exc)
  File "/Volumes/Volume/orderc/myenv/lib/python3.10/site-packages/rest_framework/views.py", line 469, in handle_exception
    self.raise_uncaught_exception(exc)
  File "/Volumes/Volume/orderc/myenv/lib/python3.10/site-packages/rest_framework/views.py", line 480, in raise_uncaught_exception
    raise exc
  File "/Volumes/Volume/orderc/myenv/lib/python3.10/site-packages/rest_framework/views.py", line 506, in dispatch
    response = handler(request, *args, **kwargs)
  File "/Volumes/Volume/jwt/tracker/app/msbctracker/views.py", line 973, in patch
    hold_status = Tracker.objects.filter(tracking_number=t).values_list('status')[0][0]
  File "/Volumes/Volume/orderc/myenv/lib/python3.10/site-packages/django/db/models/query.py", line 446, in __getitem__
    return qs._result_cache[0]
IndexError: list index out of range
/Volumes/Volume/jwt/tracker/app/msbctracker/views.py changed, reloading.
Watching for file changes with StatReloader
Internal Server Error: /api/TrackingDetails
Traceback (most recent call last):
  File "/Volumes/Volume/orderc/myenv/lib/python3.10/site-packages/django/core/handlers/exception.py", line 55, in inner
    response = get_response(request)
  File "/Volumes/Volume/orderc/myenv/lib/python3.10/site-packages/django/core/handlers/base.py", line 197, in _get_response
    response = wrapped_callback(request, *callback_args, **callback_kwargs)
  File "/Volumes/Volume/orderc/myenv/lib/python3.10/site-packages/django/views/decorators/csrf.py", line 54, in wrapped_view
    return view_func(*args, **kwargs)
  File "/Volumes/Volume/orderc/myenv/lib/python3.10/site-packages/django/views/generic/base.py", line 103, in view
    return self.dispatch(request, *args, **kwargs)
  File "/Volumes/Volume/orderc/myenv/lib/python3.10/site-packages/rest_framework/views.py", line 509, in dispatch
    response = self.handle_exception(exc)
  File "/Volumes/Volume/orderc/myenv/lib/python3.10/site-packages/rest_framework/views.py", line 469, in handle_exception
    self.raise_uncaught_exception(exc)
  File "/Volumes/Volume/orderc/myenv/lib/python3.10/site-packages/rest_framework/views.py", line 480, in raise_uncaught_exception
    raise exc
  File "/Volumes/Volume/orderc/myenv/lib/python3.10/site-packages/rest_framework/views.py", line 506, in dispatch
    response = handler(request, *args, **kwargs)
  File "/Volumes/Volume/jwt/tracker/app/msbctracker/views.py", line 973, in patch
    hold_status = Tracker.objects.filter(tracking_number=t).values_list('status')[0][0]
  File "/Volumes/Volume/orderc/myenv/lib/python3.10/site-packages/django/db/models/query.py", line 446, in __getitem__
    return qs._result_cache[0]
IndexError: list index out of range
/Volumes/Volume/jwt/tracker/app/msbctracker/views.py changed, reloading.
Watching for file changes with StatReloader
Watching for file changes with StatReloader
/Volumes/Volume/jwt/tracker/app/msbctracker/views.py changed, reloading.
Watching for file changes with StatReloader
/Volumes/Volume/jwt/tracker/app/msbctracker/views.py changed, reloading.
Watching for file changes with StatReloader
Watching for file changes with StatReloader
Watching for file changes with StatReloader
Watching for file changes with StatReloader
Watching for file changes with StatReloader
/Volumes/Volume/jwt/tracker/app/msbctracker/views.py changed, reloading.
Watching for file changes with StatReloader
/Volumes/Volume/jwt/tracker/app/msbctracker/views.py changed, reloading.
Watching for file changes with StatReloader
/Volumes/Volume/jwt/tracker/app/msbctracker/views.py changed, reloading.
Watching for file changes with StatReloader
/Volumes/Volume/jwt/tracker/app/msbctracker/views.py changed, reloading.
Watching for file changes with StatReloader
/Volumes/Volume/jwt/tracker/app/msbctracker/views.py changed, reloading.
Watching for file changes with StatReloader
/Volumes/Volume/jwt/tracker/app/msbctracker/views.py changed, reloading.
Watching for file changes with StatReloader
/Volumes/Volume/jwt/tracker/app/msbctracker/views.py changed, reloading.
Watching for file changes with StatReloader
/Volumes/Volume/jwt/tracker/app/msbctracker/views.py changed, reloading.
Watching for file changes with StatReloader
/Volumes/Volume/jwt/tracker/app/msbctracker/views.py changed, reloading.
Watching for file changes with StatReloader
/Volumes/Volume/jwt/tracker/app/msbctracker/views.py changed, reloading.
Watching for file changes with StatReloader
Method Not Allowed: /api/TrackingDetails
/Volumes/Volume/jwt/tracker/app/msbctracker/functions.py changed, reloading.
Watching for file changes with StatReloader
/Volumes/Volume/jwt/tracker/app/msbctracker/functions.py changed, reloading.
Watching for file changes with StatReloader
/Volumes/Volume/jwt/tracker/app/msbctracker/functions.py changed, reloading.
Watching for file changes with StatReloader
/Volumes/Volume/jwt/tracker/app/msbctracker/functions.py changed, reloading.
Watching for file changes with StatReloader
/Volumes/Volume/jwt/tracker/app/msbctracker/functions.py changed, reloading.
Watching for file changes with StatReloader
/Volumes/Volume/jwt/tracker/app/msbctracker/functions.py changed, reloading.
Watching for file changes with StatReloader
Internal Server Error: /api/PostTrack
Traceback (most recent call last):
  File "/Volumes/Volume/orderc/myenv/lib/python3.10/site-packages/django/core/handlers/exception.py", line 55, in inner
    response = get_response(request)
  File "/Volumes/Volume/orderc/myenv/lib/python3.10/site-packages/django/core/handlers/base.py", line 197, in _get_response
    response = wrapped_callback(request, *callback_args, **callback_kwargs)
  File "/Volumes/Volume/orderc/myenv/lib/python3.10/site-packages/django/views/decorators/csrf.py", line 54, in wrapped_view
    return view_func(*args, **kwargs)
  File "/Volumes/Volume/orderc/myenv/lib/python3.10/site-packages/django/views/generic/base.py", line 103, in view
    return self.dispatch(request, *args, **kwargs)
  File "/Volumes/Volume/orderc/myenv/lib/python3.10/site-packages/rest_framework/views.py", line 509, in dispatch
    response = self.handle_exception(exc)
  File "/Volumes/Volume/orderc/myenv/lib/python3.10/site-packages/rest_framework/views.py", line 469, in handle_exception
    self.raise_uncaught_exception(exc)
  File "/Volumes/Volume/orderc/myenv/lib/python3.10/site-packages/rest_framework/views.py", line 480, in raise_uncaught_exception
    raise exc
  File "/Volumes/Volume/orderc/myenv/lib/python3.10/site-packages/rest_framework/views.py", line 506, in dispatch
    response = handler(request, *args, **kwargs)
  File "/Volumes/Volume/jwt/tracker/app/msbctracker/views.py", line 737, in post
    numbers(p)
  File "/Volumes/Volume/jwt/tracker/app/msbctracker/functions.py", line 29, in numbers
    response = requests.post(api_url, headers=headers,body=body)
  File "/Volumes/Volume/orderc/myenv/lib/python3.10/site-packages/requests/api.py", line 115, in post
    return request("post", url, data=data, json=json, **kwargs)
  File "/Volumes/Volume/orderc/myenv/lib/python3.10/site-packages/requests/api.py", line 59, in request
    return session.request(method=method, url=url, **kwargs)
TypeError: Session.request() got an unexpected keyword argument 'body'
/Volumes/Volume/jwt/tracker/app/msbctracker/functions.py changed, reloading.
Watching for file changes with StatReloader
Internal Server Error: /api/TrackingDetails
Traceback (most recent call last):
  File "/Volumes/Volume/orderc/myenv/lib/python3.10/site-packages/django/core/handlers/exception.py", line 55, in inner
    response = get_response(request)
  File "/Volumes/Volume/orderc/myenv/lib/python3.10/site-packages/django/core/handlers/base.py", line 197, in _get_response
    response = wrapped_callback(request, *callback_args, **callback_kwargs)
  File "/Volumes/Volume/orderc/myenv/lib/python3.10/site-packages/django/views/decorators/csrf.py", line 54, in wrapped_view
    return view_func(*args, **kwargs)
  File "/Volumes/Volume/orderc/myenv/lib/python3.10/site-packages/django/views/generic/base.py", line 103, in view
    return self.dispatch(request, *args, **kwargs)
  File "/Volumes/Volume/orderc/myenv/lib/python3.10/site-packages/rest_framework/views.py", line 509, in dispatch
    response = self.handle_exception(exc)
  File "/Volumes/Volume/orderc/myenv/lib/python3.10/site-packages/rest_framework/views.py", line 469, in handle_exception
    self.raise_uncaught_exception(exc)
  File "/Volumes/Volume/orderc/myenv/lib/python3.10/site-packages/rest_framework/views.py", line 480, in raise_uncaught_exception
    raise exc
  File "/Volumes/Volume/orderc/myenv/lib/python3.10/site-packages/rest_framework/views.py", line 506, in dispatch
    response = handler(request, *args, **kwargs)
  File "/Volumes/Volume/jwt/tracker/app/msbctracker/views.py", line 912, in patch
    tracking_info = i['destination_info']['trackinfo']
KeyError: 'destination_info'
Internal Server Error: /api/TrackingDetails
Traceback (most recent call last):
  File "/Volumes/Volume/orderc/myenv/lib/python3.10/site-packages/django/core/handlers/exception.py", line 55, in inner
    response = get_response(request)
  File "/Volumes/Volume/orderc/myenv/lib/python3.10/site-packages/django/core/handlers/base.py", line 197, in _get_response
    response = wrapped_callback(request, *callback_args, **callback_kwargs)
  File "/Volumes/Volume/orderc/myenv/lib/python3.10/site-packages/django/views/decorators/csrf.py", line 54, in wrapped_view
    return view_func(*args, **kwargs)
  File "/Volumes/Volume/orderc/myenv/lib/python3.10/site-packages/django/views/generic/base.py", line 103, in view
    return self.dispatch(request, *args, **kwargs)
  File "/Volumes/Volume/orderc/myenv/lib/python3.10/site-packages/rest_framework/views.py", line 509, in dispatch
    response = self.handle_exception(exc)
  File "/Volumes/Volume/orderc/myenv/lib/python3.10/site-packages/rest_framework/views.py", line 469, in handle_exception
    self.raise_uncaught_exception(exc)
  File "/Volumes/Volume/orderc/myenv/lib/python3.10/site-packages/rest_framework/views.py", line 480, in raise_uncaught_exception
    raise exc
  File "/Volumes/Volume/orderc/myenv/lib/python3.10/site-packages/rest_framework/views.py", line 506, in dispatch
    response = handler(request, *args, **kwargs)
  File "/Volumes/Volume/jwt/tracker/app/msbctracker/views.py", line 912, in patch
    tracking_info = i['destination_info']['trackinfo']
KeyError: 'destination_info'
Internal Server Error: /api/TrackingDetails
Traceback (most recent call last):
  File "/Volumes/Volume/orderc/myenv/lib/python3.10/site-packages/django/core/handlers/exception.py", line 55, in inner
    response = get_response(request)
  File "/Volumes/Volume/orderc/myenv/lib/python3.10/site-packages/django/core/handlers/base.py", line 197, in _get_response
    response = wrapped_callback(request, *callback_args, **callback_kwargs)
  File "/Volumes/Volume/orderc/myenv/lib/python3.10/site-packages/django/views/decorators/csrf.py", line 54, in wrapped_view
    return view_func(*args, **kwargs)
  File "/Volumes/Volume/orderc/myenv/lib/python3.10/site-packages/django/views/generic/base.py", line 103, in view
    return self.dispatch(request, *args, **kwargs)
  File "/Volumes/Volume/orderc/myenv/lib/python3.10/site-packages/rest_framework/views.py", line 509, in dispatch
    response = self.handle_exception(exc)
  File "/Volumes/Volume/orderc/myenv/lib/python3.10/site-packages/rest_framework/views.py", line 469, in handle_exception
    self.raise_uncaught_exception(exc)
  File "/Volumes/Volume/orderc/myenv/lib/python3.10/site-packages/rest_framework/views.py", line 480, in raise_uncaught_exception
    raise exc
  File "/Volumes/Volume/orderc/myenv/lib/python3.10/site-packages/rest_framework/views.py", line 506, in dispatch
    response = handler(request, *args, **kwargs)
  File "/Volumes/Volume/jwt/tracker/app/msbctracker/views.py", line 912, in patch
    tracking_info = i['destination_info']['trackinfo']
KeyError: 'destination_info'
Internal Server Error: /api/TrackingDetails
Traceback (most recent call last):
  File "/Volumes/Volume/orderc/myenv/lib/python3.10/site-packages/django/core/handlers/exception.py", line 55, in inner
    response = get_response(request)
  File "/Volumes/Volume/orderc/myenv/lib/python3.10/site-packages/django/core/handlers/base.py", line 197, in _get_response
    response = wrapped_callback(request, *callback_args, **callback_kwargs)
  File "/Volumes/Volume/orderc/myenv/lib/python3.10/site-packages/django/views/decorators/csrf.py", line 54, in wrapped_view
    return view_func(*args, **kwargs)
  File "/Volumes/Volume/orderc/myenv/lib/python3.10/site-packages/django/views/generic/base.py", line 103, in view
    return self.dispatch(request, *args, **kwargs)
  File "/Volumes/Volume/orderc/myenv/lib/python3.10/site-packages/rest_framework/views.py", line 509, in dispatch
    response = self.handle_exception(exc)
  File "/Volumes/Volume/orderc/myenv/lib/python3.10/site-packages/rest_framework/views.py", line 469, in handle_exception
    self.raise_uncaught_exception(exc)
  File "/Volumes/Volume/orderc/myenv/lib/python3.10/site-packages/rest_framework/views.py", line 480, in raise_uncaught_exception
    raise exc
  File "/Volumes/Volume/orderc/myenv/lib/python3.10/site-packages/rest_framework/views.py", line 506, in dispatch
    response = handler(request, *args, **kwargs)
  File "/Volumes/Volume/jwt/tracker/app/msbctracker/views.py", line 912, in patch
    tracking_info = i['destination_info']['trackinfo']
KeyError: 'destination_info'
/Volumes/Volume/jwt/tracker/app/msbctracker/views.py changed, reloading.
Watching for file changes with StatReloader
Internal Server Error: /api/TrackingDetails
Traceback (most recent call last):
  File "/Volumes/Volume/orderc/myenv/lib/python3.10/site-packages/django/core/handlers/exception.py", line 55, in inner
    response = get_response(request)
  File "/Volumes/Volume/orderc/myenv/lib/python3.10/site-packages/django/core/handlers/base.py", line 197, in _get_response
    response = wrapped_callback(request, *callback_args, **callback_kwargs)
  File "/Volumes/Volume/orderc/myenv/lib/python3.10/site-packages/django/views/decorators/csrf.py", line 54, in wrapped_view
    return view_func(*args, **kwargs)
  File "/Volumes/Volume/orderc/myenv/lib/python3.10/site-packages/django/views/generic/base.py", line 103, in view
    return self.dispatch(request, *args, **kwargs)
  File "/Volumes/Volume/orderc/myenv/lib/python3.10/site-packages/rest_framework/views.py", line 509, in dispatch
    response = self.handle_exception(exc)
  File "/Volumes/Volume/orderc/myenv/lib/python3.10/site-packages/rest_framework/views.py", line 469, in handle_exception
    self.raise_uncaught_exception(exc)
  File "/Volumes/Volume/orderc/myenv/lib/python3.10/site-packages/rest_framework/views.py", line 480, in raise_uncaught_exception
    raise exc
  File "/Volumes/Volume/orderc/myenv/lib/python3.10/site-packages/rest_framework/views.py", line 506, in dispatch
    response = handler(request, *args, **kwargs)
  File "/Volumes/Volume/jwt/tracker/app/msbctracker/views.py", line 912, in patch
    tracking_info = i['destination_info']['trackinfo']
KeyError: 'destination_info'
/Volumes/Volume/jwt/tracker/app/msbctracker/views.py changed, reloading.
Watching for file changes with StatReloader
Internal Server Error: /api/TrackingDetails
Traceback (most recent call last):
  File "/Volumes/Volume/orderc/myenv/lib/python3.10/site-packages/django/core/handlers/exception.py", line 55, in inner
    response = get_response(request)
  File "/Volumes/Volume/orderc/myenv/lib/python3.10/site-packages/django/core/handlers/base.py", line 197, in _get_response
    response = wrapped_callback(request, *callback_args, **callback_kwargs)
  File "/Volumes/Volume/orderc/myenv/lib/python3.10/site-packages/django/views/decorators/csrf.py", line 54, in wrapped_view
    return view_func(*args, **kwargs)
  File "/Volumes/Volume/orderc/myenv/lib/python3.10/site-packages/django/views/generic/base.py", line 103, in view
    return self.dispatch(request, *args, **kwargs)
  File "/Volumes/Volume/orderc/myenv/lib/python3.10/site-packages/rest_framework/views.py", line 509, in dispatch
    response = self.handle_exception(exc)
  File "/Volumes/Volume/orderc/myenv/lib/python3.10/site-packages/rest_framework/views.py", line 469, in handle_exception
    self.raise_uncaught_exception(exc)
  File "/Volumes/Volume/orderc/myenv/lib/python3.10/site-packages/rest_framework/views.py", line 480, in raise_uncaught_exception
    raise exc
  File "/Volumes/Volume/orderc/myenv/lib/python3.10/site-packages/rest_framework/views.py", line 506, in dispatch
    response = handler(request, *args, **kwargs)
  File "/Volumes/Volume/jwt/tracker/app/msbctracker/views.py", line 913, in patch
    tracking_info = i['destination_info']['trackinfo']
KeyError: 'destination_info'
Watching for file changes with StatReloader
Internal Server Error: /api/TrackingDetails
Traceback (most recent call last):
  File "/Volumes/Volume/orderc/myenv/lib/python3.10/site-packages/django/core/handlers/exception.py", line 55, in inner
    response = get_response(request)
  File "/Volumes/Volume/orderc/myenv/lib/python3.10/site-packages/django/core/handlers/base.py", line 197, in _get_response
    response = wrapped_callback(request, *callback_args, **callback_kwargs)
  File "/Volumes/Volume/orderc/myenv/lib/python3.10/site-packages/django/views/decorators/csrf.py", line 54, in wrapped_view
    return view_func(*args, **kwargs)
  File "/Volumes/Volume/orderc/myenv/lib/python3.10/site-packages/django/views/generic/base.py", line 103, in view
    return self.dispatch(request, *args, **kwargs)
  File "/Volumes/Volume/orderc/myenv/lib/python3.10/site-packages/rest_framework/views.py", line 509, in dispatch
    response = self.handle_exception(exc)
  File "/Volumes/Volume/orderc/myenv/lib/python3.10/site-packages/rest_framework/views.py", line 469, in handle_exception
    self.raise_uncaught_exception(exc)
  File "/Volumes/Volume/orderc/myenv/lib/python3.10/site-packages/rest_framework/views.py", line 480, in raise_uncaught_exception
    raise exc
  File "/Volumes/Volume/orderc/myenv/lib/python3.10/site-packages/rest_framework/views.py", line 506, in dispatch
    response = handler(request, *args, **kwargs)
  File "/Volumes/Volume/jwt/tracker/app/msbctracker/views.py", line 913, in patch
    tracking_info = i['destination_info']['trackinfo']
KeyError: 'destination_info'
/Volumes/Volume/jwt/tracker/app/msbctracker/functions.py changed, reloading.
Watching for file changes with StatReloader
/Volumes/Volume/jwt/tracker/app/msbctracker/functions.py changed, reloading.
Watching for file changes with StatReloader
Watching for file changes with StatReloader
/Volumes/Volume/jwt/tracker/app/msbctracker/functions.py changed, reloading.
Watching for file changes with StatReloader
Internal Server Error: /api/PostTrack
Traceback (most recent call last):
  File "/Volumes/Volume/orderc/myenv/lib/python3.10/site-packages/django/core/handlers/exception.py", line 55, in inner
    response = get_response(request)
  File "/Volumes/Volume/orderc/myenv/lib/python3.10/site-packages/django/core/handlers/base.py", line 197, in _get_response
    response = wrapped_callback(request, *callback_args, **callback_kwargs)
  File "/Volumes/Volume/orderc/myenv/lib/python3.10/site-packages/django/views/decorators/csrf.py", line 54, in wrapped_view
    return view_func(*args, **kwargs)
  File "/Volumes/Volume/orderc/myenv/lib/python3.10/site-packages/django/views/generic/base.py", line 103, in view
    return self.dispatch(request, *args, **kwargs)
  File "/Volumes/Volume/orderc/myenv/lib/python3.10/site-packages/rest_framework/views.py", line 509, in dispatch
    response = self.handle_exception(exc)
  File "/Volumes/Volume/orderc/myenv/lib/python3.10/site-packages/rest_framework/views.py", line 469, in handle_exception
    self.raise_uncaught_exception(exc)
  File "/Volumes/Volume/orderc/myenv/lib/python3.10/site-packages/rest_framework/views.py", line 480, in raise_uncaught_exception
    raise exc
  File "/Volumes/Volume/orderc/myenv/lib/python3.10/site-packages/rest_framework/views.py", line 506, in dispatch
    response = handler(request, *args, **kwargs)
  File "/Volumes/Volume/jwt/tracker/app/msbctracker/views.py", line 737, in post
    numbers(p)
  File "/Volumes/Volume/jwt/tracker/app/msbctracker/functions.py", line 18, in numbers
    body.append(json)
NameError: name 'body' is not defined
/Volumes/Volume/jwt/tracker/app/msbctracker/functions.py changed, reloading.
Watching for file changes with StatReloader
Watching for file changes with StatReloader
/Volumes/Volume/jwt/tracker/app/msbctracker/functions.py changed, reloading.
Watching for file changes with StatReloader
/Volumes/Volume/jwt/tracker/app/msbctracker/functions.py changed, reloading.
Watching for file changes with StatReloader
/Volumes/Volume/jwt/tracker/app/msbctracker/functions.py changed, reloading.
Watching for file changes with StatReloader
/Volumes/Volume/jwt/tracker/app/msbctracker/functions.py changed, reloading.
Watching for file changes with StatReloader
/Volumes/Volume/jwt/tracker/app/msbctracker/functions.py changed, reloading.
Watching for file changes with StatReloader
/Volumes/Volume/jwt/tracker/app/msbctracker/functions.py changed, reloading.
Watching for file changes with StatReloader
/Volumes/Volume/jwt/tracker/app/msbctracker/functions.py changed, reloading.
Watching for file changes with StatReloader
/Volumes/Volume/jwt/tracker/app/msbctracker/functions.py changed, reloading.
Watching for file changes with StatReloader
/Volumes/Volume/jwt/tracker/app/msbctracker/functions.py changed, reloading.
Watching for file changes with StatReloader
/Volumes/Volume/jwt/tracker/app/msbctracker/functions.py changed, reloading.
Watching for file changes with StatReloader
/Volumes/Volume/jwt/tracker/app/msbctracker/functions.py changed, reloading.
Watching for file changes with StatReloader
/Volumes/Volume/jwt/tracker/app/msbctracker/functions.py changed, reloading.
Watching for file changes with StatReloader
/Volumes/Volume/jwt/tracker/app/msbctracker/functions.py changed, reloading.
Watching for file changes with StatReloader
/Volumes/Volume/jwt/tracker/app/msbctracker/functions.py changed, reloading.
Watching for file changes with StatReloader
/Volumes/Volume/jwt/tracker/app/msbctracker/functions.py changed, reloading.
Watching for file changes with StatReloader
/Volumes/Volume/jwt/tracker/app/msbctracker/views.py changed, reloading.
Watching for file changes with StatReloader
/Volumes/Volume/jwt/tracker/app/msbctracker/functions.py changed, reloading.
Watching for file changes with StatReloader
/Volumes/Volume/jwt/tracker/app/msbctracker/functions.py changed, reloading.
Watching for file changes with StatReloader
/Volumes/Volume/jwt/tracker/app/msbctracker/views.py changed, reloading.
Watching for file changes with StatReloader
/Volumes/Volume/jwt/tracker/app/msbctracker/views.py changed, reloading.
Watching for file changes with StatReloader
/Volumes/Volume/jwt/tracker/app/msbctracker/views.py changed, reloading.
Watching for file changes with StatReloader
/Volumes/Volume/jwt/tracker/app/msbctracker/views.py changed, reloading.
Watching for file changes with StatReloader
/Volumes/Volume/jwt/tracker/app/msbctracker/views.py changed, reloading.
Watching for file changes with StatReloader
/Volumes/Volume/jwt/tracker/app/msbctracker/views.py changed, reloading.
Watching for file changes with StatReloader
/Volumes/Volume/jwt/tracker/app/msbctracker/functions.py changed, reloading.
Watching for file changes with StatReloader
/Volumes/Volume/jwt/tracker/app/msbctracker/views.py changed, reloading.
Watching for file changes with StatReloader
/Volumes/Volume/jwt/tracker/app/msbctracker/models.py changed, reloading.
Watching for file changes with StatReloader
/Volumes/Volume/jwt/tracker/app/tracker/settings.py changed, reloading.
Watching for file changes with StatReloader
Watching for file changes with StatReloader
Watching for file changes with StatReloader
Watching for file changes with StatReloader
Watching for file changes with StatReloader
Watching for file changes with StatReloader
Watching for file changes with StatReloader
Watching for file changes with StatReloader
/Volumes/Volume/jwt/tracker/app/msbctracker/views.py changed, reloading.
Watching for file changes with StatReloader
Watching for file changes with StatReloader
Watching for file changes with StatReloader
Watching for file changes with StatReloader
Watching for file changes with StatReloader
Invalid HTTP_HOST header: '127.0.0.1:8000'. You may need to add '127.0.0.1' to ALLOWED_HOSTS.
Traceback (most recent call last):
  File "/Library/Frameworks/Python.framework/Versions/3.10/lib/python3.10/site-packages/django/core/handlers/exception.py", line 55, in inner
    response = get_response(request)
  File "/Library/Frameworks/Python.framework/Versions/3.10/lib/python3.10/site-packages/django/utils/deprecation.py", line 135, in __call__
    response = self.process_request(request)
  File "/Library/Frameworks/Python.framework/Versions/3.10/lib/python3.10/site-packages/django/middleware/security.py", line 28, in process_request
    host = self.redirect_host or request.get_host()
  File "/Library/Frameworks/Python.framework/Versions/3.10/lib/python3.10/site-packages/django/http/request.py", line 148, in get_host
    raise DisallowedHost(msg)
django.core.exceptions.DisallowedHost: Invalid HTTP_HOST header: '127.0.0.1:8000'. You may need to add '127.0.0.1' to ALLOWED_HOSTS.
Bad Request: /api/PostTrack
/Volumes/Volume/untitled folder 2/ct/app/tracker/settings.py changed, reloading.
Watching for file changes with StatReloader
/Volumes/Volume/untitled folder 2/ct/app/tracker/settings.py changed, reloading.
Watching for file changes with StatReloader
/Volumes/Volume/untitled folder 2/ct/app/tracker/settings.py changed, reloading.
Watching for file changes with StatReloader
Internal Server Error: /api/PostTrack
Traceback (most recent call last):
  File "/Library/Frameworks/Python.framework/Versions/3.10/lib/python3.10/site-packages/pandas/compat/_optional.py", line 141, in import_optional_dependency
    module = importlib.import_module(name)
  File "/Library/Frameworks/Python.framework/Versions/3.10/lib/python3.10/importlib/__init__.py", line 126, in import_module
    return _bootstrap._gcd_import(name[level:], package, level)
  File "<frozen importlib._bootstrap>", line 1050, in _gcd_import
  File "<frozen importlib._bootstrap>", line 1027, in _find_and_load
  File "<frozen importlib._bootstrap>", line 1004, in _find_and_load_unlocked
ModuleNotFoundError: No module named 'openpyxl'

During handling of the above exception, another exception occurred:

Traceback (most recent call last):
  File "/Library/Frameworks/Python.framework/Versions/3.10/lib/python3.10/site-packages/django/core/handlers/exception.py", line 55, in inner
    response = get_response(request)
  File "/Library/Frameworks/Python.framework/Versions/3.10/lib/python3.10/site-packages/django/core/handlers/base.py", line 197, in _get_response
    response = wrapped_callback(request, *callback_args, **callback_kwargs)
  File "/Library/Frameworks/Python.framework/Versions/3.10/lib/python3.10/site-packages/django/views/decorators/csrf.py", line 54, in wrapped_view
    return view_func(*args, **kwargs)
  File "/Library/Frameworks/Python.framework/Versions/3.10/lib/python3.10/site-packages/django/views/generic/base.py", line 103, in view
    return self.dispatch(request, *args, **kwargs)
  File "/Library/Frameworks/Python.framework/Versions/3.10/lib/python3.10/site-packages/rest_framework/views.py", line 509, in dispatch
    response = self.handle_exception(exc)
  File "/Library/Frameworks/Python.framework/Versions/3.10/lib/python3.10/site-packages/rest_framework/views.py", line 469, in handle_exception
    self.raise_uncaught_exception(exc)
  File "/Library/Frameworks/Python.framework/Versions/3.10/lib/python3.10/site-packages/rest_framework/views.py", line 480, in raise_uncaught_exception
    raise exc
  File "/Library/Frameworks/Python.framework/Versions/3.10/lib/python3.10/site-packages/rest_framework/views.py", line 506, in dispatch
    response = handler(request, *args, **kwargs)
  File "/Volumes/Volume/untitled folder 2/ct/app/msbctracker/views.py", line 731, in post
    excel_data_df = pandas.read_excel(allimages, sheet_name='Sheet1')
  File "/Library/Frameworks/Python.framework/Versions/3.10/lib/python3.10/site-packages/pandas/util/_decorators.py", line 211, in wrapper
    return func(*args, **kwargs)
  File "/Library/Frameworks/Python.framework/Versions/3.10/lib/python3.10/site-packages/pandas/util/_decorators.py", line 331, in wrapper
    return func(*args, **kwargs)
  File "/Library/Frameworks/Python.framework/Versions/3.10/lib/python3.10/site-packages/pandas/io/excel/_base.py", line 482, in read_excel
    io = ExcelFile(io, storage_options=storage_options, engine=engine)
  File "/Library/Frameworks/Python.framework/Versions/3.10/lib/python3.10/site-packages/pandas/io/excel/_base.py", line 1695, in __init__
    self._reader = self._engines[engine](self._io, storage_options=storage_options)
  File "/Library/Frameworks/Python.framework/Versions/3.10/lib/python3.10/site-packages/pandas/io/excel/_openpyxl.py", line 556, in __init__
    import_optional_dependency("openpyxl")
  File "/Library/Frameworks/Python.framework/Versions/3.10/lib/python3.10/site-packages/pandas/compat/_optional.py", line 144, in import_optional_dependency
    raise ImportError(msg)
ImportError: Missing optional dependency 'openpyxl'.  Use pip or conda to install openpyxl.
Watching for file changes with StatReloader
/Volumes/Volume/untitled folder 2/ct/app/tracker/settings.py changed, reloading.
Watching for file changes with StatReloader
/Volumes/Volume/untitled folder 2/ct/app/tracker/settings.py changed, reloading.
Watching for file changes with StatReloader
Watching for file changes with StatReloader
Watching for file changes with StatReloader
/Volumes/Volume/untitled folder 2/ct/app/tracker/settings.py changed, reloading.
Watching for file changes with StatReloader
Invalid HTTP_HOST header: '127.0.0.1:8000'. You may need to add '127.0.0.1' to ALLOWED_HOSTS.
Traceback (most recent call last):
  File "/Library/Frameworks/Python.framework/Versions/3.10/lib/python3.10/site-packages/django/core/handlers/exception.py", line 55, in inner
    response = get_response(request)
  File "/Library/Frameworks/Python.framework/Versions/3.10/lib/python3.10/site-packages/django/utils/deprecation.py", line 135, in __call__
    response = self.process_request(request)
  File "/Library/Frameworks/Python.framework/Versions/3.10/lib/python3.10/site-packages/django/middleware/common.py", line 48, in process_request
    host = request.get_host()
  File "/Library/Frameworks/Python.framework/Versions/3.10/lib/python3.10/site-packages/django/http/request.py", line 148, in get_host
    raise DisallowedHost(msg)
django.core.exceptions.DisallowedHost: Invalid HTTP_HOST header: '127.0.0.1:8000'. You may need to add '127.0.0.1' to ALLOWED_HOSTS.
Invalid HTTP_HOST header: '127.0.0.1:8000'. You may need to add '127.0.0.1' to ALLOWED_HOSTS.
Traceback (most recent call last):
  File "/Library/Frameworks/Python.framework/Versions/3.10/lib/python3.10/site-packages/django/core/handlers/exception.py", line 55, in inner
    response = get_response(request)
  File "/Library/Frameworks/Python.framework/Versions/3.10/lib/python3.10/site-packages/django/utils/deprecation.py", line 135, in __call__
    response = self.process_request(request)
  File "/Library/Frameworks/Python.framework/Versions/3.10/lib/python3.10/site-packages/django/middleware/common.py", line 48, in process_request
    host = request.get_host()
  File "/Library/Frameworks/Python.framework/Versions/3.10/lib/python3.10/site-packages/django/http/request.py", line 148, in get_host
    raise DisallowedHost(msg)
django.core.exceptions.DisallowedHost: Invalid HTTP_HOST header: '127.0.0.1:8000'. You may need to add '127.0.0.1' to ALLOWED_HOSTS.
Bad Request: /api/PostTrack
Bad Request: /api/TrackingDetails
Invalid HTTP_HOST header: '127.0.0.1:8000'. You may need to add '127.0.0.1' to ALLOWED_HOSTS.
Traceback (most recent call last):
  File "/Library/Frameworks/Python.framework/Versions/3.10/lib/python3.10/site-packages/django/core/handlers/exception.py", line 55, in inner
    response = get_response(request)
  File "/Library/Frameworks/Python.framework/Versions/3.10/lib/python3.10/site-packages/django/utils/deprecation.py", line 135, in __call__
    response = self.process_request(request)
  File "/Library/Frameworks/Python.framework/Versions/3.10/lib/python3.10/site-packages/django/middleware/common.py", line 48, in process_request
    host = request.get_host()
  File "/Library/Frameworks/Python.framework/Versions/3.10/lib/python3.10/site-packages/django/http/request.py", line 148, in get_host
    raise DisallowedHost(msg)
django.core.exceptions.DisallowedHost: Invalid HTTP_HOST header: '127.0.0.1:8000'. You may need to add '127.0.0.1' to ALLOWED_HOSTS.
Invalid HTTP_HOST header: '127.0.0.1:8000'. You may need to add '127.0.0.1' to ALLOWED_HOSTS.
Traceback (most recent call last):
  File "/Library/Frameworks/Python.framework/Versions/3.10/lib/python3.10/site-packages/django/core/handlers/exception.py", line 55, in inner
    response = get_response(request)
  File "/Library/Frameworks/Python.framework/Versions/3.10/lib/python3.10/site-packages/django/utils/deprecation.py", line 135, in __call__
    response = self.process_request(request)
  File "/Library/Frameworks/Python.framework/Versions/3.10/lib/python3.10/site-packages/django/middleware/common.py", line 48, in process_request
    host = request.get_host()
  File "/Library/Frameworks/Python.framework/Versions/3.10/lib/python3.10/site-packages/django/http/request.py", line 148, in get_host
    raise DisallowedHost(msg)
django.core.exceptions.DisallowedHost: Invalid HTTP_HOST header: '127.0.0.1:8000'. You may need to add '127.0.0.1' to ALLOWED_HOSTS.
Bad Request: /api/TrackingDetails
Bad Request: /api/PostTrack
Invalid HTTP_HOST header: '127.0.0.1:8000'. You may need to add '127.0.0.1' to ALLOWED_HOSTS.
Traceback (most recent call last):
  File "/Library/Frameworks/Python.framework/Versions/3.10/lib/python3.10/site-packages/django/core/handlers/exception.py", line 55, in inner
    response = get_response(request)
  File "/Library/Frameworks/Python.framework/Versions/3.10/lib/python3.10/site-packages/django/utils/deprecation.py", line 135, in __call__
    response = self.process_request(request)
  File "/Library/Frameworks/Python.framework/Versions/3.10/lib/python3.10/site-packages/django/middleware/common.py", line 48, in process_request
    host = request.get_host()
  File "/Library/Frameworks/Python.framework/Versions/3.10/lib/python3.10/site-packages/django/http/request.py", line 148, in get_host
    raise DisallowedHost(msg)
django.core.exceptions.DisallowedHost: Invalid HTTP_HOST header: '127.0.0.1:8000'. You may need to add '127.0.0.1' to ALLOWED_HOSTS.
Invalid HTTP_HOST header: '127.0.0.1:8000'. You may need to add '127.0.0.1' to ALLOWED_HOSTS.
Traceback (most recent call last):
  File "/Library/Frameworks/Python.framework/Versions/3.10/lib/python3.10/site-packages/django/core/handlers/exception.py", line 55, in inner
    response = get_response(request)
  File "/Library/Frameworks/Python.framework/Versions/3.10/lib/python3.10/site-packages/django/utils/deprecation.py", line 135, in __call__
    response = self.process_request(request)
  File "/Library/Frameworks/Python.framework/Versions/3.10/lib/python3.10/site-packages/django/middleware/common.py", line 48, in process_request
    host = request.get_host()
  File "/Library/Frameworks/Python.framework/Versions/3.10/lib/python3.10/site-packages/django/http/request.py", line 148, in get_host
    raise DisallowedHost(msg)
django.core.exceptions.DisallowedHost: Invalid HTTP_HOST header: '127.0.0.1:8000'. You may need to add '127.0.0.1' to ALLOWED_HOSTS.
Invalid HTTP_HOST header: '127.0.0.1:8000'. You may need to add '127.0.0.1' to ALLOWED_HOSTS.
Traceback (most recent call last):
  File "/Library/Frameworks/Python.framework/Versions/3.10/lib/python3.10/site-packages/django/core/handlers/exception.py", line 55, in inner
    response = get_response(request)
  File "/Library/Frameworks/Python.framework/Versions/3.10/lib/python3.10/site-packages/django/utils/deprecation.py", line 135, in __call__
    response = self.process_request(request)
  File "/Library/Frameworks/Python.framework/Versions/3.10/lib/python3.10/site-packages/django/middleware/common.py", line 48, in process_request
    host = request.get_host()
  File "/Library/Frameworks/Python.framework/Versions/3.10/lib/python3.10/site-packages/django/http/request.py", line 148, in get_host
    raise DisallowedHost(msg)
django.core.exceptions.DisallowedHost: Invalid HTTP_HOST header: '127.0.0.1:8000'. You may need to add '127.0.0.1' to ALLOWED_HOSTS.
Bad Request: /api/PostTrack
Bad Request: /api/TrackingDetails
Bad Request: /api/PostTrack
/Volumes/Volume/untitled folder 2/ct/app/tracker/settings.py changed, reloading.
Watching for file changes with StatReloader
Internal Server Error: /api/PostTrack
Traceback (most recent call last):
  File "/Library/Frameworks/Python.framework/Versions/3.10/lib/python3.10/site-packages/django/utils/datastructures.py", line 84, in __getitem__
    list_ = super().__getitem__(key)
KeyError: 'file'

During handling of the above exception, another exception occurred:

Traceback (most recent call last):
  File "/Library/Frameworks/Python.framework/Versions/3.10/lib/python3.10/site-packages/django/core/handlers/exception.py", line 55, in inner
    response = get_response(request)
  File "/Library/Frameworks/Python.framework/Versions/3.10/lib/python3.10/site-packages/django/core/handlers/base.py", line 197, in _get_response
    response = wrapped_callback(request, *callback_args, **callback_kwargs)
  File "/Library/Frameworks/Python.framework/Versions/3.10/lib/python3.10/site-packages/django/views/decorators/csrf.py", line 54, in wrapped_view
    return view_func(*args, **kwargs)
  File "/Library/Frameworks/Python.framework/Versions/3.10/lib/python3.10/site-packages/django/views/generic/base.py", line 103, in view
    return self.dispatch(request, *args, **kwargs)
  File "/Library/Frameworks/Python.framework/Versions/3.10/lib/python3.10/site-packages/rest_framework/views.py", line 509, in dispatch
    response = self.handle_exception(exc)
  File "/Library/Frameworks/Python.framework/Versions/3.10/lib/python3.10/site-packages/rest_framework/views.py", line 469, in handle_exception
    self.raise_uncaught_exception(exc)
  File "/Library/Frameworks/Python.framework/Versions/3.10/lib/python3.10/site-packages/rest_framework/views.py", line 480, in raise_uncaught_exception
    raise exc
  File "/Library/Frameworks/Python.framework/Versions/3.10/lib/python3.10/site-packages/rest_framework/views.py", line 506, in dispatch
    response = handler(request, *args, **kwargs)
  File "/Volumes/Volume/untitled folder 2/ct/app/msbctracker/views.py", line 729, in post
    allimages = request.FILES['file']
  File "/Library/Frameworks/Python.framework/Versions/3.10/lib/python3.10/site-packages/django/utils/datastructures.py", line 86, in __getitem__
    raise MultiValueDictKeyError(key)
django.utils.datastructures.MultiValueDictKeyError: 'file'
Internal Server Error: /api/PostTrack
Traceback (most recent call last):
  File "/Library/Frameworks/Python.framework/Versions/3.10/lib/python3.10/site-packages/django/utils/datastructures.py", line 84, in __getitem__
    list_ = super().__getitem__(key)
KeyError: 'file'

During handling of the above exception, another exception occurred:

Traceback (most recent call last):
  File "/Library/Frameworks/Python.framework/Versions/3.10/lib/python3.10/site-packages/django/core/handlers/exception.py", line 55, in inner
    response = get_response(request)
  File "/Library/Frameworks/Python.framework/Versions/3.10/lib/python3.10/site-packages/django/core/handlers/base.py", line 197, in _get_response
    response = wrapped_callback(request, *callback_args, **callback_kwargs)
  File "/Library/Frameworks/Python.framework/Versions/3.10/lib/python3.10/site-packages/django/views/decorators/csrf.py", line 54, in wrapped_view
    return view_func(*args, **kwargs)
  File "/Library/Frameworks/Python.framework/Versions/3.10/lib/python3.10/site-packages/django/views/generic/base.py", line 103, in view
    return self.dispatch(request, *args, **kwargs)
  File "/Library/Frameworks/Python.framework/Versions/3.10/lib/python3.10/site-packages/rest_framework/views.py", line 509, in dispatch
    response = self.handle_exception(exc)
  File "/Library/Frameworks/Python.framework/Versions/3.10/lib/python3.10/site-packages/rest_framework/views.py", line 469, in handle_exception
    self.raise_uncaught_exception(exc)
  File "/Library/Frameworks/Python.framework/Versions/3.10/lib/python3.10/site-packages/rest_framework/views.py", line 480, in raise_uncaught_exception
    raise exc
  File "/Library/Frameworks/Python.framework/Versions/3.10/lib/python3.10/site-packages/rest_framework/views.py", line 506, in dispatch
    response = handler(request, *args, **kwargs)
  File "/Volumes/Volume/untitled folder 2/ct/app/msbctracker/views.py", line 729, in post
    allimages = request.FILES['file']
  File "/Library/Frameworks/Python.framework/Versions/3.10/lib/python3.10/site-packages/django/utils/datastructures.py", line 86, in __getitem__
    raise MultiValueDictKeyError(key)
django.utils.datastructures.MultiValueDictKeyError: 'file'
Internal Server Error: /api/PostTrack
Traceback (most recent call last):
  File "/Library/Frameworks/Python.framework/Versions/3.10/lib/python3.10/site-packages/django/utils/datastructures.py", line 84, in __getitem__
    list_ = super().__getitem__(key)
KeyError: 'file'

During handling of the above exception, another exception occurred:

Traceback (most recent call last):
  File "/Library/Frameworks/Python.framework/Versions/3.10/lib/python3.10/site-packages/django/core/handlers/exception.py", line 55, in inner
    response = get_response(request)
  File "/Library/Frameworks/Python.framework/Versions/3.10/lib/python3.10/site-packages/django/core/handlers/base.py", line 197, in _get_response
    response = wrapped_callback(request, *callback_args, **callback_kwargs)
  File "/Library/Frameworks/Python.framework/Versions/3.10/lib/python3.10/site-packages/django/views/decorators/csrf.py", line 54, in wrapped_view
    return view_func(*args, **kwargs)
  File "/Library/Frameworks/Python.framework/Versions/3.10/lib/python3.10/site-packages/django/views/generic/base.py", line 103, in view
    return self.dispatch(request, *args, **kwargs)
  File "/Library/Frameworks/Python.framework/Versions/3.10/lib/python3.10/site-packages/rest_framework/views.py", line 509, in dispatch
    response = self.handle_exception(exc)
  File "/Library/Frameworks/Python.framework/Versions/3.10/lib/python3.10/site-packages/rest_framework/views.py", line 469, in handle_exception
    self.raise_uncaught_exception(exc)
  File "/Library/Frameworks/Python.framework/Versions/3.10/lib/python3.10/site-packages/rest_framework/views.py", line 480, in raise_uncaught_exception
    raise exc
  File "/Library/Frameworks/Python.framework/Versions/3.10/lib/python3.10/site-packages/rest_framework/views.py", line 506, in dispatch
    response = handler(request, *args, **kwargs)
  File "/Volumes/Volume/untitled folder 2/ct/app/msbctracker/views.py", line 729, in post
    allimages = request.FILES['file']
  File "/Library/Frameworks/Python.framework/Versions/3.10/lib/python3.10/site-packages/django/utils/datastructures.py", line 86, in __getitem__
    raise MultiValueDictKeyError(key)
django.utils.datastructures.MultiValueDictKeyError: 'file'
Internal Server Error: /api/PostTrack
Traceback (most recent call last):
  File "/Library/Frameworks/Python.framework/Versions/3.10/lib/python3.10/site-packages/django/utils/datastructures.py", line 84, in __getitem__
    list_ = super().__getitem__(key)
KeyError: 'file'

During handling of the above exception, another exception occurred:

Traceback (most recent call last):
  File "/Library/Frameworks/Python.framework/Versions/3.10/lib/python3.10/site-packages/django/core/handlers/exception.py", line 55, in inner
    response = get_response(request)
  File "/Library/Frameworks/Python.framework/Versions/3.10/lib/python3.10/site-packages/django/core/handlers/base.py", line 197, in _get_response
    response = wrapped_callback(request, *callback_args, **callback_kwargs)
  File "/Library/Frameworks/Python.framework/Versions/3.10/lib/python3.10/site-packages/django/views/decorators/csrf.py", line 54, in wrapped_view
    return view_func(*args, **kwargs)
  File "/Library/Frameworks/Python.framework/Versions/3.10/lib/python3.10/site-packages/django/views/generic/base.py", line 103, in view
    return self.dispatch(request, *args, **kwargs)
  File "/Library/Frameworks/Python.framework/Versions/3.10/lib/python3.10/site-packages/rest_framework/views.py", line 509, in dispatch
    response = self.handle_exception(exc)
  File "/Library/Frameworks/Python.framework/Versions/3.10/lib/python3.10/site-packages/rest_framework/views.py", line 469, in handle_exception
    self.raise_uncaught_exception(exc)
  File "/Library/Frameworks/Python.framework/Versions/3.10/lib/python3.10/site-packages/rest_framework/views.py", line 480, in raise_uncaught_exception
    raise exc
  File "/Library/Frameworks/Python.framework/Versions/3.10/lib/python3.10/site-packages/rest_framework/views.py", line 506, in dispatch
    response = handler(request, *args, **kwargs)
  File "/Volumes/Volume/untitled folder 2/ct/app/msbctracker/views.py", line 729, in post
    allimages = request.FILES['file']
  File "/Library/Frameworks/Python.framework/Versions/3.10/lib/python3.10/site-packages/django/utils/datastructures.py", line 86, in __getitem__
    raise MultiValueDictKeyError(key)
django.utils.datastructures.MultiValueDictKeyError: 'file'
Watching for file changes with StatReloader
/Volumes/Volume/untitled folder 2/ct/app/msbctracker/views.py changed, reloading.
Watching for file changes with StatReloader
/Volumes/Volume/untitled folder 2/ct/app/msbctracker/views.py changed, reloading.
Watching for file changes with StatReloader
/Volumes/Volume/untitled folder 2/ct/app/msbctracker/views.py changed, reloading.
Watching for file changes with StatReloader
/Volumes/Volume/untitled folder 2/ct/app/msbctracker/views.py changed, reloading.
Watching for file changes with StatReloader
/Volumes/Volume/untitled folder 2/ct/app/msbctracker/views.py changed, reloading.
Watching for file changes with StatReloader
/Volumes/Volume/untitled folder 2/ct/app/msbctracker/views.py changed, reloading.
Watching for file changes with StatReloader
/Volumes/Volume/untitled folder 2/ct/app/msbctracker/views.py changed, reloading.
Watching for file changes with StatReloader
/Volumes/Volume/untitled folder 2/ct/app/msbctracker/views.py changed, reloading.
Watching for file changes with StatReloader
/Volumes/Volume/untitled folder 2/ct/app/msbctracker/views.py changed, reloading.
Watching for file changes with StatReloader
/Volumes/Volume/untitled folder 2/ct/app/msbctracker/views.py changed, reloading.
Watching for file changes with StatReloader
/Volumes/Volume/untitled folder 2/ct/app/msbctracker/views.py changed, reloading.
Watching for file changes with StatReloader
/Volumes/Volume/untitled folder 2/ct/app/msbctracker/views.py changed, reloading.
Watching for file changes with StatReloader
/Volumes/Volume/untitled folder 2/ct/app/msbctracker/views.py changed, reloading.
Watching for file changes with StatReloader
/Volumes/Volume/untitled folder 2/ct/app/msbctracker/views.py changed, reloading.
Watching for file changes with StatReloader
/Volumes/Volume/untitled folder 2/ct/app/msbctracker/views.py changed, reloading.
Watching for file changes with StatReloader
/Volumes/Volume/untitled folder 2/ct/app/msbctracker/views.py changed, reloading.
Watching for file changes with StatReloader
/Volumes/Volume/untitled folder 2/ct/app/msbctracker/views.py changed, reloading.
Watching for file changes with StatReloader
/Volumes/Volume/untitled folder 2/ct/app/msbctracker/views.py changed, reloading.
Watching for file changes with StatReloader
/Volumes/Volume/untitled folder 2/ct/app/msbctracker/views.py changed, reloading.
Watching for file changes with StatReloader
/Volumes/Volume/untitled folder 2/ct/app/msbctracker/views.py changed, reloading.
Watching for file changes with StatReloader
/Volumes/Volume/untitled folder 2/ct/app/msbctracker/views.py changed, reloading.
Watching for file changes with StatReloader
/Volumes/Volume/untitled folder 2/ct/app/msbctracker/views.py changed, reloading.
Watching for file changes with StatReloader
/Volumes/Volume/untitled folder 2/ct/app/msbctracker/views.py changed, reloading.
Watching for file changes with StatReloader
/Volumes/Volume/untitled folder 2/ct/app/msbctracker/views.py changed, reloading.
Watching for file changes with StatReloader
/Volumes/Volume/untitled folder 2/ct/app/msbctracker/views.py changed, reloading.
Watching for file changes with StatReloader
/Volumes/Volume/untitled folder 2/ct/app/msbctracker/views.py changed, reloading.
Watching for file changes with StatReloader
/Volumes/Volume/untitled folder 2/ct/app/msbctracker/views.py changed, reloading.
Watching for file changes with StatReloader
/Volumes/Volume/untitled folder 2/ct/app/msbctracker/views.py changed, reloading.
Watching for file changes with StatReloader
/Volumes/Volume/untitled folder 2/ct/app/msbctracker/views.py changed, reloading.
Watching for file changes with StatReloader
/Volumes/Volume/untitled folder 2/ct/app/msbctracker/views.py changed, reloading.
Watching for file changes with StatReloader
/Volumes/Volume/untitled folder 2/ct/app/msbctracker/views.py changed, reloading.
Watching for file changes with StatReloader
/Volumes/Volume/untitled folder 2/ct/app/msbctracker/views.py changed, reloading.
Watching for file changes with StatReloader
/Volumes/Volume/untitled folder 2/ct/app/msbctracker/views.py changed, reloading.
Watching for file changes with StatReloader
/Volumes/Volume/untitled folder 2/ct/app/msbctracker/views.py changed, reloading.
Watching for file changes with StatReloader
/Volumes/Volume/untitled folder 2/ct/app/msbctracker/views.py changed, reloading.
Watching for file changes with StatReloader
/Volumes/Volume/untitled folder 2/ct/app/msbctracker/views.py changed, reloading.
Watching for file changes with StatReloader
/Volumes/Volume/untitled folder 2/ct/app/msbctracker/views.py changed, reloading.
Watching for file changes with StatReloader
/Volumes/Volume/untitled folder 2/ct/app/msbctracker/views.py changed, reloading.
Watching for file changes with StatReloader
/Volumes/Volume/untitled folder 2/ct/app/msbctracker/views.py changed, reloading.
Watching for file changes with StatReloader
/Volumes/Volume/untitled folder 2/ct/app/msbctracker/views.py changed, reloading.
Watching for file changes with StatReloader
/Volumes/Volume/untitled folder 2/ct/app/msbctracker/views.py changed, reloading.
Watching for file changes with StatReloader
/Volumes/Volume/untitled folder 2/ct/app/msbctracker/views.py changed, reloading.
Watching for file changes with StatReloader
Watching for file changes with StatReloader
Watching for file changes with StatReloader
Watching for file changes with StatReloader
/Volumes/Volume/untitled folder 2/ct/app/msbctracker/views.py changed, reloading.
Watching for file changes with StatReloader
/Volumes/Volume/untitled folder 2/ct/app/msbctracker/views.py changed, reloading.
Watching for file changes with StatReloader
/Volumes/Volume/untitled folder 2/ct/app/msbctracker/views.py changed, reloading.
Watching for file changes with StatReloader
/Volumes/Volume/untitled folder 2/ct/app/msbctracker/views.py changed, reloading.
Watching for file changes with StatReloader
/Volumes/Volume/untitled folder 2/ct/app/msbctracker/views.py changed, reloading.
Watching for file changes with StatReloader
/Volumes/Volume/untitled folder 2/ct/app/msbctracker/views.py changed, reloading.
Watching for file changes with StatReloader
Watching for file changes with StatReloader
/Volumes/Volume/untitled folder 2/ct/app/msbctracker/views.py changed, reloading.
Watching for file changes with StatReloader
/Volumes/Volume/untitled folder 2/ct/app/msbctracker/views.py changed, reloading.
Watching for file changes with StatReloader
/Volumes/Volume/untitled folder 2/ct/app/msbctracker/views.py changed, reloading.
Watching for file changes with StatReloader
Watching for file changes with StatReloader
/Volumes/Volume/untitled folder 2/ct/app/msbctracker/views.py changed, reloading.
Watching for file changes with StatReloader
Internal Server Error: /api/TrackingDetails
Traceback (most recent call last):
  File "/Library/Frameworks/Python.framework/Versions/3.10/lib/python3.10/site-packages/django/core/handlers/exception.py", line 55, in inner
    response = get_response(request)
  File "/Library/Frameworks/Python.framework/Versions/3.10/lib/python3.10/site-packages/django/core/handlers/base.py", line 197, in _get_response
    response = wrapped_callback(request, *callback_args, **callback_kwargs)
  File "/Library/Frameworks/Python.framework/Versions/3.10/lib/python3.10/site-packages/django/views/decorators/csrf.py", line 54, in wrapped_view
    return view_func(*args, **kwargs)
  File "/Library/Frameworks/Python.framework/Versions/3.10/lib/python3.10/site-packages/django/views/generic/base.py", line 103, in view
    return self.dispatch(request, *args, **kwargs)
  File "/Library/Frameworks/Python.framework/Versions/3.10/lib/python3.10/site-packages/rest_framework/views.py", line 509, in dispatch
    response = self.handle_exception(exc)
  File "/Library/Frameworks/Python.framework/Versions/3.10/lib/python3.10/site-packages/rest_framework/views.py", line 469, in handle_exception
    self.raise_uncaught_exception(exc)
  File "/Library/Frameworks/Python.framework/Versions/3.10/lib/python3.10/site-packages/rest_framework/views.py", line 480, in raise_uncaught_exception
    raise exc
  File "/Library/Frameworks/Python.framework/Versions/3.10/lib/python3.10/site-packages/rest_framework/views.py", line 506, in dispatch
    response = handler(request, *args, **kwargs)
  File "/Volumes/Volume/untitled folder 2/ct/app/msbctracker/views.py", line 961, in patch
    for new_t in origin_info:
TypeError: 'NoneType' object is not iterable
/Volumes/Volume/untitled folder 2/ct/app/msbctracker/views.py changed, reloading.
Watching for file changes with StatReloader
/Volumes/Volume/untitled folder 2/ct/app/msbctracker/views.py changed, reloading.
Watching for file changes with StatReloader
/Volumes/Volume/untitled folder 2/ct/app/msbctracker/views.py changed, reloading.
Watching for file changes with StatReloader
/Volumes/Volume/untitled folder 2/ct/app/msbctracker/views.py changed, reloading.
Watching for file changes with StatReloader
/Volumes/Volume/untitled folder 2/ct/app/msbctracker/views.py changed, reloading.
Watching for file changes with StatReloader
/Volumes/Volume/untitled folder 2/ct/app/msbctracker/views.py changed, reloading.
Watching for file changes with StatReloader
/Volumes/Volume/untitled folder 2/ct/app/msbctracker/views.py changed, reloading.
Watching for file changes with StatReloader
/Volumes/Volume/untitled folder 2/ct/app/msbctracker/views.py changed, reloading.
Watching for file changes with StatReloader
/Volumes/Volume/untitled folder 2/ct/app/msbctracker/views.py changed, reloading.
Watching for file changes with StatReloader
Watching for file changes with StatReloader
Watching for file changes with StatReloader
/Volumes/Volume/untitled folder 2/ct/app/msbctracker/views.py changed, reloading.
Watching for file changes with StatReloader
/Volumes/Volume/untitled folder 2/ct/app/msbctracker/views.py changed, reloading.
Watching for file changes with StatReloader
/Volumes/Volume/untitled folder 2/ct/app/msbctracker/views.py changed, reloading.
Watching for file changes with StatReloader
Watching for file changes with StatReloader
Method Not Allowed: /api/TrackDetails
Watching for file changes with StatReloader
/Volumes/Volume/untitled folder 2/ct/app/msbctracker/views.py changed, reloading.
Watching for file changes with StatReloader
Internal Server Error: /api/TrackingDetails
Traceback (most recent call last):
  File "/Library/Frameworks/Python.framework/Versions/3.10/lib/python3.10/site-packages/django/core/handlers/exception.py", line 55, in inner
    response = get_response(request)
  File "/Library/Frameworks/Python.framework/Versions/3.10/lib/python3.10/site-packages/django/core/handlers/base.py", line 197, in _get_response
    response = wrapped_callback(request, *callback_args, **callback_kwargs)
  File "/Library/Frameworks/Python.framework/Versions/3.10/lib/python3.10/site-packages/django/views/decorators/csrf.py", line 54, in wrapped_view
    return view_func(*args, **kwargs)
  File "/Library/Frameworks/Python.framework/Versions/3.10/lib/python3.10/site-packages/django/views/generic/base.py", line 103, in view
    return self.dispatch(request, *args, **kwargs)
  File "/Library/Frameworks/Python.framework/Versions/3.10/lib/python3.10/site-packages/rest_framework/views.py", line 509, in dispatch
    response = self.handle_exception(exc)
  File "/Library/Frameworks/Python.framework/Versions/3.10/lib/python3.10/site-packages/rest_framework/views.py", line 469, in handle_exception
    self.raise_uncaught_exception(exc)
  File "/Library/Frameworks/Python.framework/Versions/3.10/lib/python3.10/site-packages/rest_framework/views.py", line 480, in raise_uncaught_exception
    raise exc
  File "/Library/Frameworks/Python.framework/Versions/3.10/lib/python3.10/site-packages/rest_framework/views.py", line 506, in dispatch
    response = handler(request, *args, **kwargs)
  File "/Volumes/Volume/untitled folder 2/ct/app/msbctracker/views.py", line 773, in get
    for new_t in origin_info:
TypeError: 'NoneType' object is not iterable
/Volumes/Volume/untitled folder 2/ct/app/msbctracker/views.py changed, reloading.
Watching for file changes with StatReloader
Internal Server Error: /api/TrackingDetails
Traceback (most recent call last):
  File "/Library/Frameworks/Python.framework/Versions/3.10/lib/python3.10/site-packages/django/core/handlers/exception.py", line 55, in inner
    response = get_response(request)
  File "/Library/Frameworks/Python.framework/Versions/3.10/lib/python3.10/site-packages/django/core/handlers/base.py", line 197, in _get_response
    response = wrapped_callback(request, *callback_args, **callback_kwargs)
  File "/Library/Frameworks/Python.framework/Versions/3.10/lib/python3.10/site-packages/django/views/decorators/csrf.py", line 54, in wrapped_view
    return view_func(*args, **kwargs)
  File "/Library/Frameworks/Python.framework/Versions/3.10/lib/python3.10/site-packages/django/views/generic/base.py", line 103, in view
    return self.dispatch(request, *args, **kwargs)
  File "/Library/Frameworks/Python.framework/Versions/3.10/lib/python3.10/site-packages/rest_framework/views.py", line 509, in dispatch
    response = self.handle_exception(exc)
  File "/Library/Frameworks/Python.framework/Versions/3.10/lib/python3.10/site-packages/rest_framework/views.py", line 469, in handle_exception
    self.raise_uncaught_exception(exc)
  File "/Library/Frameworks/Python.framework/Versions/3.10/lib/python3.10/site-packages/rest_framework/views.py", line 480, in raise_uncaught_exception
    raise exc
  File "/Library/Frameworks/Python.framework/Versions/3.10/lib/python3.10/site-packages/rest_framework/views.py", line 506, in dispatch
    response = handler(request, *args, **kwargs)
  File "/Volumes/Volume/untitled folder 2/ct/app/msbctracker/views.py", line 773, in get
    for new_t in origin_info:
TypeError: 'NoneType' object is not iterable
/Volumes/Volume/untitled folder 2/ct/app/msbctracker/views.py changed, reloading.
Watching for file changes with StatReloader
Internal Server Error: /api/TrackingDetails
Traceback (most recent call last):
  File "/Library/Frameworks/Python.framework/Versions/3.10/lib/python3.10/site-packages/django/core/handlers/exception.py", line 55, in inner
    response = get_response(request)
  File "/Library/Frameworks/Python.framework/Versions/3.10/lib/python3.10/site-packages/django/core/handlers/base.py", line 197, in _get_response
    response = wrapped_callback(request, *callback_args, **callback_kwargs)
  File "/Library/Frameworks/Python.framework/Versions/3.10/lib/python3.10/site-packages/django/views/decorators/csrf.py", line 54, in wrapped_view
    return view_func(*args, **kwargs)
  File "/Library/Frameworks/Python.framework/Versions/3.10/lib/python3.10/site-packages/django/views/generic/base.py", line 103, in view
    return self.dispatch(request, *args, **kwargs)
  File "/Library/Frameworks/Python.framework/Versions/3.10/lib/python3.10/site-packages/rest_framework/views.py", line 511, in dispatch
    self.response = self.finalize_response(request, response, *args, **kwargs)
  File "/Library/Frameworks/Python.framework/Versions/3.10/lib/python3.10/site-packages/rest_framework/views.py", line 423, in finalize_response
    assert isinstance(response, HttpResponseBase), (
AssertionError: Expected a `Response`, `HttpResponse` or `HttpStreamingResponse` to be returned from the view, but received a `<class 'NoneType'>`
Internal Server Error: /api/TrackingDetails
Traceback (most recent call last):
  File "/Library/Frameworks/Python.framework/Versions/3.10/lib/python3.10/site-packages/django/core/handlers/exception.py", line 55, in inner
    response = get_response(request)
  File "/Library/Frameworks/Python.framework/Versions/3.10/lib/python3.10/site-packages/django/core/handlers/base.py", line 197, in _get_response
    response = wrapped_callback(request, *callback_args, **callback_kwargs)
  File "/Library/Frameworks/Python.framework/Versions/3.10/lib/python3.10/site-packages/django/views/decorators/csrf.py", line 54, in wrapped_view
    return view_func(*args, **kwargs)
  File "/Library/Frameworks/Python.framework/Versions/3.10/lib/python3.10/site-packages/django/views/generic/base.py", line 103, in view
    return self.dispatch(request, *args, **kwargs)
  File "/Library/Frameworks/Python.framework/Versions/3.10/lib/python3.10/site-packages/rest_framework/views.py", line 511, in dispatch
    self.response = self.finalize_response(request, response, *args, **kwargs)
  File "/Library/Frameworks/Python.framework/Versions/3.10/lib/python3.10/site-packages/rest_framework/views.py", line 423, in finalize_response
    assert isinstance(response, HttpResponseBase), (
AssertionError: Expected a `Response`, `HttpResponse` or `HttpStreamingResponse` to be returned from the view, but received a `<class 'NoneType'>`
/Volumes/Volume/untitled folder 2/ct/app/msbctracker/views.py changed, reloading.
Watching for file changes with StatReloader
/Volumes/Volume/untitled folder 2/ct/app/msbctracker/views.py changed, reloading.
Watching for file changes with StatReloader
Watching for file changes with StatReloader
Internal Server Error: /api/TrackingDetails
Traceback (most recent call last):
  File "/Library/Frameworks/Python.framework/Versions/3.10/lib/python3.10/site-packages/django/core/handlers/exception.py", line 55, in inner
    response = get_response(request)
  File "/Library/Frameworks/Python.framework/Versions/3.10/lib/python3.10/site-packages/django/core/handlers/base.py", line 197, in _get_response
    response = wrapped_callback(request, *callback_args, **callback_kwargs)
  File "/Library/Frameworks/Python.framework/Versions/3.10/lib/python3.10/site-packages/django/views/decorators/csrf.py", line 54, in wrapped_view
    return view_func(*args, **kwargs)
  File "/Library/Frameworks/Python.framework/Versions/3.10/lib/python3.10/site-packages/django/views/generic/base.py", line 103, in view
    return self.dispatch(request, *args, **kwargs)
  File "/Library/Frameworks/Python.framework/Versions/3.10/lib/python3.10/site-packages/rest_framework/views.py", line 509, in dispatch
    response = self.handle_exception(exc)
  File "/Library/Frameworks/Python.framework/Versions/3.10/lib/python3.10/site-packages/rest_framework/views.py", line 469, in handle_exception
    self.raise_uncaught_exception(exc)
  File "/Library/Frameworks/Python.framework/Versions/3.10/lib/python3.10/site-packages/rest_framework/views.py", line 480, in raise_uncaught_exception
    raise exc
  File "/Library/Frameworks/Python.framework/Versions/3.10/lib/python3.10/site-packages/rest_framework/views.py", line 506, in dispatch
    response = handler(request, *args, **kwargs)
  File "/Volumes/Volume/untitled folder 2/ct/app/msbctracker/views.py", line 772, in get
    for new_t in origin_info:
TypeError: 'NoneType' object is not iterable
/Volumes/Volume/untitled folder 2/ct/app/msbctracker/views.py changed, reloading.
Watching for file changes with StatReloader
Internal Server Error: /api/TrackingDetails
Traceback (most recent call last):
  File "/Library/Frameworks/Python.framework/Versions/3.10/lib/python3.10/site-packages/django/core/handlers/exception.py", line 55, in inner
    response = get_response(request)
  File "/Library/Frameworks/Python.framework/Versions/3.10/lib/python3.10/site-packages/django/core/handlers/base.py", line 197, in _get_response
    response = wrapped_callback(request, *callback_args, **callback_kwargs)
  File "/Library/Frameworks/Python.framework/Versions/3.10/lib/python3.10/site-packages/django/views/decorators/csrf.py", line 54, in wrapped_view
    return view_func(*args, **kwargs)
  File "/Library/Frameworks/Python.framework/Versions/3.10/lib/python3.10/site-packages/django/views/generic/base.py", line 103, in view
    return self.dispatch(request, *args, **kwargs)
  File "/Library/Frameworks/Python.framework/Versions/3.10/lib/python3.10/site-packages/rest_framework/views.py", line 509, in dispatch
    response = self.handle_exception(exc)
  File "/Library/Frameworks/Python.framework/Versions/3.10/lib/python3.10/site-packages/rest_framework/views.py", line 469, in handle_exception
    self.raise_uncaught_exception(exc)
  File "/Library/Frameworks/Python.framework/Versions/3.10/lib/python3.10/site-packages/rest_framework/views.py", line 480, in raise_uncaught_exception
    raise exc
  File "/Library/Frameworks/Python.framework/Versions/3.10/lib/python3.10/site-packages/rest_framework/views.py", line 506, in dispatch
    response = handler(request, *args, **kwargs)
  File "/Volumes/Volume/untitled folder 2/ct/app/msbctracker/views.py", line 778, in get
    for new_t in origin_info:
TypeError: 'NoneType' object is not iterable
/Volumes/Volume/untitled folder 2/ct/app/msbctracker/views.py changed, reloading.
Watching for file changes with StatReloader
/Volumes/Volume/untitled folder 2/ct/app/msbctracker/views.py changed, reloading.
Watching for file changes with StatReloader
/Volumes/Volume/untitled folder 2/ct/app/msbctracker/views.py changed, reloading.
Watching for file changes with StatReloader
Watching for file changes with StatReloader
/Volumes/Volume/untitled folder 2/ct/app/msbctracker/views.py changed, reloading.
Watching for file changes with StatReloader
/Volumes/Volume/untitled folder 2/ct/app/msbctracker/views.py changed, reloading.
Watching for file changes with StatReloader
Internal Server Error: /api/TrackingDetails
Traceback (most recent call last):
  File "/Library/Frameworks/Python.framework/Versions/3.10/lib/python3.10/site-packages/django/core/handlers/exception.py", line 55, in inner
    response = get_response(request)
  File "/Library/Frameworks/Python.framework/Versions/3.10/lib/python3.10/site-packages/django/core/handlers/base.py", line 197, in _get_response
    response = wrapped_callback(request, *callback_args, **callback_kwargs)
  File "/Library/Frameworks/Python.framework/Versions/3.10/lib/python3.10/site-packages/django/views/decorators/csrf.py", line 54, in wrapped_view
    return view_func(*args, **kwargs)
  File "/Library/Frameworks/Python.framework/Versions/3.10/lib/python3.10/site-packages/django/views/generic/base.py", line 103, in view
    return self.dispatch(request, *args, **kwargs)
  File "/Library/Frameworks/Python.framework/Versions/3.10/lib/python3.10/site-packages/rest_framework/views.py", line 509, in dispatch
    response = self.handle_exception(exc)
  File "/Library/Frameworks/Python.framework/Versions/3.10/lib/python3.10/site-packages/rest_framework/views.py", line 469, in handle_exception
    self.raise_uncaught_exception(exc)
  File "/Library/Frameworks/Python.framework/Versions/3.10/lib/python3.10/site-packages/rest_framework/views.py", line 480, in raise_uncaught_exception
    raise exc
  File "/Library/Frameworks/Python.framework/Versions/3.10/lib/python3.10/site-packages/rest_framework/views.py", line 506, in dispatch
    response = handler(request, *args, **kwargs)
  File "/Volumes/Volume/untitled folder 2/ct/app/msbctracker/views.py", line 773, in get
    for new_t in origin_info:
TypeError: 'NoneType' object is not iterable
/Volumes/Volume/untitled folder 2/ct/app/msbctracker/views.py changed, reloading.
Watching for file changes with StatReloader
Internal Server Error: /api/TrackingDetails
Traceback (most recent call last):
  File "/Library/Frameworks/Python.framework/Versions/3.10/lib/python3.10/site-packages/django/core/handlers/exception.py", line 55, in inner
    response = get_response(request)
  File "/Library/Frameworks/Python.framework/Versions/3.10/lib/python3.10/site-packages/django/core/handlers/base.py", line 197, in _get_response
    response = wrapped_callback(request, *callback_args, **callback_kwargs)
  File "/Library/Frameworks/Python.framework/Versions/3.10/lib/python3.10/site-packages/django/views/decorators/csrf.py", line 54, in wrapped_view
    return view_func(*args, **kwargs)
  File "/Library/Frameworks/Python.framework/Versions/3.10/lib/python3.10/site-packages/django/views/generic/base.py", line 103, in view
    return self.dispatch(request, *args, **kwargs)
  File "/Library/Frameworks/Python.framework/Versions/3.10/lib/python3.10/site-packages/rest_framework/views.py", line 509, in dispatch
    response = self.handle_exception(exc)
  File "/Library/Frameworks/Python.framework/Versions/3.10/lib/python3.10/site-packages/rest_framework/views.py", line 469, in handle_exception
    self.raise_uncaught_exception(exc)
  File "/Library/Frameworks/Python.framework/Versions/3.10/lib/python3.10/site-packages/rest_framework/views.py", line 480, in raise_uncaught_exception
    raise exc
  File "/Library/Frameworks/Python.framework/Versions/3.10/lib/python3.10/site-packages/rest_framework/views.py", line 506, in dispatch
    response = handler(request, *args, **kwargs)
  File "/Volumes/Volume/untitled folder 2/ct/app/msbctracker/views.py", line 774, in get
    for new_t in origin_info:
TypeError: 'NoneType' object is not iterable
/Volumes/Volume/untitled folder 2/ct/app/msbctracker/views.py changed, reloading.
Watching for file changes with StatReloader
Internal Server Error: /api/TrackingDetails
Traceback (most recent call last):
  File "/Library/Frameworks/Python.framework/Versions/3.10/lib/python3.10/site-packages/django/core/handlers/exception.py", line 55, in inner
    response = get_response(request)
  File "/Library/Frameworks/Python.framework/Versions/3.10/lib/python3.10/site-packages/django/core/handlers/base.py", line 197, in _get_response
    response = wrapped_callback(request, *callback_args, **callback_kwargs)
  File "/Library/Frameworks/Python.framework/Versions/3.10/lib/python3.10/site-packages/django/views/decorators/csrf.py", line 54, in wrapped_view
    return view_func(*args, **kwargs)
  File "/Library/Frameworks/Python.framework/Versions/3.10/lib/python3.10/site-packages/django/views/generic/base.py", line 103, in view
    return self.dispatch(request, *args, **kwargs)
  File "/Library/Frameworks/Python.framework/Versions/3.10/lib/python3.10/site-packages/rest_framework/views.py", line 509, in dispatch
    response = self.handle_exception(exc)
  File "/Library/Frameworks/Python.framework/Versions/3.10/lib/python3.10/site-packages/rest_framework/views.py", line 469, in handle_exception
    self.raise_uncaught_exception(exc)
  File "/Library/Frameworks/Python.framework/Versions/3.10/lib/python3.10/site-packages/rest_framework/views.py", line 480, in raise_uncaught_exception
    raise exc
  File "/Library/Frameworks/Python.framework/Versions/3.10/lib/python3.10/site-packages/rest_framework/views.py", line 506, in dispatch
    response = handler(request, *args, **kwargs)
  File "/Volumes/Volume/untitled folder 2/ct/app/msbctracker/views.py", line 775, in get
    for new_t in origin_info:
TypeError: 'NoneType' object is not iterable
/Volumes/Volume/untitled folder 2/ct/app/msbctracker/views.py changed, reloading.
Watching for file changes with StatReloader
/Volumes/Volume/untitled folder 2/ct/app/msbctracker/views.py changed, reloading.
Watching for file changes with StatReloader
/Volumes/Volume/untitled folder 2/ct/app/msbctracker/views.py changed, reloading.
Watching for file changes with StatReloader
/Volumes/Volume/untitled folder 2/ct/app/msbctracker/views.py changed, reloading.
Watching for file changes with StatReloader
/Volumes/Volume/untitled folder 2/ct/app/msbctracker/views.py changed, reloading.
Watching for file changes with StatReloader
Internal Server Error: /api/TrackingDetails
Traceback (most recent call last):
  File "/Library/Frameworks/Python.framework/Versions/3.10/lib/python3.10/site-packages/django/core/handlers/exception.py", line 55, in inner
    response = get_response(request)
  File "/Library/Frameworks/Python.framework/Versions/3.10/lib/python3.10/site-packages/django/core/handlers/base.py", line 197, in _get_response
    response = wrapped_callback(request, *callback_args, **callback_kwargs)
  File "/Library/Frameworks/Python.framework/Versions/3.10/lib/python3.10/site-packages/django/views/decorators/csrf.py", line 54, in wrapped_view
    return view_func(*args, **kwargs)
  File "/Library/Frameworks/Python.framework/Versions/3.10/lib/python3.10/site-packages/django/views/generic/base.py", line 103, in view
    return self.dispatch(request, *args, **kwargs)
  File "/Library/Frameworks/Python.framework/Versions/3.10/lib/python3.10/site-packages/rest_framework/views.py", line 509, in dispatch
    response = self.handle_exception(exc)
  File "/Library/Frameworks/Python.framework/Versions/3.10/lib/python3.10/site-packages/rest_framework/views.py", line 469, in handle_exception
    self.raise_uncaught_exception(exc)
  File "/Library/Frameworks/Python.framework/Versions/3.10/lib/python3.10/site-packages/rest_framework/views.py", line 480, in raise_uncaught_exception
    raise exc
  File "/Library/Frameworks/Python.framework/Versions/3.10/lib/python3.10/site-packages/rest_framework/views.py", line 506, in dispatch
    response = handler(request, *args, **kwargs)
  File "/Volumes/Volume/untitled folder 2/ct/app/msbctracker/views.py", line 966, in patch
    for new_t in origin_info:
TypeError: 'NoneType' object is not iterable
Watching for file changes with StatReloader
/Volumes/Volume/untitled folder 2/ct/app/msbctracker/views.py changed, reloading.
Watching for file changes with StatReloader
/Volumes/Volume/untitled folder 2/ct/app/msbctracker/views.py changed, reloading.
Watching for file changes with StatReloader
/Volumes/Volume/untitled folder 2/ct/app/msbctracker/views.py changed, reloading.
Watching for file changes with StatReloader
Internal Server Error: /api/TrackingDetails
Traceback (most recent call last):
  File "/Library/Frameworks/Python.framework/Versions/3.10/lib/python3.10/site-packages/django/core/handlers/exception.py", line 55, in inner
    response = get_response(request)
  File "/Library/Frameworks/Python.framework/Versions/3.10/lib/python3.10/site-packages/django/core/handlers/base.py", line 197, in _get_response
    response = wrapped_callback(request, *callback_args, **callback_kwargs)
  File "/Library/Frameworks/Python.framework/Versions/3.10/lib/python3.10/site-packages/django/views/decorators/csrf.py", line 54, in wrapped_view
    return view_func(*args, **kwargs)
  File "/Library/Frameworks/Python.framework/Versions/3.10/lib/python3.10/site-packages/django/views/generic/base.py", line 103, in view
    return self.dispatch(request, *args, **kwargs)
  File "/Library/Frameworks/Python.framework/Versions/3.10/lib/python3.10/site-packages/rest_framework/views.py", line 509, in dispatch
    response = self.handle_exception(exc)
  File "/Library/Frameworks/Python.framework/Versions/3.10/lib/python3.10/site-packages/rest_framework/views.py", line 469, in handle_exception
    self.raise_uncaught_exception(exc)
  File "/Library/Frameworks/Python.framework/Versions/3.10/lib/python3.10/site-packages/rest_framework/views.py", line 480, in raise_uncaught_exception
    raise exc
  File "/Library/Frameworks/Python.framework/Versions/3.10/lib/python3.10/site-packages/rest_framework/views.py", line 506, in dispatch
    response = handler(request, *args, **kwargs)
  File "/Volumes/Volume/untitled folder 2/ct/app/msbctracker/views.py", line 773, in get
    for new_t in origin_info:
TypeError: 'NoneType' object is not iterable
/Volumes/Volume/untitled folder 2/ct/app/msbctracker/views.py changed, reloading.
Watching for file changes with StatReloader
/Volumes/Volume/untitled folder 2/ct/app/msbctracker/views.py changed, reloading.
Watching for file changes with StatReloader
Internal Server Error: /api/TrackingDetails
Traceback (most recent call last):
  File "/Library/Frameworks/Python.framework/Versions/3.10/lib/python3.10/site-packages/django/db/backends/utils.py", line 89, in _execute
    return self.cursor.execute(sql, params)
  File "/Library/Frameworks/Python.framework/Versions/3.10/lib/python3.10/site-packages/django/db/backends/sqlite3/base.py", line 357, in execute
    return Database.Cursor.execute(self, query, params)
sqlite3.IntegrityError: UNIQUE constraint failed: msbctracker_tracker.tracking_number

The above exception was the direct cause of the following exception:

Traceback (most recent call last):
  File "/Library/Frameworks/Python.framework/Versions/3.10/lib/python3.10/site-packages/django/core/handlers/exception.py", line 55, in inner
    response = get_response(request)
  File "/Library/Frameworks/Python.framework/Versions/3.10/lib/python3.10/site-packages/django/core/handlers/base.py", line 197, in _get_response
    response = wrapped_callback(request, *callback_args, **callback_kwargs)
  File "/Library/Frameworks/Python.framework/Versions/3.10/lib/python3.10/site-packages/django/views/decorators/csrf.py", line 54, in wrapped_view
    return view_func(*args, **kwargs)
  File "/Library/Frameworks/Python.framework/Versions/3.10/lib/python3.10/site-packages/django/views/generic/base.py", line 103, in view
    return self.dispatch(request, *args, **kwargs)
  File "/Library/Frameworks/Python.framework/Versions/3.10/lib/python3.10/site-packages/rest_framework/views.py", line 509, in dispatch
    response = self.handle_exception(exc)
  File "/Library/Frameworks/Python.framework/Versions/3.10/lib/python3.10/site-packages/rest_framework/views.py", line 469, in handle_exception
    self.raise_uncaught_exception(exc)
  File "/Library/Frameworks/Python.framework/Versions/3.10/lib/python3.10/site-packages/rest_framework/views.py", line 480, in raise_uncaught_exception
    raise exc
  File "/Library/Frameworks/Python.framework/Versions/3.10/lib/python3.10/site-packages/rest_framework/views.py", line 506, in dispatch
    response = handler(request, *args, **kwargs)
  File "/Volumes/Volume/untitled folder 2/ct/app/msbctracker/views.py", line 921, in get
    new_data = Tracker.objects.create(api_call_time=ind_time,status=s,tracking_number=t,updated_time=u,booked=b,arrival=a,outbound=o,delivered=d,tracking_info=i,numeric_status=ns
  File "/Library/Frameworks/Python.framework/Versions/3.10/lib/python3.10/site-packages/django/db/models/manager.py", line 85, in manager_method
    return getattr(self.get_queryset(), name)(*args, **kwargs)
  File "/Library/Frameworks/Python.framework/Versions/3.10/lib/python3.10/site-packages/django/db/models/query.py", line 671, in create
    obj.save(force_insert=True, using=self.db)
  File "/Library/Frameworks/Python.framework/Versions/3.10/lib/python3.10/site-packages/django/db/models/base.py", line 831, in save
    self.save_base(
  File "/Library/Frameworks/Python.framework/Versions/3.10/lib/python3.10/site-packages/django/db/models/base.py", line 882, in save_base
    updated = self._save_table(
  File "/Library/Frameworks/Python.framework/Versions/3.10/lib/python3.10/site-packages/django/db/models/base.py", line 1025, in _save_table
    results = self._do_insert(
  File "/Library/Frameworks/Python.framework/Versions/3.10/lib/python3.10/site-packages/django/db/models/base.py", line 1066, in _do_insert
    return manager._insert(
  File "/Library/Frameworks/Python.framework/Versions/3.10/lib/python3.10/site-packages/django/db/models/manager.py", line 85, in manager_method
    return getattr(self.get_queryset(), name)(*args, **kwargs)
  File "/Library/Frameworks/Python.framework/Versions/3.10/lib/python3.10/site-packages/django/db/models/query.py", line 1790, in _insert
    return query.get_compiler(using=using).execute_sql(returning_fields)
  File "/Library/Frameworks/Python.framework/Versions/3.10/lib/python3.10/site-packages/django/db/models/sql/compiler.py", line 1657, in execute_sql
    cursor.execute(sql, params)
  File "/Library/Frameworks/Python.framework/Versions/3.10/lib/python3.10/site-packages/django/db/backends/utils.py", line 103, in execute
    return super().execute(sql, params)
  File "/Library/Frameworks/Python.framework/Versions/3.10/lib/python3.10/site-packages/django/db/backends/utils.py", line 67, in execute
    return self._execute_with_wrappers(
  File "/Library/Frameworks/Python.framework/Versions/3.10/lib/python3.10/site-packages/django/db/backends/utils.py", line 80, in _execute_with_wrappers
    return executor(sql, params, many, context)
  File "/Library/Frameworks/Python.framework/Versions/3.10/lib/python3.10/site-packages/django/db/backends/utils.py", line 84, in _execute
    with self.db.wrap_database_errors:
  File "/Library/Frameworks/Python.framework/Versions/3.10/lib/python3.10/site-packages/django/db/utils.py", line 91, in __exit__
    raise dj_exc_value.with_traceback(traceback) from exc_value
  File "/Library/Frameworks/Python.framework/Versions/3.10/lib/python3.10/site-packages/django/db/backends/utils.py", line 89, in _execute
    return self.cursor.execute(sql, params)
  File "/Library/Frameworks/Python.framework/Versions/3.10/lib/python3.10/site-packages/django/db/backends/sqlite3/base.py", line 357, in execute
    return Database.Cursor.execute(self, query, params)
django.db.utils.IntegrityError: UNIQUE constraint failed: msbctracker_tracker.tracking_number
/Volumes/Volume/untitled folder 2/ct/app/msbctracker/views.py changed, reloading.
Watching for file changes with StatReloader
Internal Server Error: /api/TrackingDetails
Traceback (most recent call last):
  File "/Library/Frameworks/Python.framework/Versions/3.10/lib/python3.10/site-packages/django/db/backends/utils.py", line 89, in _execute
    return self.cursor.execute(sql, params)
  File "/Library/Frameworks/Python.framework/Versions/3.10/lib/python3.10/site-packages/django/db/backends/sqlite3/base.py", line 357, in execute
    return Database.Cursor.execute(self, query, params)
sqlite3.IntegrityError: UNIQUE constraint failed: msbctracker_tracker.tracking_number

The above exception was the direct cause of the following exception:

Traceback (most recent call last):
  File "/Library/Frameworks/Python.framework/Versions/3.10/lib/python3.10/site-packages/django/core/handlers/exception.py", line 55, in inner
    response = get_response(request)
  File "/Library/Frameworks/Python.framework/Versions/3.10/lib/python3.10/site-packages/django/core/handlers/base.py", line 197, in _get_response
    response = wrapped_callback(request, *callback_args, **callback_kwargs)
  File "/Library/Frameworks/Python.framework/Versions/3.10/lib/python3.10/site-packages/django/views/decorators/csrf.py", line 54, in wrapped_view
    return view_func(*args, **kwargs)
  File "/Library/Frameworks/Python.framework/Versions/3.10/lib/python3.10/site-packages/django/views/generic/base.py", line 103, in view
    return self.dispatch(request, *args, **kwargs)
  File "/Library/Frameworks/Python.framework/Versions/3.10/lib/python3.10/site-packages/rest_framework/views.py", line 509, in dispatch
    response = self.handle_exception(exc)
  File "/Library/Frameworks/Python.framework/Versions/3.10/lib/python3.10/site-packages/rest_framework/views.py", line 469, in handle_exception
    self.raise_uncaught_exception(exc)
  File "/Library/Frameworks/Python.framework/Versions/3.10/lib/python3.10/site-packages/rest_framework/views.py", line 480, in raise_uncaught_exception
    raise exc
  File "/Library/Frameworks/Python.framework/Versions/3.10/lib/python3.10/site-packages/rest_framework/views.py", line 506, in dispatch
    response = handler(request, *args, **kwargs)
  File "/Volumes/Volume/untitled folder 2/ct/app/msbctracker/views.py", line 921, in get
    new_data = Tracker.objects.create(api_call_time=ind_time,status=s,tracking_number=t,updated_time=u,booked=b,arrival=a,outbound=o,delivered=d,tracking_info=i,numeric_status=ns
  File "/Library/Frameworks/Python.framework/Versions/3.10/lib/python3.10/site-packages/django/db/models/manager.py", line 85, in manager_method
    return getattr(self.get_queryset(), name)(*args, **kwargs)
  File "/Library/Frameworks/Python.framework/Versions/3.10/lib/python3.10/site-packages/django/db/models/query.py", line 671, in create
    obj.save(force_insert=True, using=self.db)
  File "/Library/Frameworks/Python.framework/Versions/3.10/lib/python3.10/site-packages/django/db/models/base.py", line 831, in save
    self.save_base(
  File "/Library/Frameworks/Python.framework/Versions/3.10/lib/python3.10/site-packages/django/db/models/base.py", line 882, in save_base
    updated = self._save_table(
  File "/Library/Frameworks/Python.framework/Versions/3.10/lib/python3.10/site-packages/django/db/models/base.py", line 1025, in _save_table
    results = self._do_insert(
  File "/Library/Frameworks/Python.framework/Versions/3.10/lib/python3.10/site-packages/django/db/models/base.py", line 1066, in _do_insert
    return manager._insert(
  File "/Library/Frameworks/Python.framework/Versions/3.10/lib/python3.10/site-packages/django/db/models/manager.py", line 85, in manager_method
    return getattr(self.get_queryset(), name)(*args, **kwargs)
  File "/Library/Frameworks/Python.framework/Versions/3.10/lib/python3.10/site-packages/django/db/models/query.py", line 1790, in _insert
    return query.get_compiler(using=using).execute_sql(returning_fields)
  File "/Library/Frameworks/Python.framework/Versions/3.10/lib/python3.10/site-packages/django/db/models/sql/compiler.py", line 1657, in execute_sql
    cursor.execute(sql, params)
  File "/Library/Frameworks/Python.framework/Versions/3.10/lib/python3.10/site-packages/django/db/backends/utils.py", line 103, in execute
    return super().execute(sql, params)
  File "/Library/Frameworks/Python.framework/Versions/3.10/lib/python3.10/site-packages/django/db/backends/utils.py", line 67, in execute
    return self._execute_with_wrappers(
  File "/Library/Frameworks/Python.framework/Versions/3.10/lib/python3.10/site-packages/django/db/backends/utils.py", line 80, in _execute_with_wrappers
    return executor(sql, params, many, context)
  File "/Library/Frameworks/Python.framework/Versions/3.10/lib/python3.10/site-packages/django/db/backends/utils.py", line 84, in _execute
    with self.db.wrap_database_errors:
  File "/Library/Frameworks/Python.framework/Versions/3.10/lib/python3.10/site-packages/django/db/utils.py", line 91, in __exit__
    raise dj_exc_value.with_traceback(traceback) from exc_value
  File "/Library/Frameworks/Python.framework/Versions/3.10/lib/python3.10/site-packages/django/db/backends/utils.py", line 89, in _execute
    return self.cursor.execute(sql, params)
  File "/Library/Frameworks/Python.framework/Versions/3.10/lib/python3.10/site-packages/django/db/backends/sqlite3/base.py", line 357, in execute
    return Database.Cursor.execute(self, query, params)
django.db.utils.IntegrityError: UNIQUE constraint failed: msbctracker_tracker.tracking_number
/Volumes/Volume/untitled folder 2/ct/app/msbctracker/views.py changed, reloading.
Watching for file changes with StatReloader
/Volumes/Volume/untitled folder 2/ct/app/msbctracker/views.py changed, reloading.
Watching for file changes with StatReloader
/Volumes/Volume/untitled folder 2/ct/app/msbctracker/views.py changed, reloading.
Watching for file changes with StatReloader
/Volumes/Volume/untitled folder 2/ct/app/msbctracker/views.py changed, reloading.
Watching for file changes with StatReloader
Internal Server Error: /api/TrackingDetails
Traceback (most recent call last):
  File "/Library/Frameworks/Python.framework/Versions/3.10/lib/python3.10/site-packages/django/core/handlers/exception.py", line 55, in inner
    response = get_response(request)
  File "/Library/Frameworks/Python.framework/Versions/3.10/lib/python3.10/site-packages/django/core/handlers/base.py", line 197, in _get_response
    response = wrapped_callback(request, *callback_args, **callback_kwargs)
  File "/Library/Frameworks/Python.framework/Versions/3.10/lib/python3.10/site-packages/django/views/decorators/csrf.py", line 54, in wrapped_view
    return view_func(*args, **kwargs)
  File "/Library/Frameworks/Python.framework/Versions/3.10/lib/python3.10/site-packages/django/views/generic/base.py", line 103, in view
    return self.dispatch(request, *args, **kwargs)
  File "/Library/Frameworks/Python.framework/Versions/3.10/lib/python3.10/site-packages/rest_framework/views.py", line 509, in dispatch
    response = self.handle_exception(exc)
  File "/Library/Frameworks/Python.framework/Versions/3.10/lib/python3.10/site-packages/rest_framework/views.py", line 469, in handle_exception
    self.raise_uncaught_exception(exc)
  File "/Library/Frameworks/Python.framework/Versions/3.10/lib/python3.10/site-packages/rest_framework/views.py", line 480, in raise_uncaught_exception
    raise exc
  File "/Library/Frameworks/Python.framework/Versions/3.10/lib/python3.10/site-packages/rest_framework/views.py", line 506, in dispatch
    response = handler(request, *args, **kwargs)
  File "/Volumes/Volume/untitled folder 2/ct/app/msbctracker/views.py", line 774, in get
    for new_t in origin_info:
TypeError: 'NoneType' object is not iterable
/Volumes/Volume/untitled folder 2/ct/app/msbctracker/views.py changed, reloading.
Watching for file changes with StatReloader
/Volumes/Volume/untitled folder 2/ct/app/msbctracker/views.py changed, reloading.
Watching for file changes with StatReloader
/Volumes/Volume/untitled folder 2/ct/app/msbctracker/views.py changed, reloading.
Watching for file changes with StatReloader
/Volumes/Volume/untitled folder 2/ct/app/msbctracker/views.py changed, reloading.
Watching for file changes with StatReloader
/Volumes/Volume/untitled folder 2/ct/app/msbctracker/views.py changed, reloading.
Watching for file changes with StatReloader
Internal Server Error: /api/TrackingDetails
Traceback (most recent call last):
  File "/Library/Frameworks/Python.framework/Versions/3.10/lib/python3.10/site-packages/django/db/backends/utils.py", line 89, in _execute
    return self.cursor.execute(sql, params)
  File "/Library/Frameworks/Python.framework/Versions/3.10/lib/python3.10/site-packages/django/db/backends/sqlite3/base.py", line 357, in execute
    return Database.Cursor.execute(self, query, params)
sqlite3.IntegrityError: UNIQUE constraint failed: msbctracker_tracker.tracking_number

The above exception was the direct cause of the following exception:

Traceback (most recent call last):
  File "/Library/Frameworks/Python.framework/Versions/3.10/lib/python3.10/site-packages/django/core/handlers/exception.py", line 55, in inner
    response = get_response(request)
  File "/Library/Frameworks/Python.framework/Versions/3.10/lib/python3.10/site-packages/django/core/handlers/base.py", line 197, in _get_response
    response = wrapped_callback(request, *callback_args, **callback_kwargs)
  File "/Library/Frameworks/Python.framework/Versions/3.10/lib/python3.10/site-packages/django/views/decorators/csrf.py", line 54, in wrapped_view
    return view_func(*args, **kwargs)
  File "/Library/Frameworks/Python.framework/Versions/3.10/lib/python3.10/site-packages/django/views/generic/base.py", line 103, in view
    return self.dispatch(request, *args, **kwargs)
  File "/Library/Frameworks/Python.framework/Versions/3.10/lib/python3.10/site-packages/rest_framework/views.py", line 509, in dispatch
    response = self.handle_exception(exc)
  File "/Library/Frameworks/Python.framework/Versions/3.10/lib/python3.10/site-packages/rest_framework/views.py", line 469, in handle_exception
    self.raise_uncaught_exception(exc)
  File "/Library/Frameworks/Python.framework/Versions/3.10/lib/python3.10/site-packages/rest_framework/views.py", line 480, in raise_uncaught_exception
    raise exc
  File "/Library/Frameworks/Python.framework/Versions/3.10/lib/python3.10/site-packages/rest_framework/views.py", line 506, in dispatch
    response = handler(request, *args, **kwargs)
  File "/Volumes/Volume/untitled folder 2/ct/app/msbctracker/views.py", line 922, in get
    new_data = Tracker.objects.create(api_call_time=ind_time,status=s,tracking_number=t,updated_time=u,booked=b,arrival=a,outbound=o,delivered=d,tracking_info=i,numeric_status=ns
  File "/Library/Frameworks/Python.framework/Versions/3.10/lib/python3.10/site-packages/django/db/models/manager.py", line 85, in manager_method
    return getattr(self.get_queryset(), name)(*args, **kwargs)
  File "/Library/Frameworks/Python.framework/Versions/3.10/lib/python3.10/site-packages/django/db/models/query.py", line 671, in create
    obj.save(force_insert=True, using=self.db)
  File "/Library/Frameworks/Python.framework/Versions/3.10/lib/python3.10/site-packages/django/db/models/base.py", line 831, in save
    self.save_base(
  File "/Library/Frameworks/Python.framework/Versions/3.10/lib/python3.10/site-packages/django/db/models/base.py", line 882, in save_base
    updated = self._save_table(
  File "/Library/Frameworks/Python.framework/Versions/3.10/lib/python3.10/site-packages/django/db/models/base.py", line 1025, in _save_table
    results = self._do_insert(
  File "/Library/Frameworks/Python.framework/Versions/3.10/lib/python3.10/site-packages/django/db/models/base.py", line 1066, in _do_insert
    return manager._insert(
  File "/Library/Frameworks/Python.framework/Versions/3.10/lib/python3.10/site-packages/django/db/models/manager.py", line 85, in manager_method
    return getattr(self.get_queryset(), name)(*args, **kwargs)
  File "/Library/Frameworks/Python.framework/Versions/3.10/lib/python3.10/site-packages/django/db/models/query.py", line 1790, in _insert
    return query.get_compiler(using=using).execute_sql(returning_fields)
  File "/Library/Frameworks/Python.framework/Versions/3.10/lib/python3.10/site-packages/django/db/models/sql/compiler.py", line 1657, in execute_sql
    cursor.execute(sql, params)
  File "/Library/Frameworks/Python.framework/Versions/3.10/lib/python3.10/site-packages/django/db/backends/utils.py", line 103, in execute
    return super().execute(sql, params)
  File "/Library/Frameworks/Python.framework/Versions/3.10/lib/python3.10/site-packages/django/db/backends/utils.py", line 67, in execute
    return self._execute_with_wrappers(
  File "/Library/Frameworks/Python.framework/Versions/3.10/lib/python3.10/site-packages/django/db/backends/utils.py", line 80, in _execute_with_wrappers
    return executor(sql, params, many, context)
  File "/Library/Frameworks/Python.framework/Versions/3.10/lib/python3.10/site-packages/django/db/backends/utils.py", line 84, in _execute
    with self.db.wrap_database_errors:
  File "/Library/Frameworks/Python.framework/Versions/3.10/lib/python3.10/site-packages/django/db/utils.py", line 91, in __exit__
    raise dj_exc_value.with_traceback(traceback) from exc_value
  File "/Library/Frameworks/Python.framework/Versions/3.10/lib/python3.10/site-packages/django/db/backends/utils.py", line 89, in _execute
    return self.cursor.execute(sql, params)
  File "/Library/Frameworks/Python.framework/Versions/3.10/lib/python3.10/site-packages/django/db/backends/sqlite3/base.py", line 357, in execute
    return Database.Cursor.execute(self, query, params)
django.db.utils.IntegrityError: UNIQUE constraint failed: msbctracker_tracker.tracking_number
Internal Server Error: /api/TrackingDetails
Traceback (most recent call last):
  File "/Library/Frameworks/Python.framework/Versions/3.10/lib/python3.10/site-packages/django/core/handlers/exception.py", line 55, in inner
    response = get_response(request)
  File "/Library/Frameworks/Python.framework/Versions/3.10/lib/python3.10/site-packages/django/core/handlers/base.py", line 197, in _get_response
    response = wrapped_callback(request, *callback_args, **callback_kwargs)
  File "/Library/Frameworks/Python.framework/Versions/3.10/lib/python3.10/site-packages/django/views/decorators/csrf.py", line 54, in wrapped_view
    return view_func(*args, **kwargs)
  File "/Library/Frameworks/Python.framework/Versions/3.10/lib/python3.10/site-packages/django/views/generic/base.py", line 103, in view
    return self.dispatch(request, *args, **kwargs)
  File "/Library/Frameworks/Python.framework/Versions/3.10/lib/python3.10/site-packages/rest_framework/views.py", line 509, in dispatch
    response = self.handle_exception(exc)
  File "/Library/Frameworks/Python.framework/Versions/3.10/lib/python3.10/site-packages/rest_framework/views.py", line 469, in handle_exception
    self.raise_uncaught_exception(exc)
  File "/Library/Frameworks/Python.framework/Versions/3.10/lib/python3.10/site-packages/rest_framework/views.py", line 480, in raise_uncaught_exception
    raise exc
  File "/Library/Frameworks/Python.framework/Versions/3.10/lib/python3.10/site-packages/rest_framework/views.py", line 506, in dispatch
    response = handler(request, *args, **kwargs)
  File "/Volumes/Volume/untitled folder 2/ct/app/msbctracker/views.py", line 958, in patch
    for new_t in origin_info:
TypeError: 'NoneType' object is not iterable
/Volumes/Volume/untitled folder 2/ct/app/msbctracker/views.py changed, reloading.
Watching for file changes with StatReloader
Internal Server Error: /api/TrackingDetails
Traceback (most recent call last):
  File "/Library/Frameworks/Python.framework/Versions/3.10/lib/python3.10/site-packages/django/db/backends/utils.py", line 89, in _execute
    return self.cursor.execute(sql, params)
  File "/Library/Frameworks/Python.framework/Versions/3.10/lib/python3.10/site-packages/django/db/backends/sqlite3/base.py", line 357, in execute
    return Database.Cursor.execute(self, query, params)
sqlite3.IntegrityError: UNIQUE constraint failed: msbctracker_tracker.tracking_number

The above exception was the direct cause of the following exception:

Traceback (most recent call last):
  File "/Library/Frameworks/Python.framework/Versions/3.10/lib/python3.10/site-packages/django/core/handlers/exception.py", line 55, in inner
    response = get_response(request)
  File "/Library/Frameworks/Python.framework/Versions/3.10/lib/python3.10/site-packages/django/core/handlers/base.py", line 197, in _get_response
    response = wrapped_callback(request, *callback_args, **callback_kwargs)
  File "/Library/Frameworks/Python.framework/Versions/3.10/lib/python3.10/site-packages/django/views/decorators/csrf.py", line 54, in wrapped_view
    return view_func(*args, **kwargs)
  File "/Library/Frameworks/Python.framework/Versions/3.10/lib/python3.10/site-packages/django/views/generic/base.py", line 103, in view
    return self.dispatch(request, *args, **kwargs)
  File "/Library/Frameworks/Python.framework/Versions/3.10/lib/python3.10/site-packages/rest_framework/views.py", line 509, in dispatch
    response = self.handle_exception(exc)
  File "/Library/Frameworks/Python.framework/Versions/3.10/lib/python3.10/site-packages/rest_framework/views.py", line 469, in handle_exception
    self.raise_uncaught_exception(exc)
  File "/Library/Frameworks/Python.framework/Versions/3.10/lib/python3.10/site-packages/rest_framework/views.py", line 480, in raise_uncaught_exception
    raise exc
  File "/Library/Frameworks/Python.framework/Versions/3.10/lib/python3.10/site-packages/rest_framework/views.py", line 506, in dispatch
    response = handler(request, *args, **kwargs)
  File "/Volumes/Volume/untitled folder 2/ct/app/msbctracker/views.py", line 922, in get
    new_data = Tracker.objects.create(api_call_time=ind_time,status=s,tracking_number=t,updated_time=u,booked=b,arrival=a,outbound=o,delivered=d,tracking_info=i,numeric_status=ns
  File "/Library/Frameworks/Python.framework/Versions/3.10/lib/python3.10/site-packages/django/db/models/manager.py", line 85, in manager_method
    return getattr(self.get_queryset(), name)(*args, **kwargs)
  File "/Library/Frameworks/Python.framework/Versions/3.10/lib/python3.10/site-packages/django/db/models/query.py", line 671, in create
    obj.save(force_insert=True, using=self.db)
  File "/Library/Frameworks/Python.framework/Versions/3.10/lib/python3.10/site-packages/django/db/models/base.py", line 831, in save
    self.save_base(
  File "/Library/Frameworks/Python.framework/Versions/3.10/lib/python3.10/site-packages/django/db/models/base.py", line 882, in save_base
    updated = self._save_table(
  File "/Library/Frameworks/Python.framework/Versions/3.10/lib/python3.10/site-packages/django/db/models/base.py", line 1025, in _save_table
    results = self._do_insert(
  File "/Library/Frameworks/Python.framework/Versions/3.10/lib/python3.10/site-packages/django/db/models/base.py", line 1066, in _do_insert
    return manager._insert(
  File "/Library/Frameworks/Python.framework/Versions/3.10/lib/python3.10/site-packages/django/db/models/manager.py", line 85, in manager_method
    return getattr(self.get_queryset(), name)(*args, **kwargs)
  File "/Library/Frameworks/Python.framework/Versions/3.10/lib/python3.10/site-packages/django/db/models/query.py", line 1790, in _insert
    return query.get_compiler(using=using).execute_sql(returning_fields)
  File "/Library/Frameworks/Python.framework/Versions/3.10/lib/python3.10/site-packages/django/db/models/sql/compiler.py", line 1657, in execute_sql
    cursor.execute(sql, params)
  File "/Library/Frameworks/Python.framework/Versions/3.10/lib/python3.10/site-packages/django/db/backends/utils.py", line 103, in execute
    return super().execute(sql, params)
  File "/Library/Frameworks/Python.framework/Versions/3.10/lib/python3.10/site-packages/django/db/backends/utils.py", line 67, in execute
    return self._execute_with_wrappers(
  File "/Library/Frameworks/Python.framework/Versions/3.10/lib/python3.10/site-packages/django/db/backends/utils.py", line 80, in _execute_with_wrappers
    return executor(sql, params, many, context)
  File "/Library/Frameworks/Python.framework/Versions/3.10/lib/python3.10/site-packages/django/db/backends/utils.py", line 84, in _execute
    with self.db.wrap_database_errors:
  File "/Library/Frameworks/Python.framework/Versions/3.10/lib/python3.10/site-packages/django/db/utils.py", line 91, in __exit__
    raise dj_exc_value.with_traceback(traceback) from exc_value
  File "/Library/Frameworks/Python.framework/Versions/3.10/lib/python3.10/site-packages/django/db/backends/utils.py", line 89, in _execute
    return self.cursor.execute(sql, params)
  File "/Library/Frameworks/Python.framework/Versions/3.10/lib/python3.10/site-packages/django/db/backends/sqlite3/base.py", line 357, in execute
    return Database.Cursor.execute(self, query, params)
django.db.utils.IntegrityError: UNIQUE constraint failed: msbctracker_tracker.tracking_number
/Volumes/Volume/untitled folder 2/ct/app/msbctracker/views.py changed, reloading.
Watching for file changes with StatReloader
Internal Server Error: /api/TrackingDetails
Traceback (most recent call last):
  File "/Library/Frameworks/Python.framework/Versions/3.10/lib/python3.10/site-packages/django/core/handlers/exception.py", line 55, in inner
    response = get_response(request)
  File "/Library/Frameworks/Python.framework/Versions/3.10/lib/python3.10/site-packages/django/core/handlers/base.py", line 197, in _get_response
    response = wrapped_callback(request, *callback_args, **callback_kwargs)
  File "/Library/Frameworks/Python.framework/Versions/3.10/lib/python3.10/site-packages/django/views/decorators/csrf.py", line 54, in wrapped_view
    return view_func(*args, **kwargs)
  File "/Library/Frameworks/Python.framework/Versions/3.10/lib/python3.10/site-packages/django/views/generic/base.py", line 103, in view
    return self.dispatch(request, *args, **kwargs)
  File "/Library/Frameworks/Python.framework/Versions/3.10/lib/python3.10/site-packages/rest_framework/views.py", line 509, in dispatch
    response = self.handle_exception(exc)
  File "/Library/Frameworks/Python.framework/Versions/3.10/lib/python3.10/site-packages/rest_framework/views.py", line 469, in handle_exception
    self.raise_uncaught_exception(exc)
  File "/Library/Frameworks/Python.framework/Versions/3.10/lib/python3.10/site-packages/rest_framework/views.py", line 480, in raise_uncaught_exception
    raise exc
  File "/Library/Frameworks/Python.framework/Versions/3.10/lib/python3.10/site-packages/rest_framework/views.py", line 506, in dispatch
    response = handler(request, *args, **kwargs)
  File "/Volumes/Volume/untitled folder 2/ct/app/msbctracker/views.py", line 1003, in patch
    "Booked":booked,
UnboundLocalError: local variable 'booked' referenced before assignment
/Volumes/Volume/untitled folder 2/ct/app/msbctracker/views.py changed, reloading.
Watching for file changes with StatReloader
Internal Server Error: /api/TrackingDetails
Traceback (most recent call last):
  File "/Library/Frameworks/Python.framework/Versions/3.10/lib/python3.10/site-packages/django/core/handlers/exception.py", line 55, in inner
    response = get_response(request)
  File "/Library/Frameworks/Python.framework/Versions/3.10/lib/python3.10/site-packages/django/core/handlers/base.py", line 197, in _get_response
    response = wrapped_callback(request, *callback_args, **callback_kwargs)
  File "/Library/Frameworks/Python.framework/Versions/3.10/lib/python3.10/site-packages/django/views/decorators/csrf.py", line 54, in wrapped_view
    return view_func(*args, **kwargs)
  File "/Library/Frameworks/Python.framework/Versions/3.10/lib/python3.10/site-packages/django/views/generic/base.py", line 103, in view
    return self.dispatch(request, *args, **kwargs)
  File "/Library/Frameworks/Python.framework/Versions/3.10/lib/python3.10/site-packages/rest_framework/views.py", line 509, in dispatch
    response = self.handle_exception(exc)
  File "/Library/Frameworks/Python.framework/Versions/3.10/lib/python3.10/site-packages/rest_framework/views.py", line 469, in handle_exception
    self.raise_uncaught_exception(exc)
  File "/Library/Frameworks/Python.framework/Versions/3.10/lib/python3.10/site-packages/rest_framework/views.py", line 480, in raise_uncaught_exception
    raise exc
  File "/Library/Frameworks/Python.framework/Versions/3.10/lib/python3.10/site-packages/rest_framework/views.py", line 506, in dispatch
    response = handler(request, *args, **kwargs)
  File "/Volumes/Volume/untitled folder 2/ct/app/msbctracker/views.py", line 1003, in patch
    "Booked":booked,
UnboundLocalError: local variable 'booked' referenced before assignment
/Volumes/Volume/untitled folder 2/ct/app/msbctracker/views.py changed, reloading.
Watching for file changes with StatReloader
Internal Server Error: /api/TrackingDetails
Traceback (most recent call last):
  File "/Library/Frameworks/Python.framework/Versions/3.10/lib/python3.10/site-packages/django/core/handlers/exception.py", line 55, in inner
    response = get_response(request)
  File "/Library/Frameworks/Python.framework/Versions/3.10/lib/python3.10/site-packages/django/core/handlers/base.py", line 197, in _get_response
    response = wrapped_callback(request, *callback_args, **callback_kwargs)
  File "/Library/Frameworks/Python.framework/Versions/3.10/lib/python3.10/site-packages/django/views/decorators/csrf.py", line 54, in wrapped_view
    return view_func(*args, **kwargs)
  File "/Library/Frameworks/Python.framework/Versions/3.10/lib/python3.10/site-packages/django/views/generic/base.py", line 103, in view
    return self.dispatch(request, *args, **kwargs)
  File "/Library/Frameworks/Python.framework/Versions/3.10/lib/python3.10/site-packages/rest_framework/views.py", line 509, in dispatch
    response = self.handle_exception(exc)
  File "/Library/Frameworks/Python.framework/Versions/3.10/lib/python3.10/site-packages/rest_framework/views.py", line 469, in handle_exception
    self.raise_uncaught_exception(exc)
  File "/Library/Frameworks/Python.framework/Versions/3.10/lib/python3.10/site-packages/rest_framework/views.py", line 480, in raise_uncaught_exception
    raise exc
  File "/Library/Frameworks/Python.framework/Versions/3.10/lib/python3.10/site-packages/rest_framework/views.py", line 506, in dispatch
    response = handler(request, *args, **kwargs)
  File "/Volumes/Volume/untitled folder 2/ct/app/msbctracker/views.py", line 1011, in patch
    new_temp.append(d)
UnboundLocalError: local variable 'd' referenced before assignment
/Volumes/Volume/untitled folder 2/ct/app/msbctracker/views.py changed, reloading.
Watching for file changes with StatReloader
Internal Server Error: /api/TrackingDetails
Traceback (most recent call last):
  File "/Library/Frameworks/Python.framework/Versions/3.10/lib/python3.10/site-packages/django/core/handlers/exception.py", line 55, in inner
    response = get_response(request)
  File "/Library/Frameworks/Python.framework/Versions/3.10/lib/python3.10/site-packages/django/core/handlers/base.py", line 197, in _get_response
    response = wrapped_callback(request, *callback_args, **callback_kwargs)
  File "/Library/Frameworks/Python.framework/Versions/3.10/lib/python3.10/site-packages/django/views/decorators/csrf.py", line 54, in wrapped_view
    return view_func(*args, **kwargs)
  File "/Library/Frameworks/Python.framework/Versions/3.10/lib/python3.10/site-packages/django/views/generic/base.py", line 103, in view
    return self.dispatch(request, *args, **kwargs)
  File "/Library/Frameworks/Python.framework/Versions/3.10/lib/python3.10/site-packages/rest_framework/views.py", line 509, in dispatch
    response = self.handle_exception(exc)
  File "/Library/Frameworks/Python.framework/Versions/3.10/lib/python3.10/site-packages/rest_framework/views.py", line 469, in handle_exception
    self.raise_uncaught_exception(exc)
  File "/Library/Frameworks/Python.framework/Versions/3.10/lib/python3.10/site-packages/rest_framework/views.py", line 480, in raise_uncaught_exception
    raise exc
  File "/Library/Frameworks/Python.framework/Versions/3.10/lib/python3.10/site-packages/rest_framework/views.py", line 506, in dispatch
    response = handler(request, *args, **kwargs)
  File "/Volumes/Volume/untitled folder 2/ct/app/msbctracker/views.py", line 958, in patch
    for new_t in origin_info:
TypeError: 'NoneType' object is not iterable
/Volumes/Volume/untitled folder 2/ct/app/msbctracker/views.py changed, reloading.
Watching for file changes with StatReloader
/Volumes/Volume/untitled folder 2/ct/app/msbctracker/views.py changed, reloading.
Watching for file changes with StatReloader
/Volumes/Volume/untitled folder 2/ct/app/msbctracker/views.py changed, reloading.
Watching for file changes with StatReloader
/Volumes/Volume/untitled folder 2/ct/app/msbctracker/views.py changed, reloading.
Watching for file changes with StatReloader
/Volumes/Volume/untitled folder 2/ct/app/msbctracker/views.py changed, reloading.
Watching for file changes with StatReloader
/Volumes/Volume/untitled folder 2/ct/app/msbctracker/views.py changed, reloading.
Watching for file changes with StatReloader
/Volumes/Volume/untitled folder 2/ct/app/msbctracker/views.py changed, reloading.
Watching for file changes with StatReloader
Internal Server Error: /api/TrackingDetails
Traceback (most recent call last):
  File "/Library/Frameworks/Python.framework/Versions/3.10/lib/python3.10/site-packages/django/core/handlers/exception.py", line 55, in inner
    response = get_response(request)
  File "/Library/Frameworks/Python.framework/Versions/3.10/lib/python3.10/site-packages/django/core/handlers/base.py", line 197, in _get_response
    response = wrapped_callback(request, *callback_args, **callback_kwargs)
  File "/Library/Frameworks/Python.framework/Versions/3.10/lib/python3.10/site-packages/django/views/decorators/csrf.py", line 54, in wrapped_view
    return view_func(*args, **kwargs)
  File "/Library/Frameworks/Python.framework/Versions/3.10/lib/python3.10/site-packages/django/views/generic/base.py", line 103, in view
    return self.dispatch(request, *args, **kwargs)
  File "/Library/Frameworks/Python.framework/Versions/3.10/lib/python3.10/site-packages/rest_framework/views.py", line 509, in dispatch
    response = self.handle_exception(exc)
  File "/Library/Frameworks/Python.framework/Versions/3.10/lib/python3.10/site-packages/rest_framework/views.py", line 469, in handle_exception
    self.raise_uncaught_exception(exc)
  File "/Library/Frameworks/Python.framework/Versions/3.10/lib/python3.10/site-packages/rest_framework/views.py", line 480, in raise_uncaught_exception
    raise exc
  File "/Library/Frameworks/Python.framework/Versions/3.10/lib/python3.10/site-packages/rest_framework/views.py", line 506, in dispatch
    response = handler(request, *args, **kwargs)
  File "/Volumes/Volume/untitled folder 2/ct/app/msbctracker/views.py", line 959, in patch
    for new_t in origin_info:
TypeError: 'NoneType' object is not iterable
/Volumes/Volume/untitled folder 2/ct/app/msbctracker/views.py changed, reloading.
Watching for file changes with StatReloader
Internal Server Error: /api/TrackingDetails
Traceback (most recent call last):
  File "/Library/Frameworks/Python.framework/Versions/3.10/lib/python3.10/site-packages/django/core/handlers/exception.py", line 55, in inner
    response = get_response(request)
  File "/Library/Frameworks/Python.framework/Versions/3.10/lib/python3.10/site-packages/django/core/handlers/base.py", line 197, in _get_response
    response = wrapped_callback(request, *callback_args, **callback_kwargs)
  File "/Library/Frameworks/Python.framework/Versions/3.10/lib/python3.10/site-packages/django/views/decorators/csrf.py", line 54, in wrapped_view
    return view_func(*args, **kwargs)
  File "/Library/Frameworks/Python.framework/Versions/3.10/lib/python3.10/site-packages/django/views/generic/base.py", line 103, in view
    return self.dispatch(request, *args, **kwargs)
  File "/Library/Frameworks/Python.framework/Versions/3.10/lib/python3.10/site-packages/rest_framework/views.py", line 509, in dispatch
    response = self.handle_exception(exc)
  File "/Library/Frameworks/Python.framework/Versions/3.10/lib/python3.10/site-packages/rest_framework/views.py", line 469, in handle_exception
    self.raise_uncaught_exception(exc)
  File "/Library/Frameworks/Python.framework/Versions/3.10/lib/python3.10/site-packages/rest_framework/views.py", line 480, in raise_uncaught_exception
    raise exc
  File "/Library/Frameworks/Python.framework/Versions/3.10/lib/python3.10/site-packages/rest_framework/views.py", line 506, in dispatch
    response = handler(request, *args, **kwargs)
  File "/Volumes/Volume/untitled folder 2/ct/app/msbctracker/views.py", line 959, in patch
    for new_t in origin_info:
TypeError: 'NoneType' object is not iterable
/Volumes/Volume/untitled folder 2/ct/app/msbctracker/views.py changed, reloading.
Watching for file changes with StatReloader
/Volumes/Volume/untitled folder 2/ct/app/msbctracker/views.py changed, reloading.
Watching for file changes with StatReloader
Internal Server Error: /api/TrackingDetails
Traceback (most recent call last):
  File "/Library/Frameworks/Python.framework/Versions/3.10/lib/python3.10/site-packages/django/core/handlers/exception.py", line 55, in inner
    response = get_response(request)
  File "/Library/Frameworks/Python.framework/Versions/3.10/lib/python3.10/site-packages/django/core/handlers/base.py", line 197, in _get_response
    response = wrapped_callback(request, *callback_args, **callback_kwargs)
  File "/Library/Frameworks/Python.framework/Versions/3.10/lib/python3.10/site-packages/django/views/decorators/csrf.py", line 54, in wrapped_view
    return view_func(*args, **kwargs)
  File "/Library/Frameworks/Python.framework/Versions/3.10/lib/python3.10/site-packages/django/views/generic/base.py", line 103, in view
    return self.dispatch(request, *args, **kwargs)
  File "/Library/Frameworks/Python.framework/Versions/3.10/lib/python3.10/site-packages/rest_framework/views.py", line 509, in dispatch
    response = self.handle_exception(exc)
  File "/Library/Frameworks/Python.framework/Versions/3.10/lib/python3.10/site-packages/rest_framework/views.py", line 469, in handle_exception
    self.raise_uncaught_exception(exc)
  File "/Library/Frameworks/Python.framework/Versions/3.10/lib/python3.10/site-packages/rest_framework/views.py", line 480, in raise_uncaught_exception
    raise exc
  File "/Library/Frameworks/Python.framework/Versions/3.10/lib/python3.10/site-packages/rest_framework/views.py", line 506, in dispatch
    response = handler(request, *args, **kwargs)
  File "/Volumes/Volume/untitled folder 2/ct/app/msbctracker/views.py", line 958, in patch
    for new_t in origin_info:
TypeError: 'NoneType' object is not iterable
/Volumes/Volume/untitled folder 2/ct/app/msbctracker/views.py changed, reloading.
Watching for file changes with StatReloader
/Volumes/Volume/untitled folder 2/ct/app/msbctracker/views.py changed, reloading.
Watching for file changes with StatReloader
/Volumes/Volume/untitled folder 2/ct/app/msbctracker/views.py changed, reloading.
Watching for file changes with StatReloader
/Volumes/Volume/untitled folder 2/ct/app/msbctracker/views.py changed, reloading.
Watching for file changes with StatReloader
/Volumes/Volume/untitled folder 2/ct/app/msbctracker/views.py changed, reloading.
Watching for file changes with StatReloader
/Volumes/Volume/untitled folder 2/ct/app/msbctracker/views.py changed, reloading.
Watching for file changes with StatReloader
/Volumes/Volume/untitled folder 2/ct/app/msbctracker/views.py changed, reloading.
Watching for file changes with StatReloader
/Volumes/Volume/untitled folder 2/ct/app/msbctracker/views.py changed, reloading.
Watching for file changes with StatReloader
/Volumes/Volume/untitled folder 2/ct/app/msbctracker/views.py changed, reloading.
Watching for file changes with StatReloader
/Volumes/Volume/untitled folder 2/ct/app/msbctracker/views.py changed, reloading.
Watching for file changes with StatReloader
/Volumes/Volume/untitled folder 2/ct/app/msbctracker/views.py changed, reloading.
Watching for file changes with StatReloader
/Volumes/Volume/untitled folder 2/ct/app/msbctracker/views.py changed, reloading.
Watching for file changes with StatReloader
/Volumes/Volume/untitled folder 2/ct/app/msbctracker/views.py changed, reloading.
Watching for file changes with StatReloader
/Volumes/Volume/untitled folder 2/ct/app/msbctracker/views.py changed, reloading.
Watching for file changes with StatReloader
/Volumes/Volume/untitled folder 2/ct/app/msbctracker/views.py changed, reloading.
Watching for file changes with StatReloader
/Volumes/Volume/untitled folder 2/ct/app/msbctracker/views.py changed, reloading.
Watching for file changes with StatReloader
Internal Server Error: /api/TrackingDetails
Traceback (most recent call last):
  File "/Library/Frameworks/Python.framework/Versions/3.10/lib/python3.10/site-packages/django/core/handlers/exception.py", line 55, in inner
    response = get_response(request)
  File "/Library/Frameworks/Python.framework/Versions/3.10/lib/python3.10/site-packages/django/core/handlers/base.py", line 197, in _get_response
    response = wrapped_callback(request, *callback_args, **callback_kwargs)
  File "/Library/Frameworks/Python.framework/Versions/3.10/lib/python3.10/site-packages/django/views/decorators/csrf.py", line 54, in wrapped_view
    return view_func(*args, **kwargs)
  File "/Library/Frameworks/Python.framework/Versions/3.10/lib/python3.10/site-packages/django/views/generic/base.py", line 103, in view
    return self.dispatch(request, *args, **kwargs)
  File "/Library/Frameworks/Python.framework/Versions/3.10/lib/python3.10/site-packages/rest_framework/views.py", line 509, in dispatch
    response = self.handle_exception(exc)
  File "/Library/Frameworks/Python.framework/Versions/3.10/lib/python3.10/site-packages/rest_framework/views.py", line 469, in handle_exception
    self.raise_uncaught_exception(exc)
  File "/Library/Frameworks/Python.framework/Versions/3.10/lib/python3.10/site-packages/rest_framework/views.py", line 480, in raise_uncaught_exception
    raise exc
  File "/Library/Frameworks/Python.framework/Versions/3.10/lib/python3.10/site-packages/rest_framework/views.py", line 506, in dispatch
    response = handler(request, *args, **kwargs)
  File "/Volumes/Volume/untitled folder 2/ct/app/msbctracker/views.py", line 773, in get
    for new_t in origin_info:
TypeError: 'NoneType' object is not iterable
/Volumes/Volume/untitled folder 2/ct/app/msbctracker/views.py changed, reloading.
Watching for file changes with StatReloader
/Volumes/Volume/untitled folder 2/ct/app/msbctracker/views.py changed, reloading.
Watching for file changes with StatReloader
/Volumes/Volume/untitled folder 2/ct/app/msbctracker/views.py changed, reloading.
Watching for file changes with StatReloader
/Volumes/Volume/untitled folder 2/ct/app/msbctracker/views.py changed, reloading.
Watching for file changes with StatReloader
/Volumes/Volume/untitled folder 2/ct/app/msbctracker/views.py changed, reloading.
Watching for file changes with StatReloader
/Volumes/Volume/untitled folder 2/ct/app/msbctracker/views.py changed, reloading.
Watching for file changes with StatReloader
Internal Server Error: /api/TrackingDetails
Traceback (most recent call last):
  File "/Library/Frameworks/Python.framework/Versions/3.10/lib/python3.10/site-packages/django/core/handlers/exception.py", line 55, in inner
    response = get_response(request)
  File "/Library/Frameworks/Python.framework/Versions/3.10/lib/python3.10/site-packages/django/core/handlers/base.py", line 197, in _get_response
    response = wrapped_callback(request, *callback_args, **callback_kwargs)
  File "/Library/Frameworks/Python.framework/Versions/3.10/lib/python3.10/site-packages/django/views/decorators/csrf.py", line 54, in wrapped_view
    return view_func(*args, **kwargs)
  File "/Library/Frameworks/Python.framework/Versions/3.10/lib/python3.10/site-packages/django/views/generic/base.py", line 103, in view
    return self.dispatch(request, *args, **kwargs)
  File "/Library/Frameworks/Python.framework/Versions/3.10/lib/python3.10/site-packages/rest_framework/views.py", line 509, in dispatch
    response = self.handle_exception(exc)
  File "/Library/Frameworks/Python.framework/Versions/3.10/lib/python3.10/site-packages/rest_framework/views.py", line 469, in handle_exception
    self.raise_uncaught_exception(exc)
  File "/Library/Frameworks/Python.framework/Versions/3.10/lib/python3.10/site-packages/rest_framework/views.py", line 480, in raise_uncaught_exception
    raise exc
  File "/Library/Frameworks/Python.framework/Versions/3.10/lib/python3.10/site-packages/rest_framework/views.py", line 506, in dispatch
    response = handler(request, *args, **kwargs)
  File "/Volumes/Volume/untitled folder 2/ct/app/msbctracker/views.py", line 781, in get
    for new_t in origin_info:
TypeError: 'NoneType' object is not iterable
/Volumes/Volume/untitled folder 2/ct/app/msbctracker/views.py changed, reloading.
Watching for file changes with StatReloader
Internal Server Error: /api/TrackingDetails
Traceback (most recent call last):
  File "/Library/Frameworks/Python.framework/Versions/3.10/lib/python3.10/site-packages/django/core/handlers/exception.py", line 55, in inner
    response = get_response(request)
  File "/Library/Frameworks/Python.framework/Versions/3.10/lib/python3.10/site-packages/django/core/handlers/base.py", line 197, in _get_response
    response = wrapped_callback(request, *callback_args, **callback_kwargs)
  File "/Library/Frameworks/Python.framework/Versions/3.10/lib/python3.10/site-packages/django/views/decorators/csrf.py", line 54, in wrapped_view
    return view_func(*args, **kwargs)
  File "/Library/Frameworks/Python.framework/Versions/3.10/lib/python3.10/site-packages/django/views/generic/base.py", line 103, in view
    return self.dispatch(request, *args, **kwargs)
  File "/Library/Frameworks/Python.framework/Versions/3.10/lib/python3.10/site-packages/rest_framework/views.py", line 509, in dispatch
    response = self.handle_exception(exc)
  File "/Library/Frameworks/Python.framework/Versions/3.10/lib/python3.10/site-packages/rest_framework/views.py", line 469, in handle_exception
    self.raise_uncaught_exception(exc)
  File "/Library/Frameworks/Python.framework/Versions/3.10/lib/python3.10/site-packages/rest_framework/views.py", line 480, in raise_uncaught_exception
    raise exc
  File "/Library/Frameworks/Python.framework/Versions/3.10/lib/python3.10/site-packages/rest_framework/views.py", line 506, in dispatch
    response = handler(request, *args, **kwargs)
  File "/Volumes/Volume/untitled folder 2/ct/app/msbctracker/views.py", line 787, in get
    for new_t in origin_info:
TypeError: 'NoneType' object is not iterable
/Volumes/Volume/untitled folder 2/ct/app/msbctracker/views.py changed, reloading.
Watching for file changes with StatReloader
/Volumes/Volume/untitled folder 2/ct/app/msbctracker/views.py changed, reloading.
Watching for file changes with StatReloader
/Volumes/Volume/untitled folder 2/ct/app/msbctracker/views.py changed, reloading.
Watching for file changes with StatReloader
Watching for file changes with StatReloader
/Volumes/Volume/untitled folder 2/ct/app/msbctracker/views.py changed, reloading.
Watching for file changes with StatReloader
/Volumes/Volume/untitled folder 2/ct/app/msbctracker/views.py changed, reloading.
Watching for file changes with StatReloader
/Volumes/Volume/untitled folder 2/ct/app/msbctracker/views.py changed, reloading.
Watching for file changes with StatReloader
Internal Server Error: /api/TrackingDetails
Traceback (most recent call last):
  File "/Library/Frameworks/Python.framework/Versions/3.10/lib/python3.10/site-packages/django/core/handlers/exception.py", line 55, in inner
    response = get_response(request)
  File "/Library/Frameworks/Python.framework/Versions/3.10/lib/python3.10/site-packages/django/core/handlers/base.py", line 197, in _get_response
    response = wrapped_callback(request, *callback_args, **callback_kwargs)
  File "/Library/Frameworks/Python.framework/Versions/3.10/lib/python3.10/site-packages/django/views/decorators/csrf.py", line 54, in wrapped_view
    return view_func(*args, **kwargs)
  File "/Library/Frameworks/Python.framework/Versions/3.10/lib/python3.10/site-packages/django/views/generic/base.py", line 103, in view
    return self.dispatch(request, *args, **kwargs)
  File "/Library/Frameworks/Python.framework/Versions/3.10/lib/python3.10/site-packages/rest_framework/views.py", line 509, in dispatch
    response = self.handle_exception(exc)
  File "/Library/Frameworks/Python.framework/Versions/3.10/lib/python3.10/site-packages/rest_framework/views.py", line 469, in handle_exception
    self.raise_uncaught_exception(exc)
  File "/Library/Frameworks/Python.framework/Versions/3.10/lib/python3.10/site-packages/rest_framework/views.py", line 480, in raise_uncaught_exception
    raise exc
  File "/Library/Frameworks/Python.framework/Versions/3.10/lib/python3.10/site-packages/rest_framework/views.py", line 506, in dispatch
    response = handler(request, *args, **kwargs)
  File "/Volumes/Volume/untitled folder 2/ct/app/msbctracker/views.py", line 961, in patch
    for new_t in origin_info:
TypeError: 'NoneType' object is not iterable
/Volumes/Volume/untitled folder 2/ct/app/msbctracker/views.py changed, reloading.
Watching for file changes with StatReloader
/Volumes/Volume/untitled folder 2/ct/app/msbctracker/views.py changed, reloading.
Watching for file changes with StatReloader
/Volumes/Volume/untitled folder 2/ct/app/msbctracker/views.py changed, reloading.
Watching for file changes with StatReloader
Internal Server Error: /api/TrackingDetails
Traceback (most recent call last):
  File "/Library/Frameworks/Python.framework/Versions/3.10/lib/python3.10/site-packages/django/core/handlers/exception.py", line 55, in inner
    response = get_response(request)
  File "/Library/Frameworks/Python.framework/Versions/3.10/lib/python3.10/site-packages/django/core/handlers/base.py", line 197, in _get_response
    response = wrapped_callback(request, *callback_args, **callback_kwargs)
  File "/Library/Frameworks/Python.framework/Versions/3.10/lib/python3.10/site-packages/django/views/decorators/csrf.py", line 54, in wrapped_view
    return view_func(*args, **kwargs)
  File "/Library/Frameworks/Python.framework/Versions/3.10/lib/python3.10/site-packages/django/views/generic/base.py", line 103, in view
    return self.dispatch(request, *args, **kwargs)
  File "/Library/Frameworks/Python.framework/Versions/3.10/lib/python3.10/site-packages/rest_framework/views.py", line 509, in dispatch
    response = self.handle_exception(exc)
  File "/Library/Frameworks/Python.framework/Versions/3.10/lib/python3.10/site-packages/rest_framework/views.py", line 469, in handle_exception
    self.raise_uncaught_exception(exc)
  File "/Library/Frameworks/Python.framework/Versions/3.10/lib/python3.10/site-packages/rest_framework/views.py", line 480, in raise_uncaught_exception
    raise exc
  File "/Library/Frameworks/Python.framework/Versions/3.10/lib/python3.10/site-packages/rest_framework/views.py", line 506, in dispatch
    response = handler(request, *args, **kwargs)
  File "/Volumes/Volume/untitled folder 2/ct/app/msbctracker/views.py", line 969, in patch
    for new_t in origin_info:
TypeError: 'NoneType' object is not iterable
/Volumes/Volume/untitled folder 2/ct/app/msbctracker/views.py changed, reloading.
Watching for file changes with StatReloader
Internal Server Error: /api/TrackingDetails
Traceback (most recent call last):
  File "/Library/Frameworks/Python.framework/Versions/3.10/lib/python3.10/site-packages/django/core/handlers/exception.py", line 55, in inner
    response = get_response(request)
  File "/Library/Frameworks/Python.framework/Versions/3.10/lib/python3.10/site-packages/django/core/handlers/base.py", line 197, in _get_response
    response = wrapped_callback(request, *callback_args, **callback_kwargs)
  File "/Library/Frameworks/Python.framework/Versions/3.10/lib/python3.10/site-packages/django/views/decorators/csrf.py", line 54, in wrapped_view
    return view_func(*args, **kwargs)
  File "/Library/Frameworks/Python.framework/Versions/3.10/lib/python3.10/site-packages/django/views/generic/base.py", line 103, in view
    return self.dispatch(request, *args, **kwargs)
  File "/Library/Frameworks/Python.framework/Versions/3.10/lib/python3.10/site-packages/rest_framework/views.py", line 509, in dispatch
    response = self.handle_exception(exc)
  File "/Library/Frameworks/Python.framework/Versions/3.10/lib/python3.10/site-packages/rest_framework/views.py", line 469, in handle_exception
    self.raise_uncaught_exception(exc)
  File "/Library/Frameworks/Python.framework/Versions/3.10/lib/python3.10/site-packages/rest_framework/views.py", line 480, in raise_uncaught_exception
    raise exc
  File "/Library/Frameworks/Python.framework/Versions/3.10/lib/python3.10/site-packages/rest_framework/views.py", line 506, in dispatch
    response = handler(request, *args, **kwargs)
  File "/Volumes/Volume/untitled folder 2/ct/app/msbctracker/views.py", line 969, in patch
    for new_t in origin_info:
TypeError: 'NoneType' object is not iterable
/Volumes/Volume/untitled folder 2/ct/app/msbctracker/views.py changed, reloading.
Watching for file changes with StatReloader
/Volumes/Volume/untitled folder 2/ct/app/msbctracker/views.py changed, reloading.
Watching for file changes with StatReloader
/Volumes/Volume/untitled folder 2/ct/app/msbctracker/views.py changed, reloading.
Watching for file changes with StatReloader
/Volumes/Volume/untitled folder 2/ct/app/msbctracker/views.py changed, reloading.
Watching for file changes with StatReloader
Internal Server Error: /api/TrackingDetails
Traceback (most recent call last):
  File "/Library/Frameworks/Python.framework/Versions/3.10/lib/python3.10/site-packages/django/core/handlers/exception.py", line 55, in inner
    response = get_response(request)
  File "/Library/Frameworks/Python.framework/Versions/3.10/lib/python3.10/site-packages/django/core/handlers/base.py", line 197, in _get_response
    response = wrapped_callback(request, *callback_args, **callback_kwargs)
  File "/Library/Frameworks/Python.framework/Versions/3.10/lib/python3.10/site-packages/django/views/decorators/csrf.py", line 54, in wrapped_view
    return view_func(*args, **kwargs)
  File "/Library/Frameworks/Python.framework/Versions/3.10/lib/python3.10/site-packages/django/views/generic/base.py", line 103, in view
    return self.dispatch(request, *args, **kwargs)
  File "/Library/Frameworks/Python.framework/Versions/3.10/lib/python3.10/site-packages/rest_framework/views.py", line 509, in dispatch
    response = self.handle_exception(exc)
  File "/Library/Frameworks/Python.framework/Versions/3.10/lib/python3.10/site-packages/rest_framework/views.py", line 469, in handle_exception
    self.raise_uncaught_exception(exc)
  File "/Library/Frameworks/Python.framework/Versions/3.10/lib/python3.10/site-packages/rest_framework/views.py", line 480, in raise_uncaught_exception
    raise exc
  File "/Library/Frameworks/Python.framework/Versions/3.10/lib/python3.10/site-packages/rest_framework/views.py", line 506, in dispatch
    response = handler(request, *args, **kwargs)
  File "/Volumes/Volume/untitled folder 2/ct/app/msbctracker/views.py", line 969, in patch
    for new_t in origin_info:
TypeError: 'NoneType' object is not iterable
/Volumes/Volume/untitled folder 2/ct/app/msbctracker/views.py changed, reloading.
Watching for file changes with StatReloader
Watching for file changes with StatReloader
/Volumes/Volume/untitled folder 2/ct/app/msbctracker/views.py changed, reloading.
Watching for file changes with StatReloader
/Volumes/Volume/untitled folder 2/ct/app/msbctracker/views.py changed, reloading.
Watching for file changes with StatReloader
/Volumes/Volume/untitled folder 2/ct/app/msbctracker/views.py changed, reloading.
Watching for file changes with StatReloader
/Volumes/Volume/untitled folder 2/ct/app/msbctracker/views.py changed, reloading.
Watching for file changes with StatReloader
/Volumes/Volume/untitled folder 2/ct/app/msbctracker/views.py changed, reloading.
Watching for file changes with StatReloader
/Volumes/Volume/untitled folder 2/ct/app/msbctracker/views.py changed, reloading.
Watching for file changes with StatReloader
/Volumes/Volume/untitled folder 2/ct/app/msbctracker/views.py changed, reloading.
Watching for file changes with StatReloader
/Volumes/Volume/untitled folder 2/ct/app/msbctracker/views.py changed, reloading.
Watching for file changes with StatReloader
/Volumes/Volume/untitled folder 2/ct/app/msbctracker/views.py changed, reloading.
Watching for file changes with StatReloader
/Volumes/Volume/untitled folder 2/ct/app/msbctracker/views.py changed, reloading.
Watching for file changes with StatReloader
/Volumes/Volume/untitled folder 2/ct/app/msbctracker/views.py changed, reloading.
Watching for file changes with StatReloader
/Volumes/Volume/untitled folder 2/ct/app/msbctracker/views.py changed, reloading.
Watching for file changes with StatReloader
/Volumes/Volume/untitled folder 2/ct/app/msbctracker/views.py changed, reloading.
Watching for file changes with StatReloader
/Volumes/Volume/untitled folder 2/ct/app/msbctracker/views.py changed, reloading.
Watching for file changes with StatReloader
/Volumes/Volume/untitled folder 2/ct/app/msbctracker/views.py changed, reloading.
Watching for file changes with StatReloader
/Volumes/Volume/untitled folder 2/ct/app/msbctracker/views.py changed, reloading.
Watching for file changes with StatReloader
/Volumes/Volume/untitled folder 2/ct/app/msbctracker/views.py changed, reloading.
Watching for file changes with StatReloader
Watching for file changes with StatReloader
Not Found: /
Watching for file changes with StatReloader
/Volumes/Volume/untitled folder 2/ct/app/msbctracker/views.py changed, reloading.
Watching for file changes with StatReloader
/Volumes/Volume/untitled folder 2/ct/app/msbctracker/views.py changed, reloading.
Watching for file changes with StatReloader
/Volumes/Volume/untitled folder 2/ct/app/msbctracker/views.py changed, reloading.
Watching for file changes with StatReloader
/Volumes/Volume/untitled folder 2/ct/app/msbctracker/views.py changed, reloading.
Watching for file changes with StatReloader
/Volumes/Volume/untitled folder 2/ct/app/msbctracker/views.py changed, reloading.
Watching for file changes with StatReloader
Watching for file changes with StatReloader
/Volumes/Volume/untitled folder 2/ct/app/msbctracker/views.py changed, reloading.
Watching for file changes with StatReloader
/Volumes/Volume/untitled folder 2/ct/app/msbctracker/views.py changed, reloading.
Watching for file changes with StatReloader
/Volumes/Volume/untitled folder 2/ct/app/msbctracker/views.py changed, reloading.
Watching for file changes with StatReloader
/Volumes/Volume/untitled folder 2/ct/app/msbctracker/views.py changed, reloading.
Watching for file changes with StatReloader
/Volumes/Volume/untitled folder 2/ct/app/msbctracker/views.py changed, reloading.
Watching for file changes with StatReloader
/Volumes/Volume/untitled folder 2/ct/app/msbctracker/views.py changed, reloading.
Watching for file changes with StatReloader
/Volumes/Volume/untitled folder 2/ct/app/msbctracker/views.py changed, reloading.
Watching for file changes with StatReloader
/Volumes/Volume/untitled folder 2/ct/app/msbctracker/views.py changed, reloading.
Watching for file changes with StatReloader
/Volumes/Volume/untitled folder 2/ct/app/msbctracker/views.py changed, reloading.
Watching for file changes with StatReloader
Watching for file changes with StatReloader
/Volumes/Volume/untitled folder 2/ct/app/msbctracker/views.py changed, reloading.
Watching for file changes with StatReloader
/Volumes/Volume/untitled folder 2/ct/app/msbctracker/views.py changed, reloading.
Watching for file changes with StatReloader
/Volumes/Volume/untitled folder 2/ct/app/msbctracker/views.py changed, reloading.
Watching for file changes with StatReloader
/Volumes/Volume/untitled folder 2/ct/app/msbctracker/views.py changed, reloading.
Watching for file changes with StatReloader
Internal Server Error: /api/TrackingDetails
Traceback (most recent call last):
  File "/Library/Frameworks/Python.framework/Versions/3.10/lib/python3.10/site-packages/urllib3/connection.py", line 174, in _new_conn
    conn = connection.create_connection(
  File "/Library/Frameworks/Python.framework/Versions/3.10/lib/python3.10/site-packages/urllib3/util/connection.py", line 95, in create_connection
    raise err
  File "/Library/Frameworks/Python.framework/Versions/3.10/lib/python3.10/site-packages/urllib3/util/connection.py", line 85, in create_connection
    sock.connect(sa)
TimeoutError: [Errno 60] Operation timed out

During handling of the above exception, another exception occurred:

Traceback (most recent call last):
  File "/Library/Frameworks/Python.framework/Versions/3.10/lib/python3.10/site-packages/urllib3/connectionpool.py", line 703, in urlopen
    httplib_response = self._make_request(
  File "/Library/Frameworks/Python.framework/Versions/3.10/lib/python3.10/site-packages/urllib3/connectionpool.py", line 386, in _make_request
    self._validate_conn(conn)
  File "/Library/Frameworks/Python.framework/Versions/3.10/lib/python3.10/site-packages/urllib3/connectionpool.py", line 1042, in _validate_conn
    conn.connect()
  File "/Library/Frameworks/Python.framework/Versions/3.10/lib/python3.10/site-packages/urllib3/connection.py", line 358, in connect
    self.sock = conn = self._new_conn()
  File "/Library/Frameworks/Python.framework/Versions/3.10/lib/python3.10/site-packages/urllib3/connection.py", line 179, in _new_conn
    raise ConnectTimeoutError(
urllib3.exceptions.ConnectTimeoutError: (<urllib3.connection.HTTPSConnection object at 0x118450460>, 'Connection to api.tracktry.com timed out. (connect timeout=None)')

During handling of the above exception, another exception occurred:

Traceback (most recent call last):
  File "/Library/Frameworks/Python.framework/Versions/3.10/lib/python3.10/site-packages/requests/adapters.py", line 489, in send
    resp = conn.urlopen(
  File "/Library/Frameworks/Python.framework/Versions/3.10/lib/python3.10/site-packages/urllib3/connectionpool.py", line 787, in urlopen
    retries = retries.increment(
  File "/Library/Frameworks/Python.framework/Versions/3.10/lib/python3.10/site-packages/urllib3/util/retry.py", line 592, in increment
    raise MaxRetryError(_pool, url, error or ResponseError(cause))
urllib3.exceptions.MaxRetryError: HTTPSConnectionPool(host='api.tracktry.com', port=443): Max retries exceeded with url: /v1/trackings/get (Caused by ConnectTimeoutError(<urllib3.connection.HTTPSConnection object at 0x118450460>, 'Connection to api.tracktry.com timed out. (connect timeout=None)'))

During handling of the above exception, another exception occurred:

Traceback (most recent call last):
  File "/Library/Frameworks/Python.framework/Versions/3.10/lib/python3.10/site-packages/django/core/handlers/exception.py", line 55, in inner
    response = get_response(request)
  File "/Library/Frameworks/Python.framework/Versions/3.10/lib/python3.10/site-packages/django/core/handlers/base.py", line 197, in _get_response
    response = wrapped_callback(request, *callback_args, **callback_kwargs)
  File "/Library/Frameworks/Python.framework/Versions/3.10/lib/python3.10/site-packages/django/views/decorators/csrf.py", line 54, in wrapped_view
    return view_func(*args, **kwargs)
  File "/Library/Frameworks/Python.framework/Versions/3.10/lib/python3.10/site-packages/django/views/generic/base.py", line 103, in view
    return self.dispatch(request, *args, **kwargs)
  File "/Library/Frameworks/Python.framework/Versions/3.10/lib/python3.10/site-packages/rest_framework/views.py", line 509, in dispatch
    response = self.handle_exception(exc)
  File "/Library/Frameworks/Python.framework/Versions/3.10/lib/python3.10/site-packages/rest_framework/views.py", line 469, in handle_exception
    self.raise_uncaught_exception(exc)
  File "/Library/Frameworks/Python.framework/Versions/3.10/lib/python3.10/site-packages/rest_framework/views.py", line 480, in raise_uncaught_exception
    raise exc
  File "/Library/Frameworks/Python.framework/Versions/3.10/lib/python3.10/site-packages/rest_framework/views.py", line 506, in dispatch
    response = handler(request, *args, **kwargs)
  File "/Volumes/Volume/untitled folder 2/ct/app/msbctracker/views.py", line 755, in get
    te = track()
  File "/Volumes/Volume/untitled folder 2/ct/app/msbctracker/views.py", line 98, in track
    response = requests.get(api_url, headers=headers)
  File "/Library/Frameworks/Python.framework/Versions/3.10/lib/python3.10/site-packages/requests/api.py", line 73, in get
    return request("get", url, params=params, **kwargs)
  File "/Library/Frameworks/Python.framework/Versions/3.10/lib/python3.10/site-packages/requests/api.py", line 59, in request
    return session.request(method=method, url=url, **kwargs)
  File "/Library/Frameworks/Python.framework/Versions/3.10/lib/python3.10/site-packages/requests/sessions.py", line 587, in request
    resp = self.send(prep, **send_kwargs)
  File "/Library/Frameworks/Python.framework/Versions/3.10/lib/python3.10/site-packages/requests/sessions.py", line 701, in send
    r = adapter.send(request, **kwargs)
  File "/Library/Frameworks/Python.framework/Versions/3.10/lib/python3.10/site-packages/requests/adapters.py", line 553, in send
    raise ConnectTimeout(e, request=request)
requests.exceptions.ConnectTimeout: HTTPSConnectionPool(host='api.tracktry.com', port=443): Max retries exceeded with url: /v1/trackings/get (Caused by ConnectTimeoutError(<urllib3.connection.HTTPSConnection object at 0x118450460>, 'Connection to api.tracktry.com timed out. (connect timeout=None)'))
Internal Server Error: /api/TrackingDetails
Traceback (most recent call last):
  File "/Library/Frameworks/Python.framework/Versions/3.10/lib/python3.10/site-packages/urllib3/connection.py", line 174, in _new_conn
    conn = connection.create_connection(
  File "/Library/Frameworks/Python.framework/Versions/3.10/lib/python3.10/site-packages/urllib3/util/connection.py", line 95, in create_connection
    raise err
  File "/Library/Frameworks/Python.framework/Versions/3.10/lib/python3.10/site-packages/urllib3/util/connection.py", line 85, in create_connection
    sock.connect(sa)
TimeoutError: [Errno 60] Operation timed out

During handling of the above exception, another exception occurred:

Traceback (most recent call last):
  File "/Library/Frameworks/Python.framework/Versions/3.10/lib/python3.10/site-packages/urllib3/connectionpool.py", line 703, in urlopen
    httplib_response = self._make_request(
  File "/Library/Frameworks/Python.framework/Versions/3.10/lib/python3.10/site-packages/urllib3/connectionpool.py", line 386, in _make_request
    self._validate_conn(conn)
  File "/Library/Frameworks/Python.framework/Versions/3.10/lib/python3.10/site-packages/urllib3/connectionpool.py", line 1042, in _validate_conn
    conn.connect()
  File "/Library/Frameworks/Python.framework/Versions/3.10/lib/python3.10/site-packages/urllib3/connection.py", line 358, in connect
    self.sock = conn = self._new_conn()
  File "/Library/Frameworks/Python.framework/Versions/3.10/lib/python3.10/site-packages/urllib3/connection.py", line 179, in _new_conn
    raise ConnectTimeoutError(
urllib3.exceptions.ConnectTimeoutError: (<urllib3.connection.HTTPSConnection object at 0x118450910>, 'Connection to api.tracktry.com timed out. (connect timeout=None)')

During handling of the above exception, another exception occurred:

Traceback (most recent call last):
  File "/Library/Frameworks/Python.framework/Versions/3.10/lib/python3.10/site-packages/requests/adapters.py", line 489, in send
    resp = conn.urlopen(
  File "/Library/Frameworks/Python.framework/Versions/3.10/lib/python3.10/site-packages/urllib3/connectionpool.py", line 787, in urlopen
    retries = retries.increment(
  File "/Library/Frameworks/Python.framework/Versions/3.10/lib/python3.10/site-packages/urllib3/util/retry.py", line 592, in increment
    raise MaxRetryError(_pool, url, error or ResponseError(cause))
urllib3.exceptions.MaxRetryError: HTTPSConnectionPool(host='api.tracktry.com', port=443): Max retries exceeded with url: /v1/trackings/get (Caused by ConnectTimeoutError(<urllib3.connection.HTTPSConnection object at 0x118450910>, 'Connection to api.tracktry.com timed out. (connect timeout=None)'))

During handling of the above exception, another exception occurred:

Traceback (most recent call last):
  File "/Library/Frameworks/Python.framework/Versions/3.10/lib/python3.10/site-packages/django/core/handlers/exception.py", line 55, in inner
    response = get_response(request)
  File "/Library/Frameworks/Python.framework/Versions/3.10/lib/python3.10/site-packages/django/core/handlers/base.py", line 197, in _get_response
    response = wrapped_callback(request, *callback_args, **callback_kwargs)
  File "/Library/Frameworks/Python.framework/Versions/3.10/lib/python3.10/site-packages/django/views/decorators/csrf.py", line 54, in wrapped_view
    return view_func(*args, **kwargs)
  File "/Library/Frameworks/Python.framework/Versions/3.10/lib/python3.10/site-packages/django/views/generic/base.py", line 103, in view
    return self.dispatch(request, *args, **kwargs)
  File "/Library/Frameworks/Python.framework/Versions/3.10/lib/python3.10/site-packages/rest_framework/views.py", line 509, in dispatch
    response = self.handle_exception(exc)
  File "/Library/Frameworks/Python.framework/Versions/3.10/lib/python3.10/site-packages/rest_framework/views.py", line 469, in handle_exception
    self.raise_uncaught_exception(exc)
  File "/Library/Frameworks/Python.framework/Versions/3.10/lib/python3.10/site-packages/rest_framework/views.py", line 480, in raise_uncaught_exception
    raise exc
  File "/Library/Frameworks/Python.framework/Versions/3.10/lib/python3.10/site-packages/rest_framework/views.py", line 506, in dispatch
    response = handler(request, *args, **kwargs)
  File "/Volumes/Volume/untitled folder 2/ct/app/msbctracker/views.py", line 755, in get
    te = track()
  File "/Volumes/Volume/untitled folder 2/ct/app/msbctracker/views.py", line 98, in track
    response = requests.get(api_url, headers=headers)
  File "/Library/Frameworks/Python.framework/Versions/3.10/lib/python3.10/site-packages/requests/api.py", line 73, in get
    return request("get", url, params=params, **kwargs)
  File "/Library/Frameworks/Python.framework/Versions/3.10/lib/python3.10/site-packages/requests/api.py", line 59, in request
    return session.request(method=method, url=url, **kwargs)
  File "/Library/Frameworks/Python.framework/Versions/3.10/lib/python3.10/site-packages/requests/sessions.py", line 587, in request
    resp = self.send(prep, **send_kwargs)
  File "/Library/Frameworks/Python.framework/Versions/3.10/lib/python3.10/site-packages/requests/sessions.py", line 701, in send
    r = adapter.send(request, **kwargs)
  File "/Library/Frameworks/Python.framework/Versions/3.10/lib/python3.10/site-packages/requests/adapters.py", line 553, in send
    raise ConnectTimeout(e, request=request)
requests.exceptions.ConnectTimeout: HTTPSConnectionPool(host='api.tracktry.com', port=443): Max retries exceeded with url: /v1/trackings/get (Caused by ConnectTimeoutError(<urllib3.connection.HTTPSConnection object at 0x118450910>, 'Connection to api.tracktry.com timed out. (connect timeout=None)'))
Internal Server Error: /api/TrackingDetails
Traceback (most recent call last):
  File "/Library/Frameworks/Python.framework/Versions/3.10/lib/python3.10/site-packages/urllib3/connection.py", line 174, in _new_conn
    conn = connection.create_connection(
  File "/Library/Frameworks/Python.framework/Versions/3.10/lib/python3.10/site-packages/urllib3/util/connection.py", line 95, in create_connection
    raise err
  File "/Library/Frameworks/Python.framework/Versions/3.10/lib/python3.10/site-packages/urllib3/util/connection.py", line 85, in create_connection
    sock.connect(sa)
TimeoutError: [Errno 60] Operation timed out

During handling of the above exception, another exception occurred:

Traceback (most recent call last):
  File "/Library/Frameworks/Python.framework/Versions/3.10/lib/python3.10/site-packages/urllib3/connectionpool.py", line 703, in urlopen
    httplib_response = self._make_request(
  File "/Library/Frameworks/Python.framework/Versions/3.10/lib/python3.10/site-packages/urllib3/connectionpool.py", line 386, in _make_request
    self._validate_conn(conn)
  File "/Library/Frameworks/Python.framework/Versions/3.10/lib/python3.10/site-packages/urllib3/connectionpool.py", line 1042, in _validate_conn
    conn.connect()
  File "/Library/Frameworks/Python.framework/Versions/3.10/lib/python3.10/site-packages/urllib3/connection.py", line 358, in connect
    self.sock = conn = self._new_conn()
  File "/Library/Frameworks/Python.framework/Versions/3.10/lib/python3.10/site-packages/urllib3/connection.py", line 179, in _new_conn
    raise ConnectTimeoutError(
urllib3.exceptions.ConnectTimeoutError: (<urllib3.connection.HTTPSConnection object at 0x1183f3f70>, 'Connection to api.tracktry.com timed out. (connect timeout=None)')

During handling of the above exception, another exception occurred:

Traceback (most recent call last):
  File "/Library/Frameworks/Python.framework/Versions/3.10/lib/python3.10/site-packages/requests/adapters.py", line 489, in send
    resp = conn.urlopen(
  File "/Library/Frameworks/Python.framework/Versions/3.10/lib/python3.10/site-packages/urllib3/connectionpool.py", line 787, in urlopen
    retries = retries.increment(
  File "/Library/Frameworks/Python.framework/Versions/3.10/lib/python3.10/site-packages/urllib3/util/retry.py", line 592, in increment
    raise MaxRetryError(_pool, url, error or ResponseError(cause))
urllib3.exceptions.MaxRetryError: HTTPSConnectionPool(host='api.tracktry.com', port=443): Max retries exceeded with url: /v1/trackings/get (Caused by ConnectTimeoutError(<urllib3.connection.HTTPSConnection object at 0x1183f3f70>, 'Connection to api.tracktry.com timed out. (connect timeout=None)'))

During handling of the above exception, another exception occurred:

Traceback (most recent call last):
  File "/Library/Frameworks/Python.framework/Versions/3.10/lib/python3.10/site-packages/django/core/handlers/exception.py", line 55, in inner
    response = get_response(request)
  File "/Library/Frameworks/Python.framework/Versions/3.10/lib/python3.10/site-packages/django/core/handlers/base.py", line 197, in _get_response
    response = wrapped_callback(request, *callback_args, **callback_kwargs)
  File "/Library/Frameworks/Python.framework/Versions/3.10/lib/python3.10/site-packages/django/views/decorators/csrf.py", line 54, in wrapped_view
    return view_func(*args, **kwargs)
  File "/Library/Frameworks/Python.framework/Versions/3.10/lib/python3.10/site-packages/django/views/generic/base.py", line 103, in view
    return self.dispatch(request, *args, **kwargs)
  File "/Library/Frameworks/Python.framework/Versions/3.10/lib/python3.10/site-packages/rest_framework/views.py", line 509, in dispatch
    response = self.handle_exception(exc)
  File "/Library/Frameworks/Python.framework/Versions/3.10/lib/python3.10/site-packages/rest_framework/views.py", line 469, in handle_exception
    self.raise_uncaught_exception(exc)
  File "/Library/Frameworks/Python.framework/Versions/3.10/lib/python3.10/site-packages/rest_framework/views.py", line 480, in raise_uncaught_exception
    raise exc
  File "/Library/Frameworks/Python.framework/Versions/3.10/lib/python3.10/site-packages/rest_framework/views.py", line 506, in dispatch
    response = handler(request, *args, **kwargs)
  File "/Volumes/Volume/untitled folder 2/ct/app/msbctracker/views.py", line 755, in get
    te = track()
  File "/Volumes/Volume/untitled folder 2/ct/app/msbctracker/views.py", line 98, in track
    response = requests.get(api_url, headers=headers)
  File "/Library/Frameworks/Python.framework/Versions/3.10/lib/python3.10/site-packages/requests/api.py", line 73, in get
    return request("get", url, params=params, **kwargs)
  File "/Library/Frameworks/Python.framework/Versions/3.10/lib/python3.10/site-packages/requests/api.py", line 59, in request
    return session.request(method=method, url=url, **kwargs)
  File "/Library/Frameworks/Python.framework/Versions/3.10/lib/python3.10/site-packages/requests/sessions.py", line 587, in request
    resp = self.send(prep, **send_kwargs)
  File "/Library/Frameworks/Python.framework/Versions/3.10/lib/python3.10/site-packages/requests/sessions.py", line 701, in send
    r = adapter.send(request, **kwargs)
  File "/Library/Frameworks/Python.framework/Versions/3.10/lib/python3.10/site-packages/requests/adapters.py", line 553, in send
    raise ConnectTimeout(e, request=request)
requests.exceptions.ConnectTimeout: HTTPSConnectionPool(host='api.tracktry.com', port=443): Max retries exceeded with url: /v1/trackings/get (Caused by ConnectTimeoutError(<urllib3.connection.HTTPSConnection object at 0x1183f3f70>, 'Connection to api.tracktry.com timed out. (connect timeout=None)'))
Watching for file changes with StatReloader
Watching for file changes with StatReloader
Internal Server Error: /api/TrackingDetails
Traceback (most recent call last):
  File "/Library/Frameworks/Python.framework/Versions/3.10/lib/python3.10/site-packages/urllib3/connection.py", line 174, in _new_conn
    conn = connection.create_connection(
  File "/Library/Frameworks/Python.framework/Versions/3.10/lib/python3.10/site-packages/urllib3/util/connection.py", line 95, in create_connection
    raise err
  File "/Library/Frameworks/Python.framework/Versions/3.10/lib/python3.10/site-packages/urllib3/util/connection.py", line 85, in create_connection
    sock.connect(sa)
TimeoutError: [Errno 60] Operation timed out

During handling of the above exception, another exception occurred:

Traceback (most recent call last):
  File "/Library/Frameworks/Python.framework/Versions/3.10/lib/python3.10/site-packages/urllib3/connectionpool.py", line 703, in urlopen
    httplib_response = self._make_request(
  File "/Library/Frameworks/Python.framework/Versions/3.10/lib/python3.10/site-packages/urllib3/connectionpool.py", line 386, in _make_request
    self._validate_conn(conn)
  File "/Library/Frameworks/Python.framework/Versions/3.10/lib/python3.10/site-packages/urllib3/connectionpool.py", line 1042, in _validate_conn
    conn.connect()
  File "/Library/Frameworks/Python.framework/Versions/3.10/lib/python3.10/site-packages/urllib3/connection.py", line 358, in connect
    self.sock = conn = self._new_conn()
  File "/Library/Frameworks/Python.framework/Versions/3.10/lib/python3.10/site-packages/urllib3/connection.py", line 179, in _new_conn
    raise ConnectTimeoutError(
urllib3.exceptions.ConnectTimeoutError: (<urllib3.connection.HTTPSConnection object at 0x10e72c490>, 'Connection to api.tracktry.com timed out. (connect timeout=None)')

During handling of the above exception, another exception occurred:

Traceback (most recent call last):
  File "/Library/Frameworks/Python.framework/Versions/3.10/lib/python3.10/site-packages/requests/adapters.py", line 489, in send
    resp = conn.urlopen(
  File "/Library/Frameworks/Python.framework/Versions/3.10/lib/python3.10/site-packages/urllib3/connectionpool.py", line 787, in urlopen
    retries = retries.increment(
  File "/Library/Frameworks/Python.framework/Versions/3.10/lib/python3.10/site-packages/urllib3/util/retry.py", line 592, in increment
    raise MaxRetryError(_pool, url, error or ResponseError(cause))
urllib3.exceptions.MaxRetryError: HTTPSConnectionPool(host='api.tracktry.com', port=443): Max retries exceeded with url: /v1/trackings/get (Caused by ConnectTimeoutError(<urllib3.connection.HTTPSConnection object at 0x10e72c490>, 'Connection to api.tracktry.com timed out. (connect timeout=None)'))

During handling of the above exception, another exception occurred:

Traceback (most recent call last):
  File "/Library/Frameworks/Python.framework/Versions/3.10/lib/python3.10/site-packages/django/core/handlers/exception.py", line 55, in inner
    response = get_response(request)
  File "/Library/Frameworks/Python.framework/Versions/3.10/lib/python3.10/site-packages/django/core/handlers/base.py", line 197, in _get_response
    response = wrapped_callback(request, *callback_args, **callback_kwargs)
  File "/Library/Frameworks/Python.framework/Versions/3.10/lib/python3.10/site-packages/django/views/decorators/csrf.py", line 54, in wrapped_view
    return view_func(*args, **kwargs)
  File "/Library/Frameworks/Python.framework/Versions/3.10/lib/python3.10/site-packages/django/views/generic/base.py", line 103, in view
    return self.dispatch(request, *args, **kwargs)
  File "/Library/Frameworks/Python.framework/Versions/3.10/lib/python3.10/site-packages/rest_framework/views.py", line 509, in dispatch
    response = self.handle_exception(exc)
  File "/Library/Frameworks/Python.framework/Versions/3.10/lib/python3.10/site-packages/rest_framework/views.py", line 469, in handle_exception
    self.raise_uncaught_exception(exc)
  File "/Library/Frameworks/Python.framework/Versions/3.10/lib/python3.10/site-packages/rest_framework/views.py", line 480, in raise_uncaught_exception
    raise exc
  File "/Library/Frameworks/Python.framework/Versions/3.10/lib/python3.10/site-packages/rest_framework/views.py", line 506, in dispatch
    response = handler(request, *args, **kwargs)
  File "/Volumes/Volume/untitled folder 2/ct/app/msbctracker/views.py", line 755, in get
    te = track()
  File "/Volumes/Volume/untitled folder 2/ct/app/msbctracker/views.py", line 98, in track
    response = requests.get(api_url, headers=headers)
  File "/Library/Frameworks/Python.framework/Versions/3.10/lib/python3.10/site-packages/requests/api.py", line 73, in get
    return request("get", url, params=params, **kwargs)
  File "/Library/Frameworks/Python.framework/Versions/3.10/lib/python3.10/site-packages/requests/api.py", line 59, in request
    return session.request(method=method, url=url, **kwargs)
  File "/Library/Frameworks/Python.framework/Versions/3.10/lib/python3.10/site-packages/requests/sessions.py", line 587, in request
    resp = self.send(prep, **send_kwargs)
  File "/Library/Frameworks/Python.framework/Versions/3.10/lib/python3.10/site-packages/requests/sessions.py", line 701, in send
    r = adapter.send(request, **kwargs)
  File "/Library/Frameworks/Python.framework/Versions/3.10/lib/python3.10/site-packages/requests/adapters.py", line 553, in send
    raise ConnectTimeout(e, request=request)
requests.exceptions.ConnectTimeout: HTTPSConnectionPool(host='api.tracktry.com', port=443): Max retries exceeded with url: /v1/trackings/get (Caused by ConnectTimeoutError(<urllib3.connection.HTTPSConnection object at 0x10e72c490>, 'Connection to api.tracktry.com timed out. (connect timeout=None)'))
Watching for file changes with StatReloader
/Volumes/Volume/untitled folder 2/ct/app/msbctracker/views.py changed, reloading.
Watching for file changes with StatReloader
Watching for file changes with StatReloader
/Volumes/Volume/untitled folder 2/ct/app/msbctracker/views.py changed, reloading.
Watching for file changes with StatReloader
/Volumes/Volume/untitled folder 2/ct/app/msbctracker/views.py changed, reloading.
Watching for file changes with StatReloader
/Volumes/Volume/untitled folder 2/ct/app/msbctracker/views.py changed, reloading.
Watching for file changes with StatReloader
/Volumes/Volume/untitled folder 2/ct/app/msbctracker/views.py changed, reloading.
Watching for file changes with StatReloader
/Volumes/Volume/untitled folder 2/ct/app/msbctracker/views.py changed, reloading.
Watching for file changes with StatReloader
/Volumes/Volume/untitled folder 2/ct/app/msbctracker/views.py changed, reloading.
Watching for file changes with StatReloader
/Volumes/Volume/untitled folder 2/ct/app/msbctracker/views.py changed, reloading.
Watching for file changes with StatReloader
Watching for file changes with StatReloader
/Volumes/Volume/untitled folder 2/ct/app/msbctracker/views.py changed, reloading.
Watching for file changes with StatReloader
/Volumes/Volume/untitled folder 2/ct/app/msbctracker/views.py changed, reloading.
Watching for file changes with StatReloader
/Volumes/Volume/untitled folder 2/ct/app/msbctracker/views.py changed, reloading.
Watching for file changes with StatReloader
/Volumes/Volume/untitled folder 2/ct/app/msbctracker/views.py changed, reloading.
Watching for file changes with StatReloader
/Volumes/Volume/untitled folder 2/ct/app/msbctracker/views.py changed, reloading.
Watching for file changes with StatReloader
/Volumes/Volume/untitled folder 2/ct/app/msbctracker/views.py changed, reloading.
Watching for file changes with StatReloader
/Volumes/Volume/untitled folder 2/ct/app/msbctracker/views.py changed, reloading.
Watching for file changes with StatReloader
/Volumes/Volume/untitled folder 2/ct/app/msbctracker/views.py changed, reloading.
Watching for file changes with StatReloader
/Volumes/Volume/untitled folder 2/ct/app/msbctracker/views.py changed, reloading.
Watching for file changes with StatReloader
/Volumes/Volume/untitled folder 2/ct/app/msbctracker/views.py changed, reloading.
Watching for file changes with StatReloader
/Volumes/Volume/untitled folder 2/ct/app/msbctracker/views.py changed, reloading.
Watching for file changes with StatReloader
/Volumes/Volume/untitled folder 2/ct/app/msbctracker/views.py changed, reloading.
Watching for file changes with StatReloader
/Volumes/Volume/untitled folder 2/ct/app/msbctracker/views.py changed, reloading.
Watching for file changes with StatReloader
/Volumes/Volume/untitled folder 2/ct/app/msbctracker/views.py changed, reloading.
Watching for file changes with StatReloader
/Volumes/Volume/untitled folder 2/ct/app/msbctracker/views.py changed, reloading.
Watching for file changes with StatReloader
/Volumes/Volume/untitled folder 2/ct/app/msbctracker/views.py changed, reloading.
Watching for file changes with StatReloader
/Volumes/Volume/untitled folder 2/ct/app/msbctracker/views.py changed, reloading.
Watching for file changes with StatReloader
/Volumes/Volume/untitled folder 2/ct/app/msbctracker/views.py changed, reloading.
Watching for file changes with StatReloader
/Volumes/Volume/untitled folder 2/ct/app/msbctracker/views.py changed, reloading.
Watching for file changes with StatReloader
/Volumes/Volume/untitled folder 2/ct/app/msbctracker/views.py changed, reloading.
Watching for file changes with StatReloader
/Volumes/Volume/untitled folder 2/ct/app/msbctracker/views.py changed, reloading.
Watching for file changes with StatReloader
/Volumes/Volume/untitled folder 2/ct/app/msbctracker/views.py changed, reloading.
Watching for file changes with StatReloader
/Volumes/Volume/untitled folder 2/ct/app/msbctracker/views.py changed, reloading.
Watching for file changes with StatReloader
/Volumes/Volume/untitled folder 2/ct/app/msbctracker/views.py changed, reloading.
Watching for file changes with StatReloader
/Volumes/Volume/untitled folder 2/ct/app/msbctracker/views.py changed, reloading.
Watching for file changes with StatReloader
/Volumes/Volume/untitled folder 2/ct/app/msbctracker/views.py changed, reloading.
Watching for file changes with StatReloader
/Volumes/Volume/untitled folder 2/ct/app/msbctracker/views.py changed, reloading.
Watching for file changes with StatReloader
/Volumes/Volume/untitled folder 2/ct/app/msbctracker/views.py changed, reloading.
Watching for file changes with StatReloader
/Volumes/Volume/untitled folder 2/ct/app/msbctracker/views.py changed, reloading.
Watching for file changes with StatReloader
/Volumes/Volume/untitled folder 2/ct/app/msbctracker/views.py changed, reloading.
Watching for file changes with StatReloader
/Volumes/Volume/untitled folder 2/ct/app/msbctracker/views.py changed, reloading.
Watching for file changes with StatReloader
/Volumes/Volume/untitled folder 2/ct/app/msbctracker/views.py changed, reloading.
Watching for file changes with StatReloader
/Volumes/Volume/untitled folder 2/ct/app/msbctracker/views.py changed, reloading.
Watching for file changes with StatReloader
/Volumes/Volume/untitled folder 2/ct/app/msbctracker/views.py changed, reloading.
Watching for file changes with StatReloader
/Volumes/Volume/untitled folder 2/ct/app/msbctracker/views.py changed, reloading.
Watching for file changes with StatReloader
/Volumes/Volume/untitled folder 2/ct/app/msbctracker/views.py changed, reloading.
Watching for file changes with StatReloader
/Volumes/Volume/untitled folder 2/ct/app/msbctracker/views.py changed, reloading.
Watching for file changes with StatReloader
/Volumes/Volume/untitled folder 2/ct/app/msbctracker/views.py changed, reloading.
Watching for file changes with StatReloader
/Volumes/Volume/untitled folder 2/ct/app/msbctracker/views.py changed, reloading.
Watching for file changes with StatReloader
/Volumes/Volume/untitled folder 2/ct/app/msbctracker/views.py changed, reloading.
Watching for file changes with StatReloader
/Volumes/Volume/untitled folder 2/ct/app/msbctracker/views.py changed, reloading.
Watching for file changes with StatReloader
/Volumes/Volume/untitled folder 2/ct/app/msbctracker/views.py changed, reloading.
Watching for file changes with StatReloader
/Volumes/Volume/untitled folder 2/ct/app/msbctracker/views.py changed, reloading.
Watching for file changes with StatReloader
/Volumes/Volume/untitled folder 2/ct/app/msbctracker/views.py changed, reloading.
Watching for file changes with StatReloader
/Volumes/Volume/untitled folder 2/ct/app/msbctracker/views.py changed, reloading.
Watching for file changes with StatReloader
/Volumes/Volume/untitled folder 2/ct/app/msbctracker/views.py changed, reloading.
Watching for file changes with StatReloader
/Volumes/Volume/untitled folder 2/ct/app/msbctracker/views.py changed, reloading.
Watching for file changes with StatReloader
/Volumes/Volume/untitled folder 2/ct/app/msbctracker/views.py changed, reloading.
Watching for file changes with StatReloader
/Volumes/Volume/untitled folder 2/ct/app/msbctracker/views.py changed, reloading.
Watching for file changes with StatReloader
/Volumes/Volume/untitled folder 2/ct/app/msbctracker/views.py changed, reloading.
Watching for file changes with StatReloader
/Volumes/Volume/untitled folder 2/ct/app/msbctracker/views.py changed, reloading.
Watching for file changes with StatReloader
/Volumes/Volume/untitled folder 2/ct/app/msbctracker/views.py changed, reloading.
Watching for file changes with StatReloader
Watching for file changes with StatReloader
/Volumes/Volume/untitled folder 2/ct/app/msbctracker/views.py changed, reloading.
Watching for file changes with StatReloader
/Volumes/Volume/untitled folder 2/ct/app/msbctracker/views.py changed, reloading.
Watching for file changes with StatReloader
/Volumes/Volume/untitled folder 2/ct/app/msbctracker/views.py changed, reloading.
Watching for file changes with StatReloader
/Volumes/Volume/untitled folder 2/ct/app/msbctracker/views.py changed, reloading.
Watching for file changes with StatReloader
/Volumes/Volume/untitled folder 2/ct/app/msbctracker/views.py changed, reloading.
Watching for file changes with StatReloader
/Volumes/Volume/untitled folder 2/ct/app/msbctracker/views.py changed, reloading.
Watching for file changes with StatReloader
/Volumes/Volume/untitled folder 2/ct/app/msbctracker/views.py changed, reloading.
Watching for file changes with StatReloader
/Volumes/Volume/untitled folder 2/ct/app/msbctracker/views.py changed, reloading.
Watching for file changes with StatReloader
/Volumes/Volume/untitled folder 2/ct/app/msbctracker/views.py changed, reloading.
Watching for file changes with StatReloader
/Volumes/Volume/untitled folder 2/ct/app/msbctracker/views.py changed, reloading.
Watching for file changes with StatReloader
/Volumes/Volume/untitled folder 2/ct/app/msbctracker/views.py changed, reloading.
Watching for file changes with StatReloader
/Volumes/Volume/untitled folder 2/ct/app/msbctracker/views.py changed, reloading.
Watching for file changes with StatReloader
/Volumes/Volume/untitled folder 2/ct/app/msbctracker/views.py changed, reloading.
Watching for file changes with StatReloader
/Volumes/Volume/untitled folder 2/ct/app/msbctracker/views.py changed, reloading.
Watching for file changes with StatReloader
/Volumes/Volume/untitled folder 2/ct/app/msbctracker/views.py changed, reloading.
Watching for file changes with StatReloader
/Volumes/Volume/untitled folder 2/ct/app/msbctracker/views.py changed, reloading.
Watching for file changes with StatReloader
/Volumes/Volume/untitled folder 2/ct/app/msbctracker/views.py changed, reloading.
Watching for file changes with StatReloader
/Volumes/Volume/untitled folder 2/ct/app/msbctracker/views.py changed, reloading.
Watching for file changes with StatReloader
/Volumes/Volume/untitled folder 2/ct/app/msbctracker/views.py changed, reloading.
Watching for file changes with StatReloader
/Volumes/Volume/untitled folder 2/ct/app/msbctracker/views.py changed, reloading.
Watching for file changes with StatReloader
/Volumes/Volume/untitled folder 2/ct/app/msbctracker/views.py changed, reloading.
Watching for file changes with StatReloader
/Volumes/Volume/untitled folder 2/ct/app/msbctracker/views.py changed, reloading.
Watching for file changes with StatReloader
/Volumes/Volume/untitled folder 2/ct/app/msbctracker/views.py changed, reloading.
Watching for file changes with StatReloader
/Volumes/Volume/untitled folder 2/ct/app/msbctracker/views.py changed, reloading.
Watching for file changes with StatReloader
/Volumes/Volume/untitled folder 2/ct/app/msbctracker/views.py changed, reloading.
Watching for file changes with StatReloader
Watching for file changes with StatReloader
Watching for file changes with StatReloader
/Volumes/Volume/untitled folder 2/ct/app/msbctracker/views.py changed, reloading.
Watching for file changes with StatReloader
/Volumes/Volume/untitled folder 2/ct/app/msbctracker/views.py changed, reloading.
Watching for file changes with StatReloader
/Volumes/Volume/untitled folder 2/ct/app/msbctracker/views.py changed, reloading.
Watching for file changes with StatReloader
/Volumes/Volume/untitled folder 2/ct/app/msbctracker/views.py changed, reloading.
Watching for file changes with StatReloader
/Volumes/Volume/untitled folder 2/ct/app/msbctracker/views.py changed, reloading.
Watching for file changes with StatReloader
/Volumes/Volume/untitled folder 2/ct/app/msbctracker/views.py changed, reloading.
Watching for file changes with StatReloader
/Volumes/Volume/untitled folder 2/ct/app/msbctracker/views.py changed, reloading.
Watching for file changes with StatReloader
/Volumes/Volume/untitled folder 2/ct/app/msbctracker/views.py changed, reloading.
Watching for file changes with StatReloader
/Volumes/Volume/untitled folder 2/ct/app/msbctracker/views.py changed, reloading.
Watching for file changes with StatReloader
/Volumes/Volume/untitled folder 2/ct/app/msbctracker/views.py changed, reloading.
Watching for file changes with StatReloader
Watching for file changes with StatReloader
