/Volumes/Volume/untitled folder 2/ct/app/tracker/settings.py changed, reloading.
Watching for file changes with StatReloader
Watching for file changes with StatReloader
Watching for file changes with StatReloader
/Volumes/Volume/untitled folder 2/ct/app/msbctracker/views.py changed, reloading.
Watching for file changes with StatReloader
Internal Server Error: /api/list
Traceback (most recent call last):
  File "/Library/Frameworks/Python.framework/Versions/3.10/lib/python3.10/site-packages/django/core/handlers/exception.py", line 47, in inner
    response = get_response(request)
  File "/Library/Frameworks/Python.framework/Versions/3.10/lib/python3.10/site-packages/django/core/handlers/base.py", line 181, in _get_response
    response = wrapped_callback(request, *callback_args, **callback_kwargs)
  File "/Library/Frameworks/Python.framework/Versions/3.10/lib/python3.10/site-packages/django/views/decorators/csrf.py", line 54, in wrapped_view
    return view_func(*args, **kwargs)
  File "/Library/Frameworks/Python.framework/Versions/3.10/lib/python3.10/site-packages/django/views/generic/base.py", line 70, in view
    return self.dispatch(request, *args, **kwargs)
  File "/Library/Frameworks/Python.framework/Versions/3.10/lib/python3.10/site-packages/rest_framework/views.py", line 509, in dispatch
    response = self.handle_exception(exc)
  File "/Library/Frameworks/Python.framework/Versions/3.10/lib/python3.10/site-packages/rest_framework/views.py", line 469, in handle_exception
    self.raise_uncaught_exception(exc)
  File "/Library/Frameworks/Python.framework/Versions/3.10/lib/python3.10/site-packages/rest_framework/views.py", line 480, in raise_uncaught_exception
    raise exc
  File "/Library/Frameworks/Python.framework/Versions/3.10/lib/python3.10/site-packages/rest_framework/views.py", line 506, in dispatch
    response = handler(request, *args, **kwargs)
  File "/Volumes/Volume/untitled folder 2/ct/app/msbctracker/views.py", line 197, in get
    user_list = Tracker.objects.all().values().order_by('-Date')[:4]
  File "/Library/Frameworks/Python.framework/Versions/3.10/lib/python3.10/site-packages/django/db/models/query.py", line 1134, in order_by
    obj.query.add_ordering(*field_names)
  File "/Library/Frameworks/Python.framework/Versions/3.10/lib/python3.10/site-packages/django/db/models/sql/query.py", line 1919, in add_ordering
    self.names_to_path(item.split(LOOKUP_SEP), self.model._meta)
  File "/Library/Frameworks/Python.framework/Versions/3.10/lib/python3.10/site-packages/django/db/models/sql/query.py", line 1481, in names_to_path
    raise FieldError("Cannot resolve keyword '%s' into field. "
django.core.exceptions.FieldError: Cannot resolve keyword 'Date' into field. Choices are: api_call_time, arrival, booked, delivered, id, msbc_patch_api_call_time, numeric_status, outbound, status, tracking_info, tracking_number, updated_time
Internal Server Error: /api/list
Traceback (most recent call last):
  File "/Library/Frameworks/Python.framework/Versions/3.10/lib/python3.10/site-packages/django/core/handlers/exception.py", line 47, in inner
    response = get_response(request)
  File "/Library/Frameworks/Python.framework/Versions/3.10/lib/python3.10/site-packages/django/core/handlers/base.py", line 181, in _get_response
    response = wrapped_callback(request, *callback_args, **callback_kwargs)
  File "/Library/Frameworks/Python.framework/Versions/3.10/lib/python3.10/site-packages/django/views/decorators/csrf.py", line 54, in wrapped_view
    return view_func(*args, **kwargs)
  File "/Library/Frameworks/Python.framework/Versions/3.10/lib/python3.10/site-packages/django/views/generic/base.py", line 70, in view
    return self.dispatch(request, *args, **kwargs)
  File "/Library/Frameworks/Python.framework/Versions/3.10/lib/python3.10/site-packages/rest_framework/views.py", line 509, in dispatch
    response = self.handle_exception(exc)
  File "/Library/Frameworks/Python.framework/Versions/3.10/lib/python3.10/site-packages/rest_framework/views.py", line 469, in handle_exception
    self.raise_uncaught_exception(exc)
  File "/Library/Frameworks/Python.framework/Versions/3.10/lib/python3.10/site-packages/rest_framework/views.py", line 480, in raise_uncaught_exception
    raise exc
  File "/Library/Frameworks/Python.framework/Versions/3.10/lib/python3.10/site-packages/rest_framework/views.py", line 506, in dispatch
    response = handler(request, *args, **kwargs)
  File "/Volumes/Volume/untitled folder 2/ct/app/msbctracker/views.py", line 197, in get
    user_list = Tracker.objects.all().values().order_by('-Date')[:4]
  File "/Library/Frameworks/Python.framework/Versions/3.10/lib/python3.10/site-packages/django/db/models/query.py", line 1134, in order_by
    obj.query.add_ordering(*field_names)
  File "/Library/Frameworks/Python.framework/Versions/3.10/lib/python3.10/site-packages/django/db/models/sql/query.py", line 1919, in add_ordering
    self.names_to_path(item.split(LOOKUP_SEP), self.model._meta)
  File "/Library/Frameworks/Python.framework/Versions/3.10/lib/python3.10/site-packages/django/db/models/sql/query.py", line 1481, in names_to_path
    raise FieldError("Cannot resolve keyword '%s' into field. "
django.core.exceptions.FieldError: Cannot resolve keyword 'Date' into field. Choices are: api_call_time, arrival, booked, delivered, id, msbc_patch_api_call_time, numeric_status, outbound, status, tracking_info, tracking_number, updated_time
Internal Server Error: /api/list
Traceback (most recent call last):
  File "/Library/Frameworks/Python.framework/Versions/3.10/lib/python3.10/site-packages/django/core/handlers/exception.py", line 47, in inner
    response = get_response(request)
  File "/Library/Frameworks/Python.framework/Versions/3.10/lib/python3.10/site-packages/django/core/handlers/base.py", line 181, in _get_response
    response = wrapped_callback(request, *callback_args, **callback_kwargs)
  File "/Library/Frameworks/Python.framework/Versions/3.10/lib/python3.10/site-packages/django/views/decorators/csrf.py", line 54, in wrapped_view
    return view_func(*args, **kwargs)
  File "/Library/Frameworks/Python.framework/Versions/3.10/lib/python3.10/site-packages/django/views/generic/base.py", line 70, in view
    return self.dispatch(request, *args, **kwargs)
  File "/Library/Frameworks/Python.framework/Versions/3.10/lib/python3.10/site-packages/rest_framework/views.py", line 509, in dispatch
    response = self.handle_exception(exc)
  File "/Library/Frameworks/Python.framework/Versions/3.10/lib/python3.10/site-packages/rest_framework/views.py", line 469, in handle_exception
    self.raise_uncaught_exception(exc)
  File "/Library/Frameworks/Python.framework/Versions/3.10/lib/python3.10/site-packages/rest_framework/views.py", line 480, in raise_uncaught_exception
    raise exc
  File "/Library/Frameworks/Python.framework/Versions/3.10/lib/python3.10/site-packages/rest_framework/views.py", line 506, in dispatch
    response = handler(request, *args, **kwargs)
  File "/Volumes/Volume/untitled folder 2/ct/app/msbctracker/views.py", line 197, in get
    user_list = Tracker.objects.all().values().order_by('-Date')[:4]
  File "/Library/Frameworks/Python.framework/Versions/3.10/lib/python3.10/site-packages/django/db/models/query.py", line 1134, in order_by
    obj.query.add_ordering(*field_names)
  File "/Library/Frameworks/Python.framework/Versions/3.10/lib/python3.10/site-packages/django/db/models/sql/query.py", line 1919, in add_ordering
    self.names_to_path(item.split(LOOKUP_SEP), self.model._meta)
  File "/Library/Frameworks/Python.framework/Versions/3.10/lib/python3.10/site-packages/django/db/models/sql/query.py", line 1481, in names_to_path
    raise FieldError("Cannot resolve keyword '%s' into field. "
django.core.exceptions.FieldError: Cannot resolve keyword 'Date' into field. Choices are: api_call_time, arrival, booked, delivered, id, msbc_patch_api_call_time, numeric_status, outbound, status, tracking_info, tracking_number, updated_time
/Volumes/Volume/untitled folder 2/ct/app/msbctracker/urls.py changed, reloading.
Watching for file changes with StatReloader
Internal Server Error: /api/list
Traceback (most recent call last):
  File "/Library/Frameworks/Python.framework/Versions/3.10/lib/python3.10/site-packages/django/core/handlers/exception.py", line 47, in inner
    response = get_response(request)
  File "/Library/Frameworks/Python.framework/Versions/3.10/lib/python3.10/site-packages/django/core/handlers/base.py", line 181, in _get_response
    response = wrapped_callback(request, *callback_args, **callback_kwargs)
  File "/Library/Frameworks/Python.framework/Versions/3.10/lib/python3.10/site-packages/django/views/decorators/csrf.py", line 54, in wrapped_view
    return view_func(*args, **kwargs)
  File "/Library/Frameworks/Python.framework/Versions/3.10/lib/python3.10/site-packages/django/views/generic/base.py", line 70, in view
    return self.dispatch(request, *args, **kwargs)
  File "/Library/Frameworks/Python.framework/Versions/3.10/lib/python3.10/site-packages/rest_framework/views.py", line 509, in dispatch
    response = self.handle_exception(exc)
  File "/Library/Frameworks/Python.framework/Versions/3.10/lib/python3.10/site-packages/rest_framework/views.py", line 469, in handle_exception
    self.raise_uncaught_exception(exc)
  File "/Library/Frameworks/Python.framework/Versions/3.10/lib/python3.10/site-packages/rest_framework/views.py", line 480, in raise_uncaught_exception
    raise exc
  File "/Library/Frameworks/Python.framework/Versions/3.10/lib/python3.10/site-packages/rest_framework/views.py", line 506, in dispatch
    response = handler(request, *args, **kwargs)
  File "/Volumes/Volume/untitled folder 2/ct/app/msbctracker/views.py", line 197, in get
    user_list = Tracker.objects.all().values().order_by('-Date')[:4]
  File "/Library/Frameworks/Python.framework/Versions/3.10/lib/python3.10/site-packages/django/db/models/query.py", line 1134, in order_by
    obj.query.add_ordering(*field_names)
  File "/Library/Frameworks/Python.framework/Versions/3.10/lib/python3.10/site-packages/django/db/models/sql/query.py", line 1919, in add_ordering
    self.names_to_path(item.split(LOOKUP_SEP), self.model._meta)
  File "/Library/Frameworks/Python.framework/Versions/3.10/lib/python3.10/site-packages/django/db/models/sql/query.py", line 1481, in names_to_path
    raise FieldError("Cannot resolve keyword '%s' into field. "
django.core.exceptions.FieldError: Cannot resolve keyword 'Date' into field. Choices are: api_call_time, arrival, booked, delivered, id, msbc_patch_api_call_time, numeric_status, outbound, status, tracking_info, tracking_number, updated_time
/Volumes/Volume/untitled folder 2/ct/app/msbctracker/views.py changed, reloading.
Watching for file changes with StatReloader
/Volumes/Volume/untitled folder 2/ct/app/msbctracker/views.py changed, reloading.
Watching for file changes with StatReloader
Internal Server Error: /api/list
Traceback (most recent call last):
  File "/Library/Frameworks/Python.framework/Versions/3.10/lib/python3.10/site-packages/django/core/handlers/exception.py", line 47, in inner
    response = get_response(request)
  File "/Library/Frameworks/Python.framework/Versions/3.10/lib/python3.10/site-packages/django/core/handlers/base.py", line 181, in _get_response
    response = wrapped_callback(request, *callback_args, **callback_kwargs)
  File "/Library/Frameworks/Python.framework/Versions/3.10/lib/python3.10/site-packages/django/views/decorators/csrf.py", line 54, in wrapped_view
    return view_func(*args, **kwargs)
  File "/Library/Frameworks/Python.framework/Versions/3.10/lib/python3.10/site-packages/django/views/generic/base.py", line 70, in view
    return self.dispatch(request, *args, **kwargs)
  File "/Library/Frameworks/Python.framework/Versions/3.10/lib/python3.10/site-packages/rest_framework/views.py", line 509, in dispatch
    response = self.handle_exception(exc)
  File "/Library/Frameworks/Python.framework/Versions/3.10/lib/python3.10/site-packages/rest_framework/views.py", line 469, in handle_exception
    self.raise_uncaught_exception(exc)
  File "/Library/Frameworks/Python.framework/Versions/3.10/lib/python3.10/site-packages/rest_framework/views.py", line 480, in raise_uncaught_exception
    raise exc
  File "/Library/Frameworks/Python.framework/Versions/3.10/lib/python3.10/site-packages/rest_framework/views.py", line 506, in dispatch
    response = handler(request, *args, **kwargs)
  File "/Volumes/Volume/untitled folder 2/ct/app/msbctracker/views.py", line 197, in get
    user_list = Tracker.objects.all().order_by('-Date')[:4].values()
  File "/Library/Frameworks/Python.framework/Versions/3.10/lib/python3.10/site-packages/django/db/models/query.py", line 1134, in order_by
    obj.query.add_ordering(*field_names)
  File "/Library/Frameworks/Python.framework/Versions/3.10/lib/python3.10/site-packages/django/db/models/sql/query.py", line 1919, in add_ordering
    self.names_to_path(item.split(LOOKUP_SEP), self.model._meta)
  File "/Library/Frameworks/Python.framework/Versions/3.10/lib/python3.10/site-packages/django/db/models/sql/query.py", line 1481, in names_to_path
    raise FieldError("Cannot resolve keyword '%s' into field. "
django.core.exceptions.FieldError: Cannot resolve keyword 'Date' into field. Choices are: api_call_time, arrival, booked, delivered, id, msbc_patch_api_call_time, numeric_status, outbound, status, tracking_info, tracking_number, updated_time
/Volumes/Volume/untitled folder 2/ct/app/msbctracker/views.py changed, reloading.
Watching for file changes with StatReloader
/Volumes/Volume/untitled folder 2/ct/app/msbctracker/views.py changed, reloading.
Watching for file changes with StatReloader
Internal Server Error: /api/list
Traceback (most recent call last):
  File "/Library/Frameworks/Python.framework/Versions/3.10/lib/python3.10/site-packages/django/core/handlers/exception.py", line 47, in inner
    response = get_response(request)
  File "/Library/Frameworks/Python.framework/Versions/3.10/lib/python3.10/site-packages/django/core/handlers/base.py", line 204, in _get_response
    response = response.render()
  File "/Library/Frameworks/Python.framework/Versions/3.10/lib/python3.10/site-packages/django/template/response.py", line 105, in render
    self.content = self.rendered_content
  File "/Library/Frameworks/Python.framework/Versions/3.10/lib/python3.10/site-packages/rest_framework/response.py", line 70, in rendered_content
    ret = renderer.render(self.data, accepted_media_type, context)
  File "/Library/Frameworks/Python.framework/Versions/3.10/lib/python3.10/site-packages/rest_framework/renderers.py", line 100, in render
    ret = json.dumps(
  File "/Library/Frameworks/Python.framework/Versions/3.10/lib/python3.10/site-packages/rest_framework/utils/json.py", line 25, in dumps
    return json.dumps(*args, **kwargs)
  File "/Library/Frameworks/Python.framework/Versions/3.10/lib/python3.10/json/__init__.py", line 238, in dumps
    **kw).encode(obj)
  File "/Library/Frameworks/Python.framework/Versions/3.10/lib/python3.10/json/encoder.py", line 199, in encode
    chunks = self.iterencode(o, _one_shot=True)
  File "/Library/Frameworks/Python.framework/Versions/3.10/lib/python3.10/json/encoder.py", line 257, in iterencode
    return _iterencode(o, 0)
  File "/Library/Frameworks/Python.framework/Versions/3.10/lib/python3.10/site-packages/rest_framework/utils/encoders.py", line 67, in default
    return super().default(obj)
  File "/Library/Frameworks/Python.framework/Versions/3.10/lib/python3.10/json/encoder.py", line 179, in default
    raise TypeError(f'Object of type {o.__class__.__name__} '
TypeError: Object of type Tracker is not JSON serializable
/Volumes/Volume/untitled folder 2/ct/app/msbctracker/views.py changed, reloading.
Watching for file changes with StatReloader
Watching for file changes with StatReloader
/Volumes/Volume/untitled folder 2/ct/app/msbctracker/views.py changed, reloading.
Watching for file changes with StatReloader
Internal Server Error: /api/list
Traceback (most recent call last):
  File "/Library/Frameworks/Python.framework/Versions/3.10/lib/python3.10/site-packages/django/core/handlers/exception.py", line 47, in inner
    response = get_response(request)
  File "/Library/Frameworks/Python.framework/Versions/3.10/lib/python3.10/site-packages/django/core/handlers/base.py", line 181, in _get_response
    response = wrapped_callback(request, *callback_args, **callback_kwargs)
  File "/Library/Frameworks/Python.framework/Versions/3.10/lib/python3.10/site-packages/django/views/decorators/csrf.py", line 54, in wrapped_view
    return view_func(*args, **kwargs)
  File "/Library/Frameworks/Python.framework/Versions/3.10/lib/python3.10/site-packages/django/views/generic/base.py", line 70, in view
    return self.dispatch(request, *args, **kwargs)
  File "/Library/Frameworks/Python.framework/Versions/3.10/lib/python3.10/site-packages/rest_framework/views.py", line 509, in dispatch
    response = self.handle_exception(exc)
  File "/Library/Frameworks/Python.framework/Versions/3.10/lib/python3.10/site-packages/rest_framework/views.py", line 469, in handle_exception
    self.raise_uncaught_exception(exc)
  File "/Library/Frameworks/Python.framework/Versions/3.10/lib/python3.10/site-packages/rest_framework/views.py", line 480, in raise_uncaught_exception
    raise exc
  File "/Library/Frameworks/Python.framework/Versions/3.10/lib/python3.10/site-packages/rest_framework/views.py", line 506, in dispatch
    response = handler(request, *args, **kwargs)
  File "/Volumes/Volume/untitled folder 2/ct/app/msbctracker/views.py", line 199, in get
    if ind_time > timedelta(hours=3).strftime('%Y-%m-%d %H:%M:%S.%f'):
AttributeError: 'datetime.timedelta' object has no attribute 'strftime'
/Volumes/Volume/untitled folder 2/ct/app/msbctracker/views.py changed, reloading.
Watching for file changes with StatReloader
Internal Server Error: /api/list
Traceback (most recent call last):
  File "/Library/Frameworks/Python.framework/Versions/3.10/lib/python3.10/site-packages/django/core/handlers/exception.py", line 47, in inner
    response = get_response(request)
  File "/Library/Frameworks/Python.framework/Versions/3.10/lib/python3.10/site-packages/django/core/handlers/base.py", line 181, in _get_response
    response = wrapped_callback(request, *callback_args, **callback_kwargs)
  File "/Library/Frameworks/Python.framework/Versions/3.10/lib/python3.10/site-packages/django/views/decorators/csrf.py", line 54, in wrapped_view
    return view_func(*args, **kwargs)
  File "/Library/Frameworks/Python.framework/Versions/3.10/lib/python3.10/site-packages/django/views/generic/base.py", line 70, in view
    return self.dispatch(request, *args, **kwargs)
  File "/Library/Frameworks/Python.framework/Versions/3.10/lib/python3.10/site-packages/rest_framework/views.py", line 509, in dispatch
    response = self.handle_exception(exc)
  File "/Library/Frameworks/Python.framework/Versions/3.10/lib/python3.10/site-packages/rest_framework/views.py", line 469, in handle_exception
    self.raise_uncaught_exception(exc)
  File "/Library/Frameworks/Python.framework/Versions/3.10/lib/python3.10/site-packages/rest_framework/views.py", line 480, in raise_uncaught_exception
    raise exc
  File "/Library/Frameworks/Python.framework/Versions/3.10/lib/python3.10/site-packages/rest_framework/views.py", line 506, in dispatch
    response = handler(request, *args, **kwargs)
  File "/Volumes/Volume/untitled folder 2/ct/app/msbctracker/views.py", line 199, in get
    if ind_time > timedelta(hours=3):
TypeError: '>' not supported between instances of 'str' and 'datetime.timedelta'
/Volumes/Volume/untitled folder 2/ct/app/msbctracker/views.py changed, reloading.
Watching for file changes with StatReloader
Internal Server Error: /api/list
Traceback (most recent call last):
  File "/Library/Frameworks/Python.framework/Versions/3.10/lib/python3.10/site-packages/django/core/handlers/exception.py", line 47, in inner
    response = get_response(request)
  File "/Library/Frameworks/Python.framework/Versions/3.10/lib/python3.10/site-packages/django/core/handlers/base.py", line 181, in _get_response
    response = wrapped_callback(request, *callback_args, **callback_kwargs)
  File "/Library/Frameworks/Python.framework/Versions/3.10/lib/python3.10/site-packages/django/views/decorators/csrf.py", line 54, in wrapped_view
    return view_func(*args, **kwargs)
  File "/Library/Frameworks/Python.framework/Versions/3.10/lib/python3.10/site-packages/django/views/generic/base.py", line 70, in view
    return self.dispatch(request, *args, **kwargs)
  File "/Library/Frameworks/Python.framework/Versions/3.10/lib/python3.10/site-packages/rest_framework/views.py", line 509, in dispatch
    response = self.handle_exception(exc)
  File "/Library/Frameworks/Python.framework/Versions/3.10/lib/python3.10/site-packages/rest_framework/views.py", line 469, in handle_exception
    self.raise_uncaught_exception(exc)
  File "/Library/Frameworks/Python.framework/Versions/3.10/lib/python3.10/site-packages/rest_framework/views.py", line 480, in raise_uncaught_exception
    raise exc
  File "/Library/Frameworks/Python.framework/Versions/3.10/lib/python3.10/site-packages/rest_framework/views.py", line 506, in dispatch
    response = handler(request, *args, **kwargs)
  File "/Volumes/Volume/untitled folder 2/ct/app/msbctracker/views.py", line 199, in get
    if int(ind_time) > timedelta(hours=3):
ValueError: invalid literal for int() with base 10: '2023-02-16 17:58:38.353617'
/Volumes/Volume/untitled folder 2/ct/app/msbctracker/views.py changed, reloading.
Watching for file changes with StatReloader
Internal Server Error: /api/list
Traceback (most recent call last):
  File "/Library/Frameworks/Python.framework/Versions/3.10/lib/python3.10/site-packages/django/core/handlers/exception.py", line 47, in inner
    response = get_response(request)
  File "/Library/Frameworks/Python.framework/Versions/3.10/lib/python3.10/site-packages/django/core/handlers/base.py", line 181, in _get_response
    response = wrapped_callback(request, *callback_args, **callback_kwargs)
  File "/Library/Frameworks/Python.framework/Versions/3.10/lib/python3.10/site-packages/django/views/decorators/csrf.py", line 54, in wrapped_view
    return view_func(*args, **kwargs)
  File "/Library/Frameworks/Python.framework/Versions/3.10/lib/python3.10/site-packages/django/views/generic/base.py", line 70, in view
    return self.dispatch(request, *args, **kwargs)
  File "/Library/Frameworks/Python.framework/Versions/3.10/lib/python3.10/site-packages/rest_framework/views.py", line 509, in dispatch
    response = self.handle_exception(exc)
  File "/Library/Frameworks/Python.framework/Versions/3.10/lib/python3.10/site-packages/rest_framework/views.py", line 469, in handle_exception
    self.raise_uncaught_exception(exc)
  File "/Library/Frameworks/Python.framework/Versions/3.10/lib/python3.10/site-packages/rest_framework/views.py", line 480, in raise_uncaught_exception
    raise exc
  File "/Library/Frameworks/Python.framework/Versions/3.10/lib/python3.10/site-packages/rest_framework/views.py", line 506, in dispatch
    response = handler(request, *args, **kwargs)
  File "/Volumes/Volume/untitled folder 2/ct/app/msbctracker/views.py", line 199, in get
    if int(ind_time) > timedelta(hours=3):
ValueError: invalid literal for int() with base 10: '17:59:11.996259'
/Volumes/Volume/untitled folder 2/ct/app/msbctracker/views.py changed, reloading.
Watching for file changes with StatReloader
Internal Server Error: /api/list
Traceback (most recent call last):
  File "/Library/Frameworks/Python.framework/Versions/3.10/lib/python3.10/site-packages/django/core/handlers/exception.py", line 47, in inner
    response = get_response(request)
  File "/Library/Frameworks/Python.framework/Versions/3.10/lib/python3.10/site-packages/django/core/handlers/base.py", line 181, in _get_response
    response = wrapped_callback(request, *callback_args, **callback_kwargs)
  File "/Library/Frameworks/Python.framework/Versions/3.10/lib/python3.10/site-packages/django/views/decorators/csrf.py", line 54, in wrapped_view
    return view_func(*args, **kwargs)
  File "/Library/Frameworks/Python.framework/Versions/3.10/lib/python3.10/site-packages/django/views/generic/base.py", line 70, in view
    return self.dispatch(request, *args, **kwargs)
  File "/Library/Frameworks/Python.framework/Versions/3.10/lib/python3.10/site-packages/rest_framework/views.py", line 509, in dispatch
    response = self.handle_exception(exc)
  File "/Library/Frameworks/Python.framework/Versions/3.10/lib/python3.10/site-packages/rest_framework/views.py", line 469, in handle_exception
    self.raise_uncaught_exception(exc)
  File "/Library/Frameworks/Python.framework/Versions/3.10/lib/python3.10/site-packages/rest_framework/views.py", line 480, in raise_uncaught_exception
    raise exc
  File "/Library/Frameworks/Python.framework/Versions/3.10/lib/python3.10/site-packages/rest_framework/views.py", line 506, in dispatch
    response = handler(request, *args, **kwargs)
  File "/Volumes/Volume/untitled folder 2/ct/app/msbctracker/views.py", line 199, in get
    if int(ind_time) > timedelta(hours=3):
ValueError: invalid literal for int() with base 10: '17:59:26'
/Volumes/Volume/untitled folder 2/ct/app/msbctracker/views.py changed, reloading.
Watching for file changes with StatReloader
/Volumes/Volume/untitled folder 2/ct/app/msbctracker/views.py changed, reloading.
Watching for file changes with StatReloader
/Volumes/Volume/untitled folder 2/ct/app/msbctracker/views.py changed, reloading.
Watching for file changes with StatReloader
Internal Server Error: /api/list
Traceback (most recent call last):
  File "/Library/Frameworks/Python.framework/Versions/3.10/lib/python3.10/site-packages/django/core/handlers/exception.py", line 47, in inner
    response = get_response(request)
  File "/Library/Frameworks/Python.framework/Versions/3.10/lib/python3.10/site-packages/django/core/handlers/base.py", line 181, in _get_response
    response = wrapped_callback(request, *callback_args, **callback_kwargs)
  File "/Library/Frameworks/Python.framework/Versions/3.10/lib/python3.10/site-packages/django/views/decorators/csrf.py", line 54, in wrapped_view
    return view_func(*args, **kwargs)
  File "/Library/Frameworks/Python.framework/Versions/3.10/lib/python3.10/site-packages/django/views/generic/base.py", line 70, in view
    return self.dispatch(request, *args, **kwargs)
  File "/Library/Frameworks/Python.framework/Versions/3.10/lib/python3.10/site-packages/rest_framework/views.py", line 509, in dispatch
    response = self.handle_exception(exc)
  File "/Library/Frameworks/Python.framework/Versions/3.10/lib/python3.10/site-packages/rest_framework/views.py", line 469, in handle_exception
    self.raise_uncaught_exception(exc)
  File "/Library/Frameworks/Python.framework/Versions/3.10/lib/python3.10/site-packages/rest_framework/views.py", line 480, in raise_uncaught_exception
    raise exc
  File "/Library/Frameworks/Python.framework/Versions/3.10/lib/python3.10/site-packages/rest_framework/views.py", line 506, in dispatch
    response = handler(request, *args, **kwargs)
  File "/Volumes/Volume/untitled folder 2/ct/app/msbctracker/views.py", line 199, in get
    if ind_time < ind_time + timedelta(hours=3):
TypeError: can only concatenate str (not "datetime.timedelta") to str
/Volumes/Volume/untitled folder 2/ct/app/msbctracker/views.py changed, reloading.
Watching for file changes with StatReloader
/Volumes/Volume/untitled folder 2/ct/app/msbctracker/views.py changed, reloading.
Watching for file changes with StatReloader
/Volumes/Volume/untitled folder 2/ct/app/msbctracker/views.py changed, reloading.
Watching for file changes with StatReloader
/Volumes/Volume/untitled folder 2/ct/app/msbctracker/views.py changed, reloading.
Watching for file changes with StatReloader
/Volumes/Volume/untitled folder 2/ct/app/msbctracker/views.py changed, reloading.
Watching for file changes with StatReloader
Internal Server Error: /api/list
Traceback (most recent call last):
  File "/Library/Frameworks/Python.framework/Versions/3.10/lib/python3.10/site-packages/django/core/handlers/exception.py", line 47, in inner
    response = get_response(request)
  File "/Library/Frameworks/Python.framework/Versions/3.10/lib/python3.10/site-packages/django/core/handlers/base.py", line 181, in _get_response
    response = wrapped_callback(request, *callback_args, **callback_kwargs)
  File "/Library/Frameworks/Python.framework/Versions/3.10/lib/python3.10/site-packages/django/views/decorators/csrf.py", line 54, in wrapped_view
    return view_func(*args, **kwargs)
  File "/Library/Frameworks/Python.framework/Versions/3.10/lib/python3.10/site-packages/django/views/generic/base.py", line 70, in view
    return self.dispatch(request, *args, **kwargs)
  File "/Library/Frameworks/Python.framework/Versions/3.10/lib/python3.10/site-packages/rest_framework/views.py", line 509, in dispatch
    response = self.handle_exception(exc)
  File "/Library/Frameworks/Python.framework/Versions/3.10/lib/python3.10/site-packages/rest_framework/views.py", line 469, in handle_exception
    self.raise_uncaught_exception(exc)
  File "/Library/Frameworks/Python.framework/Versions/3.10/lib/python3.10/site-packages/rest_framework/views.py", line 480, in raise_uncaught_exception
    raise exc
  File "/Library/Frameworks/Python.framework/Versions/3.10/lib/python3.10/site-packages/rest_framework/views.py", line 506, in dispatch
    response = handler(request, *args, **kwargs)
  File "/Volumes/Volume/untitled folder 2/ct/app/msbctracker/views.py", line 201, in get
    thr =  ind_time + timedelta(hours=3)
TypeError: can only concatenate str (not "datetime.timedelta") to str
Watching for file changes with StatReloader
Not Found: /api/details
/Volumes/Volume/untitled folder 2/ct/app/msbctracker/urls.py changed, reloading.
Watching for file changes with StatReloader
/Volumes/Volume/untitled folder 2/ct/app/msbctracker/views.py changed, reloading.
Watching for file changes with StatReloader
/Volumes/Volume/untitled folder 2/ct/app/msbctracker/views.py changed, reloading.
Watching for file changes with StatReloader
/Volumes/Volume/untitled folder 2/ct/app/msbctracker/urls.py changed, reloading.
Watching for file changes with StatReloader
/Volumes/Volume/untitled folder 2/ct/app/msbctracker/views.py changed, reloading.
Watching for file changes with StatReloader
/Volumes/Volume/untitled folder 2/ct/app/msbctracker/urls.py changed, reloading.
Watching for file changes with StatReloader
Method Not Allowed: /api/details
/Volumes/Volume/untitled folder 2/ct/app/msbctracker/views.py changed, reloading.
Watching for file changes with StatReloader
/Volumes/Volume/untitled folder 2/ct/app/msbctracker/views.py changed, reloading.
Watching for file changes with StatReloader
Internal Server Error: /api/details
Traceback (most recent call last):
  File "/Library/Frameworks/Python.framework/Versions/3.10/lib/python3.10/site-packages/django/core/handlers/exception.py", line 47, in inner
    response = get_response(request)
  File "/Library/Frameworks/Python.framework/Versions/3.10/lib/python3.10/site-packages/django/core/handlers/base.py", line 204, in _get_response
    response = response.render()
  File "/Library/Frameworks/Python.framework/Versions/3.10/lib/python3.10/site-packages/django/template/response.py", line 105, in render
    self.content = self.rendered_content
  File "/Library/Frameworks/Python.framework/Versions/3.10/lib/python3.10/site-packages/rest_framework/response.py", line 70, in rendered_content
    ret = renderer.render(self.data, accepted_media_type, context)
  File "/Library/Frameworks/Python.framework/Versions/3.10/lib/python3.10/site-packages/rest_framework/renderers.py", line 723, in render
    template = loader.get_template(self.template)
  File "/Library/Frameworks/Python.framework/Versions/3.10/lib/python3.10/site-packages/django/template/loader.py", line 19, in get_template
    raise TemplateDoesNotExist(template_name, chain=chain)
django.template.exceptions.TemplateDoesNotExist: rest_framework/api.html
Not Found: /favicon.ico
Not Found: /apple-touch-icon-precomposed.png
Not Found: /apple-touch-icon.png
/Volumes/Volume/untitled folder 2/ct/app/msbctracker/views.py changed, reloading.
Watching for file changes with StatReloader
/Volumes/Volume/untitled folder 2/ct/app/msbctracker/views.py changed, reloading.
Watching for file changes with StatReloader
/Volumes/Volume/untitled folder 2/ct/app/msbctracker/views.py changed, reloading.
Watching for file changes with StatReloader
/Volumes/Volume/untitled folder 2/ct/app/msbctracker/views.py changed, reloading.
Watching for file changes with StatReloader
/Volumes/Volume/untitled folder 2/ct/app/msbctracker/views.py changed, reloading.
Watching for file changes with StatReloader
/Volumes/Volume/untitled folder 2/ct/app/msbctracker/views.py changed, reloading.
Watching for file changes with StatReloader
/Volumes/Volume/untitled folder 2/ct/app/msbctracker/views.py changed, reloading.
Watching for file changes with StatReloader
/Volumes/Volume/untitled folder 2/ct/app/msbctracker/views.py changed, reloading.
Watching for file changes with StatReloader
Watching for file changes with StatReloader
/Volumes/Volume/untitled folder 2/ct/app/msbctracker/views.py changed, reloading.
Watching for file changes with StatReloader
/Volumes/Volume/untitled folder 2/ct/app/msbctracker/views.py changed, reloading.
Watching for file changes with StatReloader
/Volumes/Volume/untitled folder 2/ct/app/tracker/settings.py changed, reloading.
Watching for file changes with StatReloader
/Volumes/Volume/untitled folder 2/ct/app/tracker/settings.py changed, reloading.
Watching for file changes with StatReloader
/Volumes/Volume/untitled folder 2/ct/app/tracker/settings.py changed, reloading.
Watching for file changes with StatReloader
/Volumes/Volume/untitled folder 2/ct/app/tracker/settings.py changed, reloading.
Watching for file changes with StatReloader
/Volumes/Volume/untitled folder 2/ct/app/tracker/settings.py changed, reloading.
Watching for file changes with StatReloader
/Volumes/Volume/untitled folder 2/ct/app/tracker/settings.py changed, reloading.
Watching for file changes with StatReloader
Watching for file changes with StatReloader
Not Found: /main.b213d01a46f40ba01e40.hot-update.json
Not Found: /main.49cf75b05498c61b9df1.hot-update.json
/Volumes/Volume/untitled folder 2/ct/app/msbctracker/views.py changed, reloading.
Watching for file changes with StatReloader
/Volumes/Volume/untitled folder 2/ct/app/msbctracker/views.py changed, reloading.
Watching for file changes with StatReloader
/Volumes/Volume/untitled folder 2/ct/app/msbctracker/views.py changed, reloading.
Watching for file changes with StatReloader
/Volumes/Volume/untitled folder 2/ct/app/msbctracker/views.py changed, reloading.
Watching for file changes with StatReloader
/Volumes/Volume/untitled folder 2/ct/app/msbctracker/views.py changed, reloading.
Watching for file changes with StatReloader
/Volumes/Volume/untitled folder 2/ct/app/msbctracker/models.py changed, reloading.
Watching for file changes with StatReloader
Watching for file changes with StatReloader
/Volumes/Volume/untitled folder 2/ct/app/msbctracker/views.py changed, reloading.
Watching for file changes with StatReloader
/Volumes/Volume/untitled folder 2/ct/app/msbctracker/views.py changed, reloading.
Watching for file changes with StatReloader
/Volumes/Volume/untitled folder 2/ct/app/msbctracker/views.py changed, reloading.
Watching for file changes with StatReloader
/Volumes/Volume/untitled folder 2/ct/app/msbctracker/views.py changed, reloading.
Watching for file changes with StatReloader
/Volumes/Volume/untitled folder 2/ct/app/msbctracker/models.py changed, reloading.
Watching for file changes with StatReloader
Watching for file changes with StatReloader
/Volumes/Volume/untitled folder 2/ct/app/msbctracker/models.py changed, reloading.
Watching for file changes with StatReloader
/Volumes/Volume/untitled folder 2/ct/app/msbctracker/models.py changed, reloading.
Watching for file changes with StatReloader
Watching for file changes with StatReloader
Watching for file changes with StatReloader
/Volumes/Volume/untitled folder 2/ct/app/msbctracker/views.py changed, reloading.
Watching for file changes with StatReloader
/Volumes/Volume/untitled folder 2/ct/app/msbctracker/views.py changed, reloading.
Watching for file changes with StatReloader
/Volumes/Volume/untitled folder 2/ct/app/msbctracker/serializers.py changed, reloading.
Watching for file changes with StatReloader
/Volumes/Volume/untitled folder 2/ct/app/msbctracker/serializers.py changed, reloading.
Watching for file changes with StatReloader
/Volumes/Volume/untitled folder 2/ct/app/msbctracker/serializers.py changed, reloading.
Watching for file changes with StatReloader
